File: velstep7_BRAVA_expb819_basalt.txt
Time(s)	Displ(microns)	Friction	Normal_stress(MPa)
11745.065000	9966.749000	0.607798	19.967894
11745.070000	9967.301000	0.607076	19.959381
11745.075000	9967.860000	0.607553	19.959312
11745.080000	9968.268000	0.607362	19.944253
11745.085000	9968.455000	0.607839	19.951111
11745.090000	9968.814000	0.607631	19.959952
11745.095000	9969.428000	0.608384	19.976628
11745.100000	9970.049000	0.608169	19.967238
11745.105000	9970.726000	0.608749	19.950081
11745.110000	9971.163000	0.608264	19.942804
11745.115000	9971.419000	0.607379	19.963591
11745.120000	9972.303000	0.607262	19.953430
11745.125000	9972.968000	0.608424	19.960548
11745.130000	9973.462000	0.607973	19.952301
11745.135000	9973.779000	0.607721	19.953514
11745.140000	9974.032000	0.607490	19.960601
11745.145000	9974.970000	0.608017	19.959106
11745.150000	9974.766000	0.607772	19.951561
11745.155000	9975.838000	0.608510	19.947221
11745.160000	9976.721000	0.607391	19.959045
11745.165000	9977.303000	0.608278	19.965651
11745.170000	9977.435000	0.607365	19.948983
11745.175000	9977.620000	0.607099	19.956604
11745.180000	9977.898000	0.606189	19.959510
11745.185000	9979.011000	0.607107	19.964743
11745.190000	9979.334000	0.607752	19.962432
11745.195000	9980.412000	0.608810	19.953735
11745.200000	9979.893000	0.607413	19.954025
11745.205000	9980.561000	0.607408	19.949799
11745.210000	9980.963000	0.607941	19.947854
11745.215000	9982.007000	0.608690	19.961440
11745.220000	9982.299000	0.608241	19.972532
11745.225000	9982.914000	0.607682	19.969023
11745.230000	9983.084000	0.607495	19.955139
11745.235000	9983.709000	0.606747	19.960670
11745.240000	9984.085000	0.606055	19.961043
11745.245000	9984.343000	0.607744	19.953705
11745.250000	9985.299000	0.607482	19.960059
11745.255000	9985.774000	0.607652	19.959464
11745.260000	9985.980000	0.607122	19.959235
11745.265000	9985.569000	0.607557	19.958114
11745.270000	9986.867000	0.607599	19.958740
11745.275000	9987.697000	0.608082	19.968351
11745.280000	9988.645000	0.608487	19.967871
11745.285000	9988.760000	0.608890	19.954010
11745.290000	9989.269000	0.607611	19.952354
11745.295000	9989.665000	0.608313	19.951355
11745.300000	9990.124000	0.607300	19.965415
11745.305000	9990.543000	0.608159	19.958106
11745.310000	9990.873000	0.608444	19.946748
11745.315000	9991.872000	0.608739	19.948281
11745.320000	9992.340000	0.607474	19.954437
11745.325000	9992.108000	0.607687	19.954544
11745.330000	9992.844000	0.606845	19.954842
11745.335000	9993.168000	0.607480	19.954231
11745.340000	9993.842000	0.607696	19.953713
11745.345000	9994.473000	0.608220	19.958091
11745.350000	9995.165000	0.608285	19.958785
11745.355000	9995.475000	0.608614	19.957229
11745.360000	9995.807000	0.607443	19.959739
11745.365000	9996.559000	0.607317	19.962454
11745.370000	9996.923000	0.606972	19.970953
11745.375000	9997.603000	0.608568	19.946901
11745.380000	9997.675000	0.607708	19.954216
11745.385000	9998.327000	0.607637	19.965804
11745.390000	9999.577000	0.608018	19.947510
11745.395000	9999.872000	0.607769	19.962424
11745.400000	10000.050000	0.607918	19.945146
11745.405000	10001.143000	0.607381	19.958419
11745.410000	10000.792000	0.607306	19.960258
11745.415000	10001.370000	0.607555	19.961936
11745.420000	10002.193000	0.607170	19.957893
11745.425000	10002.670000	0.608093	19.952797
11745.430000	10003.200000	0.607274	19.965941
11745.435000	10003.858000	0.607481	19.973279
11745.440000	10004.594000	0.607593	19.957992
11745.445000	10005.331000	0.608220	19.962714
11745.450000	10005.497000	0.608562	19.955353
11745.455000	10005.230000	0.607935	19.958206
11745.460000	10005.792000	0.607721	19.957863
11745.465000	10006.980000	0.609254	19.956810
11745.470000	10007.622000	0.609023	19.963728
11745.475000	10007.606000	0.609246	19.951325
11745.480000	10007.381000	0.607463	19.958717
11745.485000	10008.779000	0.607804	19.947098
11745.490000	10009.301000	0.607704	19.951439
11745.495000	10009.882000	0.608009	19.962332
11745.500000	10010.214000	0.607681	19.963027
11745.505000	10010.721000	0.608360	19.952332
11745.510000	10011.328000	0.607460	19.953186
11745.515000	10011.765000	0.608618	19.953026
11745.520000	10011.731000	0.607860	19.964652
11745.525000	10012.888000	0.608259	19.956383
11745.530000	10013.198000	0.608104	19.958549
11745.535000	10013.553000	0.608913	19.952446
11745.540000	10013.302000	0.607962	19.954704
11745.545000	10014.359000	0.607912	19.961753
11745.550000	10015.253000	0.608784	19.955078
11745.555000	10016.093000	0.608799	19.965971
11745.560000	10016.189000	0.607970	19.958496
11745.565000	10017.288000	0.607967	19.960883
11745.570000	10017.371000	0.607390	19.945367
11745.575000	10017.303000	0.606925	19.954193
11745.580000	10018.009000	0.605692	19.959823
11745.585000	10018.374000	0.607149	19.954162
11745.590000	10019.340000	0.607862	19.958030
11745.595000	10020.241000	0.608490	19.956520
11745.600000	10020.380000	0.608277	19.956001
11745.605000	10020.575000	0.608215	19.973554
11745.610000	10021.588000	0.608504	19.960746
11745.615000	10022.253000	0.609056	19.949738
11745.620000	10021.680000	0.608479	19.941523
11745.625000	10022.654000	0.607800	19.956276
11745.630000	10023.350000	0.607244	19.966460
11745.635000	10023.696000	0.608673	19.960868
11745.640000	10023.919000	0.609363	19.936495
11745.645000	10024.258000	0.608772	19.963225
11745.650000	10024.998000	0.608467	19.957595
11745.655000	10026.295000	0.608568	19.967314
11745.660000	10026.483000	0.608870	19.948380
11745.665000	10026.742000	0.608773	19.952545
11745.670000	10027.158000	0.607361	19.953011
11745.675000	10028.010000	0.607178	19.957489
11745.680000	10027.552000	0.606898	19.967947
11745.685000	10029.174000	0.607506	19.964560
11745.690000	10029.570000	0.606998	19.962027
11745.695000	10029.955000	0.607737	19.957672
11745.700000	10030.176000	0.606787	19.954475
11745.705000	10030.421000	0.607151	19.955772
11745.710000	10031.176000	0.607522	19.948953
11745.715000	10032.536000	0.608316	19.971555
11745.720000	10031.991000	0.607437	19.968138
11745.725000	10032.917000	0.607966	19.954788
11745.730000	10033.019000	0.607867	19.964461
11745.735000	10033.713000	0.608854	19.958183
11745.740000	10034.245000	0.608378	19.955368
11745.745000	10034.565000	0.608561	19.952744
11745.750000	10035.573000	0.607703	19.964072
11745.755000	10035.842000	0.607702	19.956131
11745.760000	10035.471000	0.606281	19.956451
11745.765000	10036.435000	0.607086	19.953857
11745.770000	10037.034000	0.607135	19.953987
11745.775000	10037.568000	0.608252	19.957908
11745.780000	10037.498000	0.608419	19.968161
11745.785000	10039.195000	0.609131	19.960349
11745.790000	10039.617000	0.608050	19.968909
11745.795000	10039.835000	0.607909	19.952477
11745.800000	10040.395000	0.606952	19.949273
11745.805000	10039.905000	0.606990	19.953011
11745.810000	10041.435000	0.606764	19.968954
11745.815000	10042.208000	0.608691	19.959052
11745.820000	10042.221000	0.608066	19.960731
11745.825000	10042.446000	0.609132	19.947137
11745.830000	10043.355000	0.608502	19.962699
11745.835000	10044.031000	0.608361	19.955360
11745.840000	10043.481000	0.607988	19.945664
11745.845000	10043.977000	0.607673	19.956024
11745.850000	10045.027000	0.607523	19.974126
11745.855000	10046.050000	0.609050	19.972837
11745.860000	10046.148000	0.608843	19.948991
11745.865000	10047.002000	0.608078	19.946130
11745.870000	10047.045000	0.607799	19.941194
11745.875000	10047.860000	0.607459	19.977460
11745.880000	10048.422000	0.606913	19.982838
11745.885000	10048.115000	0.608116	19.962531
11745.890000	10048.905000	0.607772	19.950966
11745.895000	10050.143000	0.608890	19.950349
11745.900000	10049.867000	0.608433	19.956436
11745.905000	10050.573000	0.608303	19.962782
11745.910000	10051.078000	0.608410	19.958419
11745.915000	10051.515000	0.608614	19.959090
11745.920000	10052.171000	0.608508	19.950287
11745.925000	10052.944000	0.609334	19.946549
11745.930000	10053.259000	0.607689	19.955437
11745.935000	10053.856000	0.607715	19.963134
11745.940000	10053.623000	0.607118	19.956405
11745.945000	10054.962000	0.608336	19.947999
11745.950000	10055.046000	0.607998	19.953812
11745.955000	10056.581000	0.608338	19.962752
11745.960000	10056.339000	0.607020	19.968176
11745.965000	10056.504000	0.607039	19.967070
11745.970000	10056.829000	0.607201	19.946107
11745.975000	10057.300000	0.609001	19.934649
11745.980000	10058.148000	0.607628	19.966574
11745.985000	10058.485000	0.607504	19.971105
11745.990000	10058.998000	0.607562	19.951172
11745.995000	10059.308000	0.608398	19.948968
11746.000000	10060.339000	0.608263	19.948067
11746.005000	10061.299000	0.608855	19.966795
11746.010000	10061.560000	0.607757	19.980130
11746.015000	10061.043000	0.607753	19.953461
11746.020000	10061.712000	0.607384	19.946107
11746.025000	10062.746000	0.608128	19.967139
11746.030000	10063.504000	0.607767	19.961837
11746.035000	10063.686000	0.608356	19.954201
11746.040000	10064.656000	0.608461	19.943864
11746.045000	10064.832000	0.607894	19.959922
11746.050000	10065.221000	0.607745	19.957786
11746.055000	10065.880000	0.608453	19.960647
11746.060000	10065.928000	0.607713	19.965826
11746.065000	10066.205000	0.608194	19.955131
11746.070000	10067.672000	0.607808	19.946442
11746.075000	10067.482000	0.609127	19.951172
11746.080000	10068.060000	0.607322	19.975835
11746.085000	10068.609000	0.607031	19.967680
11746.090000	10068.942000	0.607606	19.944452
11746.095000	10070.140000	0.607938	19.955414
11746.100000	10070.651000	0.607799	19.961631
11746.105000	10070.756000	0.607596	19.969931
11746.110000	10071.058000	0.606884	19.962249
11746.115000	10071.598000	0.607665	19.947938
11746.120000	10071.979000	0.606541	19.961425
11746.125000	10072.187000	0.609576	19.961715
11746.130000	10073.178000	0.609702	19.959388
11746.135000	10073.870000	0.609404	19.965430
11746.140000	10074.611000	0.608991	19.952904
11746.145000	10074.815000	0.608526	19.964751
11746.150000	10074.680000	0.607480	19.967352
11746.155000	10076.139000	0.608671	19.956871
11746.160000	10076.240000	0.607676	19.954773
11746.165000	10077.386000	0.608203	19.950387
11746.170000	10076.515000	0.606837	19.946374
11746.175000	10077.869000	0.607247	19.951645
11746.180000	10078.120000	0.607442	19.949731
11746.185000	10078.537000	0.608600	19.957496
11746.190000	10079.202000	0.607666	19.959587
11746.195000	10079.869000	0.608552	19.952828
11746.200000	10080.051000	0.608596	19.960715
11746.205000	10081.090000	0.608003	19.962066
11746.210000	10080.751000	0.606795	19.970312
11746.215000	10081.059000	0.607925	19.952858
11746.220000	10082.254000	0.607655	19.961860
11746.225000	10082.823000	0.609013	19.957275
11746.230000	10083.424000	0.609031	19.958183
11746.235000	10084.146000	0.608442	19.966017
11746.240000	10084.132000	0.607556	19.968870
11746.245000	10084.706000	0.607955	19.952858
11746.250000	10084.973000	0.607433	19.955604
11746.255000	10085.401000	0.608104	19.958129
11746.260000	10085.913000	0.607149	19.964819
11746.265000	10086.666000	0.608250	19.959907
11746.270000	10087.305000	0.608580	19.955780
11746.275000	10088.303000	0.609833	19.957893
11746.280000	10088.434000	0.609087	19.960174
11746.285000	10088.902000	0.607991	19.959640
11746.290000	10088.950000	0.607018	19.953499
11746.295000	10089.369000	0.606991	19.966811
11746.300000	10090.278000	0.608053	19.948258
11746.305000	10089.779000	0.607707	19.957283
11746.310000	10091.341000	0.607557	19.955292
11746.315000	10091.593000	0.608951	19.951966
11746.320000	10092.849000	0.608963	19.945825
11746.325000	10092.898000	0.608756	19.958755
11746.330000	10092.876000	0.607424	19.965506
11746.335000	10093.879000	0.608482	19.944512
11746.340000	10094.117000	0.607434	19.948906
11746.345000	10094.167000	0.607781	19.952774
11746.350000	10094.743000	0.607023	19.969854
11746.355000	10095.427000	0.607941	19.967215
11746.360000	10096.560000	0.608074	19.959625
11746.365000	10096.525000	0.608899	19.938570
11746.370000	10096.628000	0.607943	19.970358
11746.375000	10097.609000	0.608182	19.960418
11746.380000	10098.101000	0.607861	19.961982
11746.385000	10099.097000	0.608542	19.956642
11746.390000	10098.900000	0.608409	19.953178
11746.395000	10099.638000	0.608683	19.955612
11746.400000	10100.293000	0.608967	19.946702
11746.405000	10100.799000	0.608958	19.953438
11746.410000	10100.696000	0.607708	19.959136
11746.415000	10101.766000	0.607861	19.955185
11746.420000	10102.376000	0.607755	19.952103
11746.425000	10102.791000	0.607709	19.962775
11746.430000	10103.019000	0.607225	19.965056
11746.435000	10104.237000	0.608374	19.967482
11746.440000	10104.218000	0.608473	19.958457
11746.445000	10105.014000	0.608386	19.947274
11746.450000	10105.485000	0.607642	19.950958
11746.455000	10105.654000	0.607916	19.965697
11746.460000	10106.407000	0.606974	19.964705
11746.465000	10106.851000	0.608285	19.951401
11746.470000	10107.336000	0.607894	19.935793
11746.475000	10108.296000	0.608890	19.936610
11746.480000	10108.272000	0.607881	19.959861
11746.485000	10108.637000	0.608134	19.972760
11746.490000	10109.289000	0.607802	19.968115
11746.495000	10109.789000	0.609318	19.947450
11746.500000	10109.540000	0.608784	19.948312
11746.505000	10110.671000	0.608261	19.959830
11746.510000	10110.739000	0.607867	19.965636
11746.515000	10111.881000	0.608171	19.961669
11746.520000	10112.223000	0.607505	19.959510
11746.525000	10112.776000	0.608403	19.946534
11746.530000	10113.082000	0.607925	19.947045
11746.535000	10113.581000	0.607988	19.957183
11746.540000	10113.999000	0.607325	19.968107
11746.545000	10114.875000	0.607722	19.965239
11746.550000	10114.942000	0.608768	19.934779
11746.555000	10115.963000	0.608067	19.954612
11746.560000	10116.424000	0.606865	19.964530
11746.565000	10116.544000	0.607903	19.969938
11746.570000	10117.521000	0.607648	19.956993
11746.575000	10118.349000	0.608769	19.958854
11746.580000	10117.811000	0.607555	19.972333
11746.585000	10118.208000	0.608441	19.950257
11746.590000	10119.251000	0.607881	19.960662
11746.595000	10119.737000	0.609806	19.956199
11746.600000	10120.436000	0.608568	19.966124
11746.605000	10121.031000	0.608105	19.962851
11746.610000	10120.869000	0.606565	19.967169
11746.615000	10121.546000	0.607086	19.965842
11746.620000	10122.308000	0.607500	19.955970
11746.625000	10123.062000	0.608593	19.948968
11746.630000	10123.225000	0.607331	19.971799
11746.635000	10124.403000	0.607514	19.954940
11746.640000	10123.263000	0.606295	19.960158
11746.645000	10124.300000	0.607341	19.946664
11746.650000	10124.887000	0.607380	19.963660
11746.655000	10125.669000	0.609739	19.955139
11746.660000	10126.195000	0.608564	19.959945
11746.665000	10126.447000	0.608917	19.950318
11746.670000	10127.824000	0.608368	19.955406
11746.675000	10127.280000	0.607897	19.972204
11746.680000	10128.138000	0.607077	19.965491
11746.685000	10128.585000	0.608086	19.953087
11746.690000	10128.878000	0.607567	19.951889
11746.695000	10129.533000	0.607867	19.953842
11746.700000	10130.137000	0.608466	19.956016
11746.705000	10130.753000	0.608758	19.958564
11746.710000	10131.656000	0.608162	19.959396
11746.715000	10132.019000	0.609222	19.959266
11746.720000	10131.939000	0.607589	19.962782
11746.725000	10133.075000	0.608001	19.954132
11746.730000	10133.076000	0.607898	19.965880
11746.735000	10133.372000	0.608564	19.962813
11746.740000	10134.398000	0.607970	19.971098
11746.745000	10135.003000	0.609479	19.944947
11746.750000	10135.118000	0.608296	19.939158
11746.755000	10135.965000	0.607972	19.969480
11746.760000	10135.849000	0.606980	19.980626
11746.765000	10136.383000	0.608069	19.954651
11746.770000	10136.956000	0.607644	19.956390
11746.775000	10137.233000	0.608053	19.944452
11746.780000	10137.327000	0.607347	19.965514
11746.785000	10138.608000	0.608379	19.956008
11746.790000	10139.454000	0.608777	19.958472
11746.795000	10139.963000	0.609012	19.947838
11746.800000	10139.786000	0.608382	19.960647
11746.805000	10141.038000	0.608047	19.959777
11746.810000	10141.647000	0.607319	19.957672
11746.815000	10141.680000	0.608202	19.957412
11746.820000	10141.998000	0.607124	19.958152
11746.825000	10142.433000	0.608454	19.942865
11746.830000	10142.897000	0.608365	19.956375
11746.835000	10143.459000	0.608934	19.959190
11746.840000	10144.441000	0.607530	19.967741
11746.845000	10144.872000	0.608721	19.962279
11746.850000	10145.122000	0.608294	19.960174
11746.855000	10145.516000	0.607808	19.971815
11746.860000	10146.026000	0.607972	19.955505
11746.865000	10146.344000	0.609091	19.949341
11746.870000	10147.472000	0.608890	19.954826
11746.875000	10147.885000	0.609212	19.964812
11746.880000	10147.814000	0.607921	19.951798
11746.885000	10149.402000	0.608607	19.955902
11746.890000	10148.829000	0.608530	19.961676
11746.895000	10150.097000	0.607527	19.959014
11746.900000	10150.186000	0.607706	19.954826
11746.905000	10150.497000	0.608334	19.956939
11746.910000	10151.142000	0.608105	19.956336
11746.915000	10151.964000	0.608054	19.961783
11746.920000	10152.767000	0.607824	19.964468
11746.925000	10152.912000	0.608482	19.952980
11746.930000	10153.421000	0.607698	19.952034
11746.935000	10153.884000	0.607635	19.963736
11746.940000	10154.506000	0.606742	19.978787
11746.945000	10154.473000	0.607325	19.962935
11746.950000	10155.189000	0.607286	19.955009
11746.955000	10155.582000	0.607919	19.948899
11746.960000	10156.251000	0.607507	19.955864
11746.965000	10156.544000	0.607735	19.963522
11746.970000	10156.453000	0.607599	19.951500
11746.975000	10157.349000	0.608982	19.953888
11746.980000	10158.351000	0.608944	19.963607
11746.985000	10159.296000	0.610096	19.959701
11746.990000	10159.262000	0.608588	19.957420
11746.995000	10159.848000	0.607921	19.952591
11747.000000	10160.158000	0.607227	19.945291
11747.005000	10160.285000	0.608089	19.941316
11747.010000	10161.073000	0.607777	19.962775
11747.015000	10161.651000	0.608677	19.975255
11747.020000	10162.853000	0.607739	19.967070
11747.025000	10162.640000	0.609176	19.943109
11747.030000	10163.408000	0.607740	19.944002
11747.035000	10163.637000	0.607820	19.950097
11747.040000	10163.976000	0.607030	19.958907
11747.045000	10164.807000	0.607972	19.964858
11747.050000	10164.733000	0.608385	19.959892
11747.055000	10165.744000	0.609199	19.940958
11747.060000	10166.109000	0.607853	19.957260
11747.065000	10167.147000	0.609093	19.954971
11747.070000	10166.827000	0.608387	19.965796
11747.075000	10166.804000	0.608377	19.961554
11747.080000	10168.570000	0.608566	19.964102
11747.085000	10168.824000	0.609984	19.942033
11747.090000	10169.279000	0.608224	19.960792
11747.095000	10169.559000	0.607542	19.955902
11747.100000	10169.734000	0.606613	19.955948
11747.105000	10170.496000	0.607610	19.946427
11747.110000	10170.804000	0.608335	19.961105
11747.115000	10172.108000	0.609467	19.953308
11747.120000	10172.443000	0.609641	19.960860
11747.125000	10173.235000	0.609155	19.958030
11747.130000	10173.568000	0.608200	19.954521
11747.135000	10173.708000	0.607859	19.959754
11747.140000	10174.174000	0.607080	19.960960
11747.145000	10175.260000	0.608424	19.962363
11747.150000	10175.416000	0.608430	19.949883
11747.155000	10175.630000	0.607720	19.952385
11747.160000	10175.641000	0.606885	19.958496
11747.165000	10176.806000	0.607489	19.957824
11747.170000	10176.948000	0.607050	19.942003
11747.175000	10177.737000	0.607464	19.957962
11747.180000	10178.625000	0.607726	19.962035
11747.185000	10178.707000	0.608355	19.960914
11747.190000	10179.254000	0.607757	19.965041
11747.195000	10179.039000	0.607730	19.959640
11747.200000	10180.280000	0.607782	19.945833
11747.205000	10181.026000	0.608915	19.951783
11747.210000	10180.655000	0.607721	19.969488
11747.215000	10181.609000	0.607885	19.971517
11747.220000	10181.275000	0.608141	19.957359
11747.225000	10183.145000	0.609449	19.945245
11747.230000	10183.502000	0.608526	19.963385
11747.235000	10183.445000	0.607996	19.965201
11747.240000	10183.954000	0.607049	19.960044
11747.245000	10185.397000	0.607950	19.958793
11747.250000	10185.457000	0.607523	19.960975
11747.255000	10186.051000	0.607448	19.959335
11747.260000	10185.422000	0.606779	19.962791
11747.265000	10186.512000	0.607688	19.964644
11747.270000	10186.998000	0.607419	19.962256
11747.275000	10188.474000	0.608888	19.949814
11747.280000	10188.419000	0.608203	19.959480
11747.285000	10188.547000	0.607001	19.960723
11747.290000	10188.838000	0.606593	19.959663
11747.295000	10189.884000	0.607814	19.957092
11747.300000	10189.723000	0.606835	19.962363
11747.305000	10190.809000	0.607502	19.972020
11747.310000	10190.838000	0.606713	19.971083
11747.315000	10191.118000	0.608082	19.958465
11747.320000	10191.757000	0.608849	19.944490
11747.325000	10192.342000	0.609605	19.944688
11747.330000	10193.033000	0.608702	19.966963
11747.335000	10193.786000	0.608993	19.957878
11747.340000	10194.012000	0.608899	19.955330
11747.345000	10194.903000	0.609200	19.956741
11747.350000	10195.639000	0.608270	19.943551
11747.355000	10196.372000	0.608128	19.955833
11747.360000	10196.485000	0.607346	19.950081
11747.365000	10196.855000	0.606741	19.956093
11747.370000	10197.221000	0.606406	19.956611
11747.375000	10197.618000	0.607535	19.945108
11747.380000	10198.448000	0.607387	19.946534
11747.385000	10198.974000	0.608517	19.947045
11747.390000	10199.063000	0.607516	19.970289
11747.395000	10200.028000	0.608169	19.979153
11747.400000	10200.254000	0.608272	19.949067
11747.405000	10201.064000	0.608533	19.944116
11747.410000	10200.920000	0.607674	19.954826
11747.415000	10201.729000	0.608004	19.960494
11747.420000	10202.191000	0.607980	19.956772
11747.425000	10202.852000	0.607837	19.967566
11747.430000	10202.615000	0.608287	19.959434
11747.435000	10203.651000	0.608938	19.952309
11747.440000	10204.095000	0.609006	19.952225
11747.445000	10205.036000	0.609143	19.960601
11747.450000	10205.496000	0.608198	19.965720
11747.455000	10205.886000	0.609138	19.943025
11747.460000	10205.771000	0.607097	19.959861
11747.465000	10206.735000	0.606678	19.962058
11747.470000	10206.825000	0.607068	19.959472
11747.475000	10207.595000	0.608352	19.965239
11747.480000	10208.109000	0.607972	19.966757
11747.485000	10208.479000	0.609209	19.958701
11747.490000	10208.728000	0.608835	19.964270
11747.495000	10209.644000	0.609871	19.964621
11747.500000	10210.848000	0.608982	19.955124
11747.505000	10211.107000	0.608976	19.956283
11747.510000	10211.314000	0.607434	19.969252
11747.515000	10211.660000	0.607719	19.954132
11747.520000	10212.226000	0.607743	19.950509
11747.525000	10212.885000	0.607517	19.968611
11747.530000	10213.290000	0.607138	19.962355
11747.535000	10213.585000	0.607870	19.962325
11747.540000	10213.683000	0.607988	19.950165
11747.545000	10214.626000	0.608625	19.952477
11747.550000	10215.680000	0.608360	19.958412
11747.555000	10216.113000	0.608504	19.958450
11747.560000	10216.727000	0.606944	19.951660
11747.565000	10216.605000	0.606719	19.952309
11747.570000	10217.428000	0.606648	19.954796
11747.575000	10218.072000	0.606552	19.962523
11747.580000	10218.560000	0.607385	19.957717
11747.585000	10219.716000	0.612451	19.964072
11747.590000	10221.228000	0.614815	19.975591
11747.595000	10222.651000	0.618326	19.974469
11747.600000	10224.753000	0.617687	19.961425
11747.605000	10226.551000	0.617699	19.948403
11747.610000	10227.853000	0.613506	19.945512
11747.615000	10229.887000	0.612579	19.944215
11747.620000	10230.020000	0.610137	19.957870
11747.625000	10231.863000	0.611142	19.944139
11747.630000	10233.420000	0.610124	19.944322
11747.635000	10235.163000	0.610524	19.953774
11747.640000	10236.109000	0.607886	19.953613
11747.645000	10238.525000	0.608965	19.942048
11747.650000	10239.177000	0.607610	19.929805
11747.655000	10241.364000	0.607629	19.955734
11747.660000	10242.248000	0.607000	19.953568
11747.665000	10243.863000	0.609165	19.940485
11747.670000	10244.671000	0.607929	19.948769
11747.675000	10246.677000	0.609331	19.941675
11747.680000	10248.518000	0.607809	19.930202
11747.685000	10250.788000	0.608592	19.939775
11747.690000	10251.516000	0.606023	19.937517
11747.695000	10253.250000	0.606651	19.946908
11747.700000	10254.663000	0.605533	19.946710
11747.705000	10256.600000	0.608230	19.932712
11747.710000	10257.159000	0.606466	19.937624
11747.715000	10259.197000	0.608271	19.939447
11747.720000	10260.107000	0.606959	19.940165
11747.725000	10261.695000	0.608348	19.934535
11747.730000	10262.978000	0.607028	19.939295
11747.735000	10265.134000	0.607815	19.957466
11747.740000	10266.255000	0.606482	19.944268
11747.745000	10268.591000	0.608303	19.929180
11747.750000	10269.255000	0.606223	19.940127
11747.755000	10270.663000	0.607321	19.945252
11747.760000	10272.074000	0.606412	19.942507
11747.765000	10274.232000	0.608418	19.945687
11747.770000	10275.073000	0.607289	19.928440
11747.775000	10277.587000	0.608229	19.941332
11747.780000	10278.185000	0.605487	19.955269
11747.785000	10279.879000	0.607456	19.936381
11747.790000	10281.654000	0.606082	19.923344
11747.795000	10283.467000	0.608135	19.938975
11747.800000	10284.408000	0.607227	19.931461
11747.805000	10286.319000	0.607691	19.945756
11747.810000	10288.556000	0.606562	19.935786
11747.815000	10289.100000	0.607290	19.942117
11747.820000	10290.077000	0.605721	19.938936
11747.825000	10292.771000	0.607973	19.934603
11747.830000	10293.148000	0.606423	19.937975
11747.835000	10295.318000	0.607533	19.945161
11747.840000	10296.477000	0.605152	19.955742
11747.845000	10298.316000	0.607840	19.931438
11747.850000	10299.189000	0.606557	19.935458
11747.855000	10301.123000	0.607961	19.953675
11747.860000	10302.935000	0.606593	19.946382
11747.865000	10305.000000	0.608011	19.942697
11747.870000	10306.182000	0.605797	19.935412
11747.875000	10307.204000	0.606442	19.921353
11747.880000	10308.134000	0.604571	19.931232
11747.885000	10310.008000	0.606851	19.944299
11747.890000	10311.577000	0.605834	19.959090
11747.895000	10313.388000	0.608341	19.944864
11747.900000	10314.058000	0.606561	19.937586
11747.905000	10315.840000	0.607445	19.933055
11747.910000	10317.539000	0.605786	19.930949
11747.915000	10319.200000	0.607080	19.934733
11747.920000	10320.629000	0.605667	19.945939
11747.925000	10322.727000	0.608790	19.937251
11747.930000	10323.638000	0.606621	19.943765
11747.935000	10325.198000	0.607580	19.934115
11747.940000	10326.951000	0.605422	19.932315
11747.945000	10328.319000	0.606575	19.949921
11747.950000	10329.497000	0.605749	19.940645
11747.955000	10330.815000	0.607143	19.929134
11747.960000	10332.126000	0.606364	19.932902
11747.965000	10334.166000	0.607106	19.949502
11747.970000	10335.571000	0.606291	19.953438
11747.975000	10337.473000	0.607612	19.937136
11747.980000	10338.288000	0.605745	19.939569
11747.985000	10340.636000	0.607238	19.926586
11747.990000	10341.718000	0.605344	19.938952
11747.995000	10343.270000	0.606761	19.939028
11748.000000	10344.537000	0.605709	19.936366
11748.005000	10346.493000	0.607433	19.932925
11748.010000	10347.588000	0.605616	19.935443
11748.015000	10349.109000	0.606911	19.934176
11748.020000	10350.519000	0.605523	19.927677
11748.025000	10352.361000	0.607009	19.935068
11748.030000	10352.867000	0.605660	19.947503
11748.035000	10355.455000	0.607215	19.944536
11748.040000	10355.988000	0.606377	19.924168
11748.045000	10358.100000	0.607445	19.929195
11748.050000	10359.338000	0.605788	19.940103
11748.055000	10361.285000	0.607311	19.942232
11748.060000	10362.744000	0.605876	19.938120
11748.065000	10364.686000	0.606760	19.936213
11748.070000	10365.366000	0.605230	19.921704
11748.075000	10366.892000	0.606266	19.941240
11748.080000	10368.082000	0.605512	19.942453
11748.085000	10370.038000	0.607919	19.939569
11748.090000	10371.228000	0.606534	19.936098
11748.095000	10372.774000	0.607292	19.935847
11748.100000	10374.289000	0.605282	19.944497
11748.105000	10376.161000	0.606749	19.938707
11748.110000	10377.071000	0.605790	19.924892
11748.115000	10378.917000	0.607419	19.928195
11748.120000	10380.738000	0.606385	19.943856
11748.125000	10382.368000	0.607775	19.930957
11748.130000	10382.494000	0.604731	19.929851
11748.135000	10385.328000	0.606271	19.933329
11748.140000	10386.485000	0.605786	19.920949
11748.145000	10388.729000	0.607042	19.939524
11748.150000	10389.134000	0.605089	19.948838
11748.155000	10391.214000	0.606524	19.943674
11748.160000	10392.103000	0.605774	19.937395
11748.165000	10393.671000	0.607708	19.933482
11748.170000	10395.263000	0.606489	19.935626
11748.175000	10397.460000	0.606570	19.949189
11748.180000	10398.042000	0.605333	19.939318
11748.185000	10399.944000	0.606873	19.945222
11748.190000	10401.143000	0.606515	19.939020
11748.195000	10403.112000	0.608554	19.929126
11748.200000	10404.492000	0.606205	19.931994
11748.205000	10406.054000	0.606857	19.935733
11748.210000	10407.816000	0.605303	19.933749
11748.215000	10409.621000	0.606705	19.933177
11748.220000	10409.632000	0.605898	19.922627
11748.225000	10412.105000	0.606891	19.937167
11748.230000	10413.212000	0.605072	19.949753
11748.235000	10415.055000	0.607057	19.942941
11748.240000	10416.235000	0.606496	19.933047
11748.245000	10418.282000	0.608160	19.925983
11748.250000	10419.697000	0.606146	19.933253
11748.255000	10421.450000	0.606343	19.942140
11748.260000	10422.229000	0.604837	19.924892
11748.265000	10424.042000	0.606294	19.933230
11748.270000	10425.349000	0.605503	19.942636
11748.275000	10426.947000	0.606941	19.942079
11748.280000	10428.510000	0.606356	19.942697
11748.285000	10429.656000	0.608179	19.923626
11748.290000	10431.795000	0.605568	19.939104
11748.295000	10432.752000	0.606134	19.944093
11748.300000	10434.057000	0.605386	19.927654
11748.305000	10435.473000	0.607002	19.933398
11748.310000	10437.249000	0.605735	19.946877
11748.315000	10439.188000	0.607345	19.942773
11748.320000	10440.626000	0.607562	19.927326
11748.325000	10442.508000	0.608095	19.936014
11748.330000	10443.749000	0.605813	19.930278
11748.335000	10445.734000	0.606439	19.931148
11748.340000	10446.253000	0.604715	19.935862
11748.345000	10448.027000	0.606264	19.934031
11748.350000	10449.466000	0.606184	19.922963
11748.355000	10451.247000	0.606591	19.939699
11748.360000	10452.081000	0.605098	19.951447
11748.365000	10454.492000	0.607465	19.931659
11748.370000	10455.213000	0.606025	19.937228
11748.375000	10456.862000	0.607562	19.930248
11748.380000	10457.926000	0.606152	19.931026
11748.385000	10460.170000	0.607908	19.942682
11748.390000	10461.854000	0.607028	19.928172
11748.395000	10462.755000	0.607816	19.922604
11748.400000	10463.911000	0.606007	19.910528
11748.405000	10465.825000	0.606708	19.944543
11748.410000	10467.626000	0.605793	19.958275
11748.415000	10469.775000	0.607420	19.938334
11748.420000	10470.511000	0.605474	19.934123
11748.425000	10471.940000	0.606266	19.923984
11748.430000	10472.985000	0.604806	19.937136
11748.435000	10475.174000	0.606943	19.951889
11748.440000	10476.381000	0.606286	19.938578
11748.445000	10477.994000	0.608241	19.939775
11748.450000	10479.088000	0.605868	19.946572
11748.455000	10480.835000	0.607727	19.938334
11748.460000	10482.741000	0.606298	19.935885
11748.465000	10484.397000	0.607155	19.932399
11748.470000	10484.872000	0.604907	19.939508
11748.475000	10486.847000	0.605702	19.943193
11748.480000	10487.662000	0.605861	19.929126
11748.485000	10489.756000	0.607398	19.943803
11748.490000	10491.270000	0.605761	19.962676
11748.495000	10493.819000	0.608575	19.930812
11748.500000	10494.849000	0.605818	19.930042
11748.505000	10496.322000	0.606307	19.922512
11748.510000	10496.994000	0.604303	19.944452
11748.515000	10499.394000	0.606626	19.940538
11748.520000	10500.312000	0.606363	19.930789
11748.525000	10502.216000	0.607299	19.935740
11748.530000	10503.678000	0.606150	19.936488
11748.535000	10505.515000	0.607891	19.935565
11748.540000	10506.515000	0.605787	19.930477
11748.545000	10508.287000	0.606128	19.937273
11748.550000	10509.085000	0.605426	19.938166
11748.555000	10511.393000	0.608152	19.929409
11748.560000	10512.355000	0.605935	19.949974
11748.565000	10514.292000	0.607022	19.944330
11748.570000	10515.062000	0.606168	19.930530
11748.575000	10516.342000	0.607104	19.927181
11748.580000	10518.499000	0.606216	19.923885
11748.585000	10520.253000	0.607574	19.938570
11748.590000	10520.931000	0.606268	19.937891
11748.595000	10522.802000	0.607153	19.941774
11748.600000	10524.595000	0.605931	19.927471
11748.605000	10526.053000	0.608018	19.919721
11748.610000	10527.610000	0.605400	19.935633
11748.615000	10529.574000	0.606389	19.941583
11748.620000	10530.724000	0.605026	19.927829
11748.625000	10531.705000	0.607007	19.925198
11748.630000	10533.518000	0.605381	19.941301
11748.635000	10535.398000	0.607164	19.950165
11748.640000	10536.222000	0.606623	19.928912
11748.645000	10538.063000	0.607328	19.929126
11748.650000	10539.061000	0.605494	19.951721
11748.655000	10541.484000	0.607595	19.949181
11748.660000	10542.589000	0.606085	19.935259
11748.665000	10544.054000	0.607575	19.930980
11748.670000	10545.349000	0.605665	19.923542
11748.675000	10547.610000	0.606463	19.943872
11748.680000	10548.164000	0.604931	19.944589
11748.685000	10550.225000	0.606773	19.923176
11748.690000	10551.033000	0.604708	19.936259
11748.695000	10553.160000	0.606455	19.937540
11748.700000	10554.240000	0.605727	19.953201
11748.705000	10556.115000	0.607644	19.939745
11748.710000	10556.952000	0.606802	19.930331
11748.715000	10558.766000	0.608555	19.933978
11748.720000	10560.686000	0.607466	19.934115
11748.725000	10562.776000	0.608091	19.944612
11748.730000	10563.563000	0.606064	19.934649
11748.735000	10565.201000	0.607030	19.920399
11748.740000	10566.855000	0.605578	19.922863
11748.745000	10568.136000	0.607253	19.928134
11748.750000	10569.035000	0.605482	19.941873
11748.755000	10571.672000	0.607059	19.935679
11748.760000	10572.446000	0.605504	19.939287
11748.765000	10574.334000	0.607418	19.932673
11748.770000	10575.357000	0.605913	19.948548
11748.775000	10577.194000	0.606721	19.947510
11748.780000	10578.239000	0.604931	19.947305
11748.785000	10579.747000	0.607555	19.919850
11748.790000	10581.072000	0.605894	19.937266
11748.795000	10583.129000	0.607982	19.942941
11748.800000	10584.289000	0.606259	19.942194
11748.805000	10586.126000	0.606920	19.943651
11748.810000	10587.131000	0.605401	19.923771
11748.815000	10589.320000	0.607101	19.928279
11748.820000	10590.200000	0.605421	19.936899
11748.825000	10591.888000	0.606583	19.945520
11748.830000	10593.662000	0.605309	19.936587
11748.835000	10594.964000	0.606995	19.919285
11748.840000	10596.593000	0.606253	19.927745
11748.845000	10598.671000	0.607342	19.938715
11748.850000	10599.617000	0.605257	19.943056
11748.855000	10600.354000	0.606959	19.931773
11748.860000	10601.958000	0.605389	19.938463
11748.865000	10604.296000	0.607328	19.932307
11748.870000	10605.114000	0.605817	19.939943
11748.875000	10607.049000	0.607423	19.928691
11748.880000	10608.109000	0.605966	19.929904
11748.885000	10610.145000	0.607337	19.944025
11748.890000	10611.214000	0.606490	19.935229
11748.895000	10612.646000	0.607678	19.937494
11748.900000	10614.445000	0.606066	19.927089
11748.905000	10616.367000	0.607469	19.920216
11748.910000	10617.009000	0.606137	19.928478
11748.915000	10618.957000	0.606998	19.946664
11748.920000	10620.258000	0.606199	19.943689
11748.925000	10622.053000	0.608442	19.931270
11748.930000	10623.555000	0.606619	19.932154
11748.935000	10625.597000	0.607226	19.926708
11748.940000	10626.486000	0.604669	19.948434
11748.945000	10628.775000	0.606209	19.936426
11748.950000	10629.186000	0.604822	19.931964
11748.955000	10631.479000	0.606588	19.932772
11748.960000	10631.974000	0.605215	19.938852
11748.965000	10634.323000	0.607550	19.933070
11748.970000	10635.111000	0.606344	19.931842
11748.975000	10636.966000	0.607508	19.941416
11748.980000	10637.866000	0.606456	19.935343
11748.985000	10640.115000	0.608014	19.931392
11748.990000	10641.766000	0.606603	19.931545
11748.995000	10643.517000	0.607189	19.941469
11749.000000	10644.531000	0.605434	19.935038
11749.005000	10646.130000	0.606778	19.930713
11749.010000	10647.306000	0.606075	19.925663
11749.015000	10649.248000	0.607356	19.932032
11749.020000	10649.970000	0.605538	19.942476
11749.025000	10652.164000	0.606810	19.946153
11749.030000	10653.019000	0.606164	19.924488
11749.035000	10655.703000	0.607854	19.931545
11749.040000	10656.218000	0.606081	19.943727
11749.045000	10658.500000	0.606665	19.940836
11749.050000	10659.453000	0.605053	19.933093
11749.055000	10660.994000	0.606920	19.929561
11749.060000	10662.771000	0.606012	19.934222
11749.065000	10664.201000	0.607789	19.943856
11749.070000	10665.278000	0.605890	19.945481
11749.075000	10667.286000	0.607485	19.929690
11749.080000	10668.073000	0.606405	19.916356
11749.085000	10669.849000	0.607136	19.930560
11749.090000	10670.934000	0.605729	19.937197
11749.095000	10673.056000	0.607679	19.940012
11749.100000	10674.997000	0.606262	19.930751
11749.105000	10676.593000	0.607309	19.928622
11749.110000	10677.341000	0.605435	19.932979
11749.115000	10679.005000	0.606446	19.952110
11749.120000	10679.879000	0.605684	19.938456
11749.125000	10682.327000	0.608111	19.931438
11749.130000	10683.601000	0.606304	19.932185
11749.135000	10684.890000	0.607175	19.935290
11749.140000	10685.763000	0.605337	19.930888
11749.145000	10687.879000	0.607544	19.925861
11749.150000	10689.551000	0.606321	19.934016
11749.155000	10691.190000	0.606859	19.948396
11749.160000	10693.053000	0.605227	19.937105
11749.165000	10694.148000	0.606502	19.918126
11749.170000	10695.229000	0.605187	19.925159
11749.175000	10696.743000	0.606466	19.949738
11749.180000	10698.512000	0.606230	19.945459
11749.185000	10699.927000	0.607546	19.931186
11749.190000	10701.428000	0.605816	19.938150
11749.195000	10702.813000	0.607043	19.943544
11749.200000	10704.415000	0.606695	19.915730
11749.205000	10706.708000	0.608231	19.928798
11749.210000	10707.068000	0.606002	19.941354
11749.215000	10708.385000	0.606895	19.944391
11749.220000	10710.217000	0.605773	19.937182
11749.225000	10712.395000	0.607784	19.936801
11749.230000	10713.693000	0.605766	19.945535
11749.235000	10715.321000	0.607386	19.927822
11749.240000	10716.166000	0.604923	19.940371
11749.245000	10718.351000	0.606960	19.923565
11749.250000	10719.159000	0.606099	19.946801
11749.255000	10721.607000	0.607008	19.951286
11749.260000	10722.365000	0.606096	19.935298
11749.265000	10724.148000	0.607907	19.928318
11749.270000	10725.562000	0.606354	19.929767
11749.275000	10727.046000	0.607247	19.943773
11749.280000	10728.097000	0.605754	19.937029
11749.285000	10730.401000	0.607186	19.924816
11749.290000	10731.027000	0.605724	19.929813
11749.295000	10733.077000	0.606488	19.945268
11749.300000	10734.347000	0.605356	19.943879
11749.305000	10736.080000	0.606823	19.937281
11749.310000	10736.894000	0.605793	19.929775
11749.315000	10738.921000	0.606894	19.936968
11749.320000	10740.821000	0.605384	19.956390
11749.325000	10742.089000	0.607331	19.930408
11749.330000	10742.860000	0.605984	19.916410
11749.335000	10744.785000	0.607688	19.932467
11749.340000	10746.705000	0.606337	19.946366
11749.345000	10747.769000	0.607539	19.941698
11749.350000	10749.088000	0.605238	19.922833
11749.355000	10751.211000	0.607079	19.923626
11749.360000	10752.456000	0.604996	19.946946
11749.365000	10753.884000	0.607384	19.951683
11749.370000	10755.121000	0.606033	19.935702
11749.375000	10757.239000	0.607516	19.927654
11749.380000	10758.455000	0.606238	19.938311
11749.385000	10760.354000	0.607156	19.948426
11749.390000	10761.363000	0.605749	19.943391
11749.395000	10762.683000	0.607375	19.931926
11749.400000	10764.357000	0.606187	19.931956
11749.405000	10766.264000	0.608171	19.941362
11749.410000	10767.771000	0.606180	19.950005
11749.415000	10769.077000	0.607310	19.931560
11749.420000	10770.369000	0.606242	19.918057
11749.425000	10771.988000	0.606846	19.929309
11749.430000	10773.051000	0.604829	19.940721
11749.435000	10774.451000	0.606611	19.936068
11749.440000	10776.212000	0.605540	19.944353
11749.445000	10778.540000	0.607641	19.942415
11749.450000	10779.326000	0.606850	19.921338
11749.455000	10781.337000	0.606874	19.936091
11749.460000	10782.220000	0.605244	19.935976
11749.465000	10784.506000	0.607392	19.927631
11749.470000	10785.197000	0.606502	19.916173
11749.475000	10787.146000	0.607448	19.930545
11749.480000	10788.548000	0.606546	19.933032
11749.485000	10790.004000	0.606897	19.941553
11749.490000	10791.262000	0.605437	19.927181
11749.495000	10792.434000	0.606957	19.927906
11749.500000	10794.042000	0.605976	19.931171
11749.505000	10796.199000	0.607860	19.940447
11749.510000	10797.079000	0.606911	19.933505
11749.515000	10799.587000	0.607593	19.928447
11749.520000	10800.595000	0.606432	19.926746
11749.525000	10801.995000	0.606936	19.931140
11749.530000	10803.202000	0.605624	19.923184
11749.535000	10804.620000	0.607565	19.943033
11749.540000	10805.987000	0.606417	19.942537
11749.545000	10808.337000	0.607334	19.941324
11749.550000	10809.268000	0.606169	19.936243
11749.555000	10811.347000	0.607493	19.931804
11749.560000	10812.429000	0.605782	19.934176
11749.565000	10813.730000	0.606624	19.942232
11749.570000	10815.307000	0.605507	19.940576
11749.572000	10816.190000	0.607324	19.930217