File: velstep3_TR2_exp013_sepiolite.txt
Time(s)	Displ(microns)	Friction	Effective_Normal_stress(MPa)
20086.207000	5753.577000	0.455250	30.004552
20088.247000	5754.144000	0.454260	30.011269
20090.317000	5754.407000	0.454460	29.997399
20092.347000	5755.155000	0.453884	30.009979
20094.367000	5755.317000	0.453634	30.003214
20096.407000	5755.661000	0.454209	30.009548
20098.437000	5756.127000	0.454955	29.995701
20100.427000	5756.248000	0.453956	29.990034
20102.437000	5757.220000	0.453298	29.997849
20104.467000	5757.402000	0.454153	29.999751
20106.497000	5757.644000	0.454300	30.005466
20108.567000	5758.231000	0.454271	29.994416
20110.547000	5758.494000	0.453891	30.001492
20112.557000	5758.798000	0.455027	30.009544
20114.577000	5759.506000	0.454269	29.993320
20116.607000	5759.911000	0.454800	29.989533
20118.637000	5760.336000	0.454722	29.994695
20120.697000	5761.064000	0.453939	29.994469
20122.807000	5760.862000	0.454597	29.997230
20124.837000	5761.550000	0.453789	29.997613
20126.897000	5761.995000	0.453579	30.009225
20128.977000	5762.258000	0.454145	30.001655
20131.037000	5762.481000	0.454843	29.993680
20133.077000	5763.169000	0.454448	29.990778
20135.097000	5763.735000	0.454940	30.006681
20137.137000	5764.241000	0.454594	30.000484
20139.197000	5764.120000	0.454688	30.001853
20141.237000	5765.010000	0.454618	29.997346
20143.277000	5765.233000	0.455011	29.991114
20145.277000	5765.678000	0.454106	30.006672
20147.307000	5765.982000	0.455012	29.995221
20149.387000	5766.568000	0.454211	30.008618
20151.417000	5767.034000	0.454145	29.995531
20153.437000	5767.095000	0.453830	29.997998
20155.477000	5767.843000	0.453736	30.000276
20157.577000	5768.268000	0.453767	29.997285
20159.627000	5768.390000	0.453569	29.994504
20161.687000	5769.199000	0.454320	29.996554
20163.697000	5769.260000	0.454116	29.986021
20165.687000	5769.705000	0.454434	29.989704
20167.767000	5770.231000	0.454276	29.999546
20169.787000	5770.697000	0.454782	30.002808
20171.827000	5771.020000	0.454555	30.005660
20173.847000	5771.202000	0.454137	30.001363
20175.897000	5771.789000	0.454530	30.012390
20177.927000	5772.234000	0.454578	29.998062
20179.927000	5772.538000	0.454540	30.008206
20181.957000	5773.084000	0.454695	29.994712
20183.967000	5773.165000	0.453847	29.999222
20186.017000	5773.408000	0.454049	29.997046
20188.047000	5773.833000	0.453811	30.003374
20190.037000	5774.521000	0.454177	29.990312
20192.077000	5774.946000	0.453981	29.999643
20194.117000	5775.432000	0.454735	29.999037
20196.117000	5775.391000	0.453556	30.000701
20198.127000	5775.978000	0.454757	29.990829
20200.137000	5776.585000	0.455708	29.991480
20202.167000	5777.172000	0.454847	29.988984
20204.187000	5777.496000	0.454386	29.997942
20206.197000	5777.698000	0.454563	30.001416
20208.267000	5778.022000	0.454888	30.006963
20210.327000	5778.528000	0.454880	30.005081
20212.377000	5778.933000	0.454079	29.996586
20214.427000	5779.378000	0.454862	30.001392
20216.487000	5780.066000	0.455169	29.990151
20218.557000	5780.106000	0.455750	29.992055
20220.598000	5780.855000	0.454907	29.997685
20222.628000	5780.895000	0.455542	29.995355
20224.678000	5781.361000	0.455687	30.001699
20226.708000	5781.766000	0.454341	30.002967
20228.748000	5782.413000	0.454934	30.012350
20230.748000	5782.656000	0.454946	30.000970
20232.758000	5783.121000	0.455117	29.995508
20234.748000	5783.830000	0.454667	30.000774
20236.778000	5783.728000	0.454005	29.998506
20238.808000	5784.275000	0.454688	30.005145
20240.868000	5784.801000	0.453991	30.007295
20242.898000	5785.064000	0.454800	29.992352
20244.928000	5785.489000	0.453797	30.005494
20246.998000	5785.894000	0.454500	29.996104
20249.068000	5786.177000	0.455391	29.991074
20251.108000	5786.905000	0.454433	29.999187
20253.128000	5786.905000	0.453988	30.010891
20255.198000	5787.776000	0.454537	29.998452
20257.228000	5787.877000	0.454092	29.995058
20259.268000	5788.221000	0.454237	30.000678
20261.298000	5788.605000	0.454333	29.995017
20263.338000	5788.868000	0.454477	30.005960
20265.338000	5789.273000	0.455067	30.001767
20267.368000	5790.305000	0.455526	29.998343
20269.398000	5790.507000	0.455042	30.006863
20271.429000	5790.629000	0.455241	30.016142
20273.489000	5791.337000	0.455457	30.005874
20275.489000	5791.519000	0.454842	29.996373
20277.579000	5791.701000	0.455055	29.994279
20279.579000	5792.066000	0.455598	29.999999
20281.619000	5792.774000	0.455871	29.995900
20283.639000	5792.936000	0.455773	29.997081
20285.659000	5793.300000	0.455314	29.999607
20287.729000	5794.089000	0.455753	30.001472
20289.799000	5794.453000	0.455329	30.000281
20291.789000	5794.797000	0.455978	30.000988
20293.829000	5795.303000	0.455626	29.991127
20295.849000	5795.364000	0.455638	29.995891
20297.829000	5795.890000	0.455682	30.008987
20299.859000	5796.113000	0.455709	30.010967
20301.889000	5796.780000	0.456343	30.001983
20303.999000	5797.408000	0.455866	30.008185
20306.029000	5797.610000	0.456076	30.000988
20308.069000	5798.217000	0.455985	30.001782
20310.089000	5798.622000	0.456040	29.989316
20312.119000	5798.743000	0.456243	29.990475
20314.149000	5799.148000	0.456396	29.993089
20316.209000	5799.877000	0.456216	29.993744
20318.249000	5800.281000	0.455817	30.005199
20320.269000	5800.706000	0.455868	29.994921
20322.259000	5801.030000	0.454564	30.001198
20324.289000	5801.536000	0.455168	29.991800
20326.359000	5801.718000	0.456561	29.997446
20328.389000	5802.224000	0.455097	29.993896
20330.389000	5802.750000	0.455903	30.000070
20332.409000	5803.054000	0.455625	29.997588
20334.459000	5803.863000	0.454206	30.011188
20336.489000	5803.742000	0.455036	30.004402
20338.489000	5804.409000	0.455278	29.993475
20340.519000	5804.753000	0.456049	29.988425
20342.589000	5805.118000	0.454958	29.994782
20344.619000	5805.462000	0.455278	29.998130
20346.649000	5805.846000	0.455032	30.007014
20348.759000	5806.514000	0.455728	29.994927
20350.829000	5806.919000	0.455880	30.003558
20352.859000	5807.060000	0.455589	29.999567
20354.889000	5807.384000	0.455504	30.003830
20356.909000	5807.748000	0.455264	30.007592
20358.950000	5808.497000	0.455886	30.000341
20360.970000	5808.639000	0.455982	29.991127
20363.050000	5808.962000	0.455524	30.006736
20365.100000	5809.489000	0.455602	29.997670
20367.130000	5809.913000	0.454471	30.010574
20369.170000	5810.055000	0.454801	29.990076
20371.190000	5810.581000	0.455095	29.993777
20373.250000	5810.925000	0.455111	29.994614
20375.290000	5811.816000	0.454521	30.006923
20377.310000	5812.079000	0.455149	29.996667
20379.360000	5812.423000	0.455023	30.001463
20381.380000	5812.706000	0.454955	29.997560
20383.450000	5813.596000	0.453861	30.005120
20385.540000	5813.698000	0.454395	30.001864
20387.540000	5813.961000	0.454606	30.013813
20389.560000	5814.608000	0.454538	29.990709
20391.560000	5815.195000	0.454251	29.993771
20393.590000	5815.276000	0.454235	29.999483
20395.620000	5815.782000	0.454104	29.996693
20397.690000	5815.843000	0.453915	29.996051
20399.720000	5816.713000	0.454242	29.988537
20401.750000	5816.996000	0.454165	29.988194
20403.810000	5817.421000	0.453873	29.994914
20405.840000	5817.846000	0.453664	29.993592
20407.860000	5817.886000	0.452947	30.002194
20409.890000	5818.311000	0.453627	29.987533
20411.941000	5818.797000	0.453556	29.991268
20413.991000	5819.485000	0.453033	29.996177
20416.061000	5819.890000	0.453313	29.990472
20418.081000	5820.254000	0.452976	29.996698
20420.071000	5820.679000	0.453228	30.008814
20422.061000	5820.922000	0.453599	29.993209
20424.141000	5821.286000	0.453410	29.999936
20426.201000	5821.326000	0.453140	29.994570
20428.231000	5821.893000	0.453973	29.999159
20430.271000	5822.682000	0.454782	30.000894
20432.291000	5823.067000	0.453858	30.001572
20434.331000	5823.350000	0.453531	30.009294
20436.341000	5823.998000	0.453201	30.013076
20438.331000	5824.079000	0.453929	30.003666
20440.361000	5824.908000	0.454174	30.002096
20442.391000	5825.353000	0.453759	29.991502
20444.451000	5825.434000	0.453376	30.011064
20446.451000	5825.738000	0.452964	30.004390
20448.481000	5826.264000	0.453562	29.990056
20450.521000	5826.628000	0.453344	29.989641
20452.511000	5827.235000	0.453598	29.994791
20454.551000	5827.438000	0.452750	30.005152
20456.551000	5827.822000	0.453474	29.990963
20458.581000	5828.166000	0.453839	29.993179
20460.621000	5828.976000	0.453544	30.003653
20462.661000	5829.137000	0.453623	29.997988
20464.721000	5829.441000	0.453612	30.003078
20466.781000	5829.886000	0.452964	29.995955
20468.811000	5830.412000	0.453952	29.990247
20470.771000	5830.635000	0.453096	30.002734
20472.821000	5831.121000	0.453167	29.997127
20474.891000	5831.687000	0.452945	29.991944
20476.961000	5831.849000	0.453538	29.992208
20479.001000	5832.314000	0.453870	29.996952
20481.032000	5832.922000	0.453676	29.998815
20483.052000	5833.124000	0.452962	29.999587
20485.122000	5833.650000	0.453610	30.003596
20487.102000	5833.893000	0.453374	30.015744
20489.222000	5834.055000	0.453663	30.014210
20491.332000	5834.803000	0.454344	29.995339
20493.342000	5835.026000	0.453612	30.004396
20495.392000	5836.159000	0.454109	29.997797
20497.402000	5835.896000	0.453755	30.000017
20499.432000	5836.483000	0.452855	30.004449
20501.532000	5836.948000	0.453211	29.990953
20503.562000	5837.414000	0.453046	30.003721
20505.622000	5837.677000	0.452859	30.009781
20507.652000	5838.041000	0.453280	30.001324
20509.612000	5838.405000	0.453785	29.991472
20511.642000	5838.547000	0.454197	30.003909
20513.682000	5839.478000	0.454326	29.998659
20515.702000	5839.518000	0.454142	30.007951
20517.762000	5840.206000	0.455301	29.991297
20519.762000	5840.571000	0.454489	29.994345
20521.792000	5840.652000	0.454498	29.991954
20523.822000	5841.542000	0.453818	30.004309
20525.862000	5841.886000	0.453984	30.014269
20527.892000	5841.866000	0.454110	29.998920
20529.942000	5842.513000	0.454068	30.001184
20531.932000	5843.120000	0.453770	30.007129
20533.982000	5843.242000	0.454089	29.996611
20536.032000	5843.748000	0.453748	30.000427
20538.062000	5844.051000	0.454502	29.995357
20540.102000	5845.002000	0.454846	29.995209
20542.122000	5845.103000	0.453851	30.002119
20544.152000	5845.002000	0.454807	30.002569
20546.172000	5845.751000	0.454084	30.001091
20548.202000	5846.115000	0.453674	30.002469
20550.262000	5846.763000	0.454227	29.993041
20552.353000	5846.783000	0.454519	29.992020
20554.403000	5847.350000	0.453980	30.000786
20556.433000	5847.673000	0.454678	29.996989
20558.473000	5848.240000	0.454394	30.001652
20560.553000	5848.564000	0.454378	30.011581
20562.563000	5849.353000	0.454917	30.005653
20564.623000	5849.535000	0.456402	29.995197
20566.623000	5849.839000	0.454598	30.010637
20568.653000	5850.041000	0.454600	30.006455
20570.753000	5850.648000	0.454530	30.005975
20572.783000	5851.235000	0.454486	30.002769
20574.833000	5851.599000	0.455128	29.993797
20576.863000	5851.862000	0.455407	29.988873
20578.873000	5852.004000	0.454531	29.982935
20580.903000	5852.753000	0.454571	29.992552
20582.933000	5852.732000	0.454426	29.987297
20584.983000	5853.501000	0.454839	30.000396
20587.003000	5853.866000	0.454763	29.998384
20589.044000	5854.392000	0.454441	29.998503
20591.014000	5854.756000	0.453865	30.015260
20593.034000	5855.201000	0.454362	30.003762
20595.084000	5855.748000	0.454098	30.005115
20597.084000	5855.950000	0.454846	29.990832
20599.114000	5856.537000	0.454711	29.991021
20601.144000	5856.436000	0.455378	29.989650
20603.214000	5856.901000	0.454610	29.989917
20605.245000	5857.629000	0.454152	29.997210
20607.275000	5858.075000	0.454695	29.999916
20609.325000	5858.257000	0.454692	30.001677
20611.355000	5858.823000	0.453831	30.003976
20613.405000	5859.167000	0.454255	29.997771
20615.385000	5859.754000	0.453965	29.996289
20617.415000	5859.693000	0.453865	29.997759
20619.445000	5860.179000	0.454504	29.995108
20621.485000	5860.827000	0.454464	29.995185
20623.505000	5861.191000	0.454690	29.999057
20625.535000	5861.596000	0.454648	30.004987
20627.575000	5862.122000	0.453464	30.004689
20629.605000	5862.587000	0.454858	29.991555
20631.655000	5862.607000	0.454409	29.989555
20633.715000	5863.255000	0.454448	30.001334
20635.715000	5863.842000	0.453479	30.001797
20637.745000	5864.125000	0.454240	29.996151
20639.775000	5864.530000	0.453730	30.005173
20641.815000	5864.813000	0.454057	30.000700
20643.825000	5865.198000	0.454718	30.004422
20645.845000	5865.683000	0.454713	29.994603
20647.885000	5865.906000	0.454310	29.999753
20649.935000	5866.371000	0.454786	29.998916
20651.955000	5866.897000	0.454130	30.004489
20653.985000	5867.262000	0.454003	30.012207
20655.965000	5867.808000	0.454192	29.999313
20657.995000	5868.233000	0.453884	29.997821
20660.025000	5868.415000	0.453882	30.009963
20662.055000	5868.759000	0.454007	30.001146
20664.085000	5869.204000	0.454430	29.990832
20666.155000	5869.751000	0.453656	29.996753
20668.175000	5870.196000	0.454858	30.011741
20670.205000	5870.499000	0.454391	30.004375
20672.235000	5871.066000	0.454610	30.003022
20674.265000	5871.572000	0.453651	30.005915
20676.335000	5871.815000	0.454567	29.994210
20678.365000	5872.138000	0.454273	29.992669
20680.445000	5872.503000	0.453991	29.989070
20682.465000	5872.968000	0.454289	29.992807
20684.505000	5873.292000	0.454129	29.990062
20686.595000	5873.656000	0.454575	29.995877
20688.625000	5874.122000	0.454955	29.996176
20690.665000	5874.567000	0.454956	30.012808
20692.766000	5875.012000	0.454759	30.004912
20694.836000	5875.579000	0.453991	30.011035
20696.856000	5875.680000	0.454759	30.009493
20698.886000	5876.590000	0.454704	30.000795
20700.956000	5876.671000	0.454720	30.010592
20702.986000	5877.036000	0.455172	30.010884
20705.016000	5877.440000	0.455428	30.002052
20707.046000	5877.764000	0.456292	29.993113
20709.076000	5878.209000	0.455146	30.014986
20711.116000	5878.553000	0.455830	30.002492
20713.176000	5879.160000	0.455562	30.004549
20715.236000	5879.261000	0.455613	30.000863
20717.286000	5879.484000	0.456090	29.997067
20719.336000	5880.455000	0.455528	30.001572
20721.366000	5880.759000	0.456691	29.996476
20723.426000	5881.103000	0.456393	29.999203
20725.416000	5881.427000	0.455342	29.994632
20727.456000	5882.034000	0.455396	30.003386
20729.556000	5882.297000	0.456691	30.003471
20731.546000	5882.661000	0.455968	30.011688
20733.586000	5883.086000	0.456434	29.999238
20735.656000	5883.369000	0.456057	30.000181
20737.686000	5884.179000	0.456315	29.998960
20739.706000	5884.361000	0.455908	29.987710
20741.726000	5885.170000	0.456648	30.001568
20743.776000	5885.231000	0.456469	30.008434
20745.836000	5885.595000	0.455877	30.011578
20747.846000	5886.182000	0.455537	30.007049
20749.846000	5886.789000	0.456542	29.998077
20751.916000	5886.931000	0.455840	30.008070
20753.946000	5887.174000	0.456375	29.991081
20755.986000	5887.943000	0.455559	29.990490
20758.046000	5888.024000	0.456173	29.987618
20760.106000	5888.226000	0.456442	29.989382
20762.156000	5889.197000	0.456084	30.003774
20764.166000	5889.420000	0.455749	29.997331
20766.236000	5889.986000	0.455866	30.001337
20768.346000	5890.270000	0.455675	30.006694
20770.386000	5890.715000	0.455739	30.009734
20772.376000	5891.221000	0.455063	29.997824
20774.406000	5891.302000	0.455293	29.995056
20776.416000	5891.484000	0.455484	29.997336
20778.466000	5892.172000	0.455398	30.009393
20780.536000	5892.475000	0.456166	29.997623
20782.546000	5892.981000	0.456078	29.995986
20784.576000	5893.568000	0.456137	29.994724
20786.606000	5894.013000	0.455918	29.995679
20788.636000	5894.418000	0.455052	30.000374
20790.636000	5894.580000	0.455337	30.005057
20792.646000	5895.207000	0.455505	29.996275
20794.686000	5895.389000	0.455550	29.998173
20796.726000	5896.037000	0.454996	30.005588
20798.746000	5896.361000	0.455396	30.006341
20800.776000	5896.583000	0.455665	29.996220
20802.817000	5897.008000	0.454939	29.997892
20804.817000	5897.474000	0.455304	29.999792
20806.847000	5897.980000	0.454964	30.004667
20808.917000	5898.222000	0.455518	29.989888
20810.947000	5898.870000	0.454723	30.002816
20813.017000	5898.708000	0.455348	29.992965
20815.057000	5899.416000	0.455366	29.989856
20817.077000	5899.639000	0.455462	30.001765
20819.117000	5900.529000	0.455799	29.999609
20821.147000	5900.691000	0.455952	30.002330
20823.167000	5901.480000	0.455482	30.005252
20825.197000	5901.946000	0.455216	29.990410
20827.297000	5901.986000	0.454780	29.998657
20829.327000	5902.553000	0.454344	30.000696
20831.367000	5903.039000	0.455024	29.993674
20833.387000	5903.322000	0.454530	29.991658
20835.417000	5903.888000	0.454405	29.997711
20837.497000	5903.828000	0.454352	29.989268
20839.517000	5904.779000	0.453771	29.998030
20841.537000	5905.022000	0.453171	30.002116
20843.527000	5905.204000	0.453268	30.006996
20845.607000	5905.629000	0.453498	29.999753
20847.607000	5906.438000	0.454425	30.002922
20849.617000	5906.519000	0.453725	29.995595
20851.647000	5906.802000	0.454228	29.991957
20853.677000	5907.025000	0.453512	29.991851
20855.717000	5907.834000	0.453939	30.000377
20857.757000	5908.158000	0.454037	29.992402
20859.767000	5908.441000	0.453313	30.006111
20861.787000	5909.049000	0.453718	30.008395
20863.817000	5909.393000	0.453561	30.011704
20865.857000	5909.595000	0.454061	29.998231
20867.887000	5910.040000	0.453789	30.004884
20869.907000	5910.344000	0.453493	30.009178
20871.977000	5910.789000	0.453752	29.999523
20873.977000	5911.295000	0.453841	30.002411
20875.997000	5912.104000	0.453680	29.993820
20878.007000	5912.023000	0.453355	30.002189
20880.047000	5912.630000	0.453414	30.001113
20882.087000	5913.075000	0.453790	29.999793
20884.148000	5913.561000	0.453301	30.002232
20886.178000	5913.541000	0.453935	29.999337
20888.218000	5914.047000	0.453437	29.998568
20890.228000	5914.613000	0.453709	29.993038
20892.258000	5915.038000	0.453629	29.991195
20894.338000	5915.463000	0.453688	29.991841
20896.388000	5916.212000	0.453349	30.000822
20898.428000	5916.172000	0.453411	29.995317
20900.478000	5916.617000	0.453165	29.989537
20902.498000	5917.264000	0.453205	29.992741
20904.508000	5917.426000	0.453793	30.004203
20906.538000	5917.790000	0.453166	30.000970
20908.608000	5918.195000	0.453463	29.998779
20910.638000	5918.762000	0.453939	29.989859
20912.678000	5919.227000	0.453528	29.989562
20914.708000	5919.490000	0.453604	29.993293
20916.728000	5919.531000	0.453162	29.995727
20918.768000	5920.178000	0.453752	29.993131
20920.798000	5920.623000	0.453778	29.997630
20922.788000	5921.150000	0.453949	29.995090
20924.798000	5921.291000	0.452959	30.004458
20926.848000	5921.797000	0.453556	30.004401
20928.858000	5922.242000	0.453687	29.993463
20930.928000	5922.768000	0.453663	30.000253
20932.959000	5923.254000	0.453873	29.991908
20934.979000	5923.598000	0.453879	29.993086
20936.969000	5923.760000	0.453118	30.014118
20939.000000	5924.488000	0.454201	30.006921
20941.010000	5924.934000	0.454057	30.001113
20943.010000	5924.853000	0.454039	29.992772
20945.010000	5925.520000	0.454277	29.993216
20947.041000	5926.047000	0.454926	29.991861
20949.101000	5926.148000	0.454476	30.010091
20951.091000	5926.795000	0.454306	30.007054
20953.131000	5926.896000	0.454530	29.996353
20955.121000	5927.342000	0.454402	29.987430
20957.171000	5928.009000	0.454161	29.995163
20959.201000	5928.617000	0.454629	29.995522
20961.241000	5928.880000	0.454194	30.000487
20963.271000	5928.900000	0.455154	29.999102
20965.341000	5929.790000	0.454535	30.007326
20967.381000	5929.912000	0.454641	30.000676
20969.381000	5930.074000	0.453546	30.000024
20971.491000	5930.984000	0.454885	29.996187
20973.601000	5931.267000	0.455137	29.992799
20975.631000	5931.510000	0.454122	30.006945
20977.661000	5931.895000	0.454016	29.995569
20979.751000	5932.380000	0.454138	30.006830
20981.751000	5932.846000	0.454846	29.996080
20983.801000	5932.886000	0.454508	30.000213
20985.871000	5933.878000	0.454114	29.997782
20987.881000	5934.060000	0.453685	30.002665
20989.931000	5934.627000	0.454580	30.003663
20991.951000	5935.052000	0.454633	29.996589
20993.981000	5935.375000	0.454135	30.002459
20996.001000	5935.517000	0.454999	30.006061
20998.051000	5936.266000	0.454324	30.001650
21000.051000	5936.529000	0.453855	30.011416
21002.091000	5936.974000	0.454239	30.014696
21004.111000	5937.338000	0.453937	30.008042
21006.142000	5937.783000	0.453920	30.005119
21008.252000	5938.451000	0.454635	30.002435
21010.292000	5938.411000	0.454553	29.995577
21012.312000	5939.119000	0.454538	29.996023
21014.372000	5939.605000	0.454269	30.009700
21016.402000	5939.807000	0.454628	30.010199
21018.462000	5940.070000	0.454594	30.003957
21020.492000	5940.535000	0.453799	29.998312
21022.492000	5941.082000	0.453953	30.007348
21024.532000	5941.284000	0.454101	30.000759
21026.592000	5941.709000	0.454482	30.003819
21028.622000	5942.174000	0.453731	30.000422
21030.662000	5942.741000	0.453589	30.007287
21032.682000	5943.085000	0.453873	30.002776
21034.702000	5943.510000	0.453822	30.000542
21036.782000	5944.056000	0.454162	29.997236
21038.802000	5944.380000	0.454172	30.002028
21040.802000	5944.663000	0.454108	30.001002
21042.813000	5944.967000	0.453672	30.010813
21044.853000	5945.291000	0.454538	30.001815
21046.873000	5945.918000	0.454260	30.019128
21048.913000	5946.282000	0.454306	30.006204
21050.963000	5946.586000	0.454965	30.007414
21053.033000	5946.889000	0.454948	30.009400
21055.063000	5947.618000	0.453724	30.006018
21057.093000	5948.002000	0.454749	30.007725
21059.143000	5948.448000	0.454572	29.998875
21061.193000	5948.549000	0.454644	30.014488
21063.233000	5949.297000	0.454611	30.002911
21065.213000	5949.480000	0.453514	30.011774
21067.243000	5950.107000	0.454220	30.013903
21069.273000	5950.087000	0.454647	30.008504
21071.303000	5950.633000	0.455316	30.006532
21073.363000	5951.220000	0.454361	30.005354
21075.393000	5951.503000	0.455761	30.004659
21077.423000	5951.948000	0.455162	29.999441
21079.453000	5952.353000	0.455235	30.001545
21081.483000	5953.021000	0.455469	30.003545
21083.533000	5952.920000	0.455339	30.000979
21085.583000	5953.830000	0.455190	30.000837
21087.643000	5953.891000	0.455147	30.006814
21089.673000	5954.195000	0.455128	30.001242
21091.703000	5954.761000	0.455292	30.010130
21093.783000	5955.550000	0.455899	30.003741
21095.843000	5955.874000	0.455275	29.993204
21097.883000	5955.996000	0.454782	30.009115
21099.943000	5956.522000	0.455023	30.005758
21101.973000	5956.866000	0.455706	30.006609
21104.003000	5957.311000	0.455337	30.006432
21106.063000	5957.797000	0.455590	29.998964
21108.093000	5958.120000	0.454739	29.996742
21110.133000	5958.626000	0.454631	29.996672
21112.184000	5958.829000	0.454991	29.998787
21114.214000	5959.253000	0.455224	30.004282
21116.284000	5959.840000	0.454682	29.995004
21118.354000	5959.962000	0.454551	30.009788
21120.384000	5960.630000	0.455138	30.004255
21122.414000	5961.297000	0.455696	29.995507
21124.434000	5961.398000	0.454309	30.004873
21126.454000	5961.742000	0.455267	30.006747
21128.464000	5961.884000	0.455084	30.010154
21130.524000	5962.471000	0.456082	30.002858
21132.534000	5963.017000	0.455699	30.004974
21134.574000	5963.604000	0.454931	30.009266
21136.544000	5963.665000	0.455743	29.993081
21138.604000	5964.130000	0.455564	30.005582
21140.634000	5964.758000	0.455985	29.994402
21142.654000	5964.899000	0.455638	30.007264
21144.684000	5965.324000	0.455809	30.002255
21146.734000	5965.850000	0.455824	30.000289
21148.764000	5966.073000	0.455600	29.999938
21150.774000	5966.478000	0.456258	30.006591
21152.804000	5967.064000	0.455599	30.004624
21154.834000	5967.409000	0.455636	29.996863
21156.904000	5967.813000	0.455393	30.010119
21158.934000	5968.076000	0.455329	30.002476
21160.954000	5968.562000	0.455988	30.004101
21163.004000	5969.452000	0.456156	29.998593
21165.024000	5969.594000	0.455573	30.000123
21167.074000	5969.978000	0.455913	30.007103
21169.124000	5970.464000	0.455537	30.007403
21171.154000	5970.666000	0.455363	29.994806
21173.184000	5971.334000	0.455860	30.000726
21175.254000	5971.435000	0.456077	29.994155
21177.274000	5972.265000	0.455294	29.994399
21179.354000	5972.387000	0.456348	30.005318
21181.375000	5972.731000	0.456293	29.998496
21183.395000	5973.196000	0.455871	30.004058
21185.505000	5973.904000	0.456099	30.004189
21187.535000	5973.843000	0.456335	29.996001
21189.565000	5974.552000	0.455935	29.999073
21191.625000	5974.896000	0.454953	30.006853
21193.655000	5975.280000	0.455472	29.996558
21195.645000	5975.543000	0.455862	30.007435
21197.675000	5976.069000	0.455032	30.008812
21199.715000	5976.312000	0.455510	29.994861
21201.765000	5977.041000	0.455378	29.995578
21203.765000	5977.263000	0.454995	29.988001
21205.795000	5977.526000	0.455610	29.996974
21207.835000	5978.053000	0.454769	30.014925
21209.865000	5978.295000	0.455703	30.001269
21211.875000	5978.983000	0.454914	30.001202
21213.905000	5979.348000	0.454924	30.001101
21215.905000	5979.651000	0.455125	30.006148
21217.965000	5980.015000	0.455234	30.001523
21220.035000	5980.663000	0.454712	29.999904
21222.065000	5980.845000	0.455889	29.995806
21224.095000	5981.149000	0.455604	29.984594
21226.125000	5981.513000	0.454980	29.990194
21228.145000	5982.241000	0.454736	30.001012
21230.175000	5982.626000	0.456031	29.985081
21232.225000	5983.213000	0.455270	29.996946
21234.275000	5983.577000	0.455262	29.985554
21236.345000	5983.658000	0.455278	29.994260
21238.415000	5984.467000	0.454822	30.003072
21240.455000	5984.326000	0.454747	30.000674
21242.475000	5984.832000	0.455068	29.995913
21244.485000	5985.398000	0.455560	29.990109
21246.495000	5985.803000	0.455217	29.991766
21248.565000	5986.309000	0.454130	30.002525
21250.595000	5986.794000	0.454653	29.989256
21252.625000	5987.280000	0.454638	29.992909
21254.725000	5987.422000	0.455562	29.991205
21256.755000	5987.806000	0.453865	29.993793
21258.815000	5988.474000	0.453118	30.004470
21260.835000	5988.899000	0.453671	29.996582
21262.845000	5988.798000	0.453411	30.001654
21264.865000	5989.324000	0.453964	30.000165
21266.895000	5989.769000	0.453577	30.001327
21268.935000	5990.336000	0.453662	29.992699
21270.955000	5990.781000	0.453669	29.998348
21272.985000	5990.983000	0.454352	29.998941
21275.015000	5991.570000	0.452652	30.004686
21277.055000	5992.096000	0.453532	29.986766
21279.115000	5992.643000	0.453466	29.993287
21281.145000	5992.906000	0.453266	29.992986
21283.175000	5993.088000	0.453878	29.991004
21285.195000	5993.594000	0.453346	30.000729
21287.205000	5994.140000	0.452714	29.994555
21289.205000	5994.464000	0.453547	29.997148
21291.215000	5994.686000	0.453327	29.997376
21293.235000	5995.132000	0.453234	30.002743
21295.265000	5995.739000	0.453509	29.997698
21297.331000	5996.123000	0.453466	30.001181
21299.341000	5996.629000	0.453450	29.995113
21301.351000	5996.831000	0.453990	29.991011
21303.382000	5997.297000	0.453036	29.998161
21305.432000	5997.742000	0.454030	29.996513
21307.452000	5998.005000	0.453179	29.990287
21309.482000	5998.511000	0.453686	29.997166
21311.552000	5998.572000	0.454188	29.996767
21313.582000	5999.462000	0.453589	30.001741
21315.672000	5999.624000	0.454498	29.985257
21317.762000	6000.271000	0.454325	29.993421
21319.822000	6000.656000	0.455272	29.989485
21321.862000	6002.821000	0.461043	29.990136
21323.882000	6006.504000	0.468306	30.000784
21325.952000	6010.511000	0.473564	30.010673
21327.982000	6014.882000	0.476180	30.020016
21330.002000	6018.544000	0.479133	30.026595
21332.072000	6022.935000	0.481243	30.027791
21334.102000	6026.598000	0.482151	30.030067
21336.162000	6030.686000	0.483539	30.043250
21338.232000	6035.198000	0.484577	30.032353
21340.242000	6039.165000	0.485438	30.038322
21342.272000	6043.576000	0.486133	30.040329
21344.332000	6047.360000	0.487098	30.035447
21346.352000	6051.589000	0.487554	30.039392
21348.382000	6055.070000	0.489043	30.038379
21350.452000	6059.238000	0.489115	30.046761
21352.482000	6063.670000	0.489801	30.051193
21354.512000	6068.061000	0.490923	30.042827
21356.582000	6072.715000	0.491160	30.035613
21358.612000	6076.904000	0.490834	30.043776
21360.652000	6080.709000	0.490766	30.038599
21362.672000	6084.857000	0.491259	30.021442
21364.712000	6088.884000	0.491702	30.028276
21366.722000	6092.627000	0.491550	30.040988
21368.712000	6096.209000	0.492250	30.034821
21370.752000	6100.297000	0.492753	30.032877
21372.812000	6104.688000	0.492549	30.028744
21374.842000	6107.804000	0.493525	30.018970
21376.842000	6112.661000	0.494347	30.014014
21378.862000	6116.405000	0.494524	30.021454
21380.912000	6120.796000	0.493946	30.024806
21382.962000	6124.620000	0.494602	30.024601
21385.062000	6128.667000	0.495572	30.025983
21387.082000	6133.059000	0.495508	30.024331
21389.092000	6136.741000	0.496469	30.030728
21391.162000	6140.910000	0.497321	30.020093
21393.142000	6145.240000	0.496734	30.025689
21395.172000	6149.207000	0.496306	30.019373
21397.202000	6153.578000	0.497595	30.023019
21399.232000	6157.847000	0.497009	30.024226
21401.262000	6162.137000	0.496359	30.027040
21403.302000	6165.679000	0.496505	30.029263
21405.312000	6169.726000	0.495557	30.019150
21407.342000	6173.834000	0.495774	30.028734
21409.412000	6178.164000	0.495896	30.029570
21411.482000	6182.029000	0.496313	30.023209
21413.552000	6185.955000	0.497144	30.028017
21415.582000	6190.285000	0.496570	30.032386
21417.632000	6194.130000	0.497766	30.028976
21419.652000	6198.137000	0.497932	30.039654
21421.672000	6202.386000	0.497898	30.036641
21423.692000	6206.474000	0.497459	30.027706
21425.692000	6210.157000	0.497739	30.029559
21427.712000	6213.941000	0.498758	30.027761
21429.712000	6218.433000	0.498223	30.032723
21431.742000	6222.521000	0.498677	30.038042
21433.772000	6226.750000	0.498060	30.037772
21435.802000	6230.352000	0.498458	30.037310
21437.782000	6234.076000	0.498987	30.040313
21439.802000	6238.001000	0.498488	30.041746
21441.802000	6242.655000	0.499384	30.040000
21443.822000	6246.804000	0.499403	30.035906
21445.832000	6251.316000	0.499346	30.031158
21447.922000	6255.505000	0.498244	30.037641
21449.962000	6259.330000	0.497954	30.032692
21451.992000	6262.912000	0.498119	30.035871
21454.012000	6267.019000	0.498365	30.033575
21456.032000	6270.662000	0.498309	30.030876
21458.062000	6274.952000	0.499440	30.023405
21460.092000	6279.060000	0.498958	30.036903
21462.162000	6283.127000	0.499207	30.031254
21464.202000	6287.538000	0.498238	30.025288
21466.242000	6291.221000	0.499446	30.020060
21468.252000	6295.451000	0.500284	30.019507
21470.282000	6299.154000	0.499721	30.019804
21472.302000	6303.383000	0.500261	30.013582
21474.362000	6307.734000	0.499571	30.014020
21476.442000	6311.579000	0.500625	30.017000
21478.492000	6316.091000	0.500537	30.010801
21480.552000	6320.098000	0.501805	30.011522
21482.662000	6324.185000	0.501329	30.006772
21484.762000	6328.779000	0.500566	30.010715
21486.832000	6333.109000	0.499517	30.012358
21488.872000	6336.732000	0.499455	30.002642
21490.902000	6340.819000	0.499587	30.008595
21492.912000	6345.109000	0.499524	30.003708
21494.942000	6348.893000	0.500394	30.012038
21497.012000	6353.628000	0.500210	30.007049
21499.062000	6357.473000	0.499933	30.001185
21501.102000	6361.500000	0.500318	30.002008
21503.152000	6365.406000	0.500101	30.003370
21505.172000	6369.230000	0.499881	30.004357
21507.192000	6373.581000	0.501387	30.013720
21509.262000	6377.507000	0.500205	30.009294
21511.372000	6381.493000	0.500506	29.999986
21513.413000	6386.066000	0.499696	29.999463
21515.413000	6389.911000	0.500110	30.010773
21517.493000	6393.675000	0.499850	30.003941
21519.523000	6398.147000	0.501195	30.000708
21521.553000	6401.668000	0.500955	29.995882
21523.593000	6405.978000	0.501699	30.006037
21525.623000	6410.572000	0.500902	30.003731
21527.633000	6414.579000	0.501005	30.013331
21529.663000	6418.423000	0.500816	30.013375
21531.713000	6422.632000	0.500712	30.003391
21533.743000	6427.024000	0.500947	30.010255
21535.833000	6431.233000	0.500065	30.006739
21537.873000	6435.017000	0.500574	30.001805
21539.903000	6439.023000	0.500263	30.001337
21541.953000	6443.172000	0.500498	30.002371
21543.993000	6446.248000	0.500445	30.016478
21546.023000	6450.841000	0.501438	30.007831
21548.103000	6455.414000	0.501744	30.008641
21550.123000	6459.563000	0.501872	30.001642
21552.113000	6463.488000	0.500613	30.003203
21554.133000	6467.394000	0.500758	30.003747
21556.213000	6471.441000	0.500763	29.994713
21558.233000	6475.488000	0.501765	29.997130
21560.313000	6479.738000	0.501544	30.005140
21562.353000	6483.542000	0.501502	30.000186
21564.363000	6487.670000	0.501699	30.011226
21566.353000	6491.596000	0.502035	30.002406
21568.393000	6495.785000	0.501232	30.007534
21570.433000	6500.237000	0.502251	30.008497
21572.483000	6504.345000	0.501491	30.003196
21574.503000	6508.776000	0.500164	30.003382
21576.533000	6512.580000	0.500691	30.005165
21578.533000	6516.567000	0.499677	30.005495
21580.613000	6520.047000	0.499701	30.007713
21582.663000	6524.176000	0.499952	29.994129
21584.693000	6527.737000	0.501245	30.006734
21586.723000	6532.634000	0.501876	30.000442
21588.743000	6537.066000	0.501527	30.003479
21590.783000	6540.971000	0.501745	30.003291
21592.813000	6544.998000	0.501052	30.002386
21594.843000	6548.964000	0.500242	30.005381
21596.863000	6552.910000	0.500409	30.002585
21598.883000	6556.775000	0.501283	29.999363
21600.923000	6560.964000	0.501587	30.001143
21602.893000	6564.930000	0.501308	30.002659
21604.953000	6568.876000	0.501432	30.006548
21607.013000	6572.721000	0.501603	30.006671
21609.043000	6576.283000	0.502344	30.000997
21611.063000	6581.079000	0.502763	30.004552
21613.093000	6585.105000	0.502396	29.996418
21615.153000	6589.578000	0.501787	30.003731
21617.183000	6593.807000	0.501421	30.002361
21619.183000	6597.915000	0.501162	30.006874
21621.323000	6602.306000	0.500722	30.002575
21623.353000	6606.272000	0.500130	29.999554
21625.383000	6609.975000	0.500831	29.998068
21627.413000	6614.285000	0.500222	30.005731
21629.443000	6617.908000	0.501268	30.009003
21631.473000	6622.481000	0.501450	30.013391
21633.543000	6626.346000	0.501342	29.999917
21635.563000	6630.029000	0.502059	29.991356
21637.603000	6634.117000	0.501377	30.004124
21639.613000	6638.386000	0.502305	29.999194
21641.653000	6642.474000	0.502570	30.003158
21643.693000	6646.481000	0.502211	30.006774
21645.723000	6650.427000	0.502746	30.003644
21647.743000	6654.109000	0.503083	30.001817
21649.753000	6658.116000	0.503942	30.001246
21651.813000	6662.548000	0.503635	30.007630
21653.833000	6666.696000	0.503617	30.000950
21655.843000	6670.946000	0.503387	30.001071
21657.843000	6674.932000	0.502345	29.998414
21659.873000	6678.858000	0.501488	30.013139
21661.913000	6683.209000	0.502294	30.010038
21663.933000	6687.154000	0.501422	30.005884
21665.963000	6691.384000	0.501611	30.010899
21667.993000	6695.310000	0.501517	29.999923
21670.033000	6699.195000	0.501965	29.996590
21672.053000	6703.019000	0.501034	29.999364
21674.053000	6707.330000	0.501975	29.996634
21676.063000	6711.093000	0.502017	29.996707
21678.133000	6715.222000	0.502626	30.000917
21680.163000	6719.592000	0.502207	29.998095
21682.203000	6723.700000	0.501825	29.999030
21684.243000	6727.828000	0.502334	29.998270
21686.243000	6731.329000	0.501922	30.010627
21688.284000	6735.538000	0.501739	30.004876
21690.284000	6739.262000	0.502276	30.000729
21692.294000	6743.147000	0.502670	30.001436
21694.324000	6747.639000	0.503758	30.002077
21696.344000	6751.363000	0.503646	30.001295
21698.354000	6755.693000	0.502595	30.008188
21700.364000	6759.821000	0.503102	29.996724
21702.404000	6764.374000	0.502593	30.009696
21704.424000	6768.401000	0.502081	30.006470
21706.464000	6772.388000	0.502176	29.995561
21708.484000	6776.354000	0.501740	30.007762
21710.524000	6780.320000	0.501504	30.002738
21712.554000	6784.246000	0.502146	30.005097
21714.574000	6788.050000	0.502345	29.996423
21716.594000	6792.461000	0.502127	30.001249
21718.674000	6796.468000	0.502043	30.001974
21720.694000	6800.475000	0.501922	30.004792
21722.694000	6804.461000	0.502230	30.006808
21724.724000	6808.751000	0.502633	29.997075
21726.794000	6812.454000	0.501293	29.998505
21728.854000	6816.704000	0.502260	30.008422
21730.844000	6821.014000	0.501538	30.012967
21732.884000	6824.839000	0.501511	29.997738
21734.904000	6828.704000	0.502182	30.002087
21736.954000	6832.346000	0.502105	30.004360
21739.004000	6836.778000	0.504204	30.001954
21740.964000	6840.764000	0.504830	29.995656
21743.024000	6845.459000	0.504745	29.993174
21745.044000	6849.324000	0.503621	29.994720
21747.074000	6853.877000	0.503708	30.001601
21749.104000	6857.580000	0.502199	30.000193
21751.134000	6861.202000	0.502344	30.007300
21753.174000	6865.735000	0.502029	30.011744
21755.184000	6869.661000	0.502093	30.000510
21757.254000	6873.688000	0.502362	29.998772
21759.284000	6877.371000	0.502613	30.004488
21761.314000	6881.883000	0.504178	30.002991
21763.344000	6885.809000	0.503409	30.006697
21765.374000	6889.715000	0.504154	30.001285
21767.404000	6893.944000	0.503556	29.997066
21769.434000	6898.092000	0.503367	30.008993
21771.414000	6901.937000	0.502509	30.011463
21773.414000	6905.903000	0.502817	30.006107
21775.444000	6909.809000	0.503036	30.008787
21777.424000	6913.552000	0.503191	29.999821
21779.454000	6917.417000	0.504619	30.002678
21781.534000	6921.869000	0.503746	30.005553
21783.554000	6926.301000	0.503882	30.004358
21785.584000	6930.348000	0.503718	30.000832
21787.624000	6934.598000	0.503101	30.001633
21789.634000	6938.442000	0.504477	30.003666
21791.664000	6942.833000	0.503004	30.000093
21793.694000	6946.719000	0.503735	30.006865
21795.684000	6950.624000	0.503143	30.000590
21797.734000	6955.157000	0.502656	30.001011
21799.754000	6959.002000	0.501876	30.011623
21801.814000	6962.948000	0.502084	30.013358
21803.844000	6966.509000	0.502945	30.008329
21805.884000	6970.637000	0.502556	30.005449
21807.884000	6974.624000	0.502486	29.994927
21809.904000	6978.651000	0.502735	29.995119
21811.914000	6982.738000	0.501286	30.005106
21813.914000	6986.887000	0.501764	29.998045
21815.904000	6990.651000	0.502061	30.012617
21817.924000	6994.374000	0.502558	30.003546
21819.964000	6998.927000	0.503601	30.004056
21821.994000	7002.772000	0.504154	30.007770
21824.014000	7006.758000	0.503833	30.002526
21825.994000	7010.745000	0.503495	30.004506
21828.034000	7014.853000	0.503552	30.013620
21830.054000	7019.183000	0.503226	30.015066
21832.094000	7023.372000	0.502415	30.010811
21834.124000	7027.824000	0.502453	30.005597
21836.194000	7031.588000	0.502590	30.003894
21838.224000	7035.817000	0.502604	29.990845
21840.244000	7039.560000	0.503020	29.990153
21842.264000	7043.790000	0.502420	30.009257
21844.304000	7047.594000	0.503237	30.003029
21846.344000	7051.722000	0.503211	30.006742
21848.354000	7055.729000	0.503298	30.000158
21850.374000	7059.958000	0.502793	29.998996
21852.374000	7063.823000	0.502703	29.996705
21854.374000	7067.648000	0.503010	30.007121
21856.394000	7072.019000	0.502646	29.999813
21858.424000	7076.086000	0.502768	30.000769
21860.484000	7080.113000	0.502973	29.993837
21862.555000	7084.180000	0.501812	30.006443
21864.625000	7088.187000	0.503130	29.997572
21866.655000	7091.769000	0.503631	29.994955
21868.645000	7095.553000	0.504161	29.995488
21870.675000	7100.450000	0.503779	30.005600
21872.705000	7104.497000	0.503678	29.996063
21874.725000	7108.908000	0.503470	30.000140
21876.755000	7113.138000	0.502466	30.008223
21878.835000	7117.428000	0.502642	30.010889
21880.865000	7121.131000	0.501895	30.001965
21882.895000	7125.299000	0.502387	30.000336
21884.995000	7129.407000	0.500946	30.012068
21887.095000	7133.151000	0.501508	30.002457
21889.095000	7137.198000	0.500752	30.000406
21891.155000	7141.245000	0.501240	29.999365
21893.195000	7145.029000	0.500767	30.004695
21895.255000	7149.724000	0.501858	29.989324
21897.295000	7153.812000	0.501017	29.994929
21899.325000	7157.717000	0.501990	29.990831
21901.335000	7161.906000	0.501138	30.006725
21903.365000	7165.791000	0.501519	29.996111
21905.365000	7169.737000	0.501300	30.006344
21907.395000	7173.562000	0.501694	29.997905
21909.385000	7177.548000	0.501650	30.002665
21911.405000	7181.413000	0.501973	30.007159
21913.475000	7185.744000	0.501851	29.992634
21915.505000	7190.256000	0.501656	29.996511
21917.505000	7194.121000	0.501492	30.012413
21919.565000	7198.735000	0.500947	30.007096
21921.635000	7202.681000	0.500860	30.003762
21923.675000	7206.627000	0.501002	29.994195
21925.705000	7210.877000	0.500501	29.999083
21927.715000	7214.519000	0.500435	29.995293
21929.745000	7218.586000	0.500746	30.003165
21931.846000	7222.876000	0.500595	29.995115
21933.886000	7226.903000	0.501478	29.997945
21935.886000	7230.748000	0.501973	30.003400
21937.946000	7235.018000	0.501268	30.005158
21940.046000	7239.551000	0.501559	29.994230
21942.076000	7243.537000	0.502132	29.994333
21944.066000	7247.159000	0.501561	30.003800
21946.096000	7251.085000	0.501748	29.998508
21948.136000	7255.456000	0.501421	30.003242
21950.236000	7259.483000	0.501587	30.002830
21952.236000	7263.287000	0.500795	30.000432
21954.296000	7267.274000	0.501880	30.002643
21956.316000	7270.491000	0.502533	29.998099
21958.346000	7275.024000	0.503532	29.994245
21960.376000	7280.063000	0.503955	29.995206
21962.426000	7284.413000	0.504126	29.994806
21964.466000	7288.521000	0.503038	30.008120
21966.506000	7292.690000	0.502056	30.008742
21968.536000	7296.332000	0.500823	30.006638
21970.606000	7300.197000	0.500882	30.005453
21972.636000	7304.123000	0.501066	30.005968
21974.666000	7308.433000	0.501123	30.006884
21976.696000	7312.622000	0.501415	30.000155
21978.686000	7316.426000	0.501622	29.999109
21980.716000	7320.352000	0.501588	29.997962
21982.746000	7324.197000	0.502371	30.004871
21984.766000	7328.568000	0.502271	30.001617
21986.806000	7332.372000	0.501959	29.997932
21988.836000	7336.723000	0.502826	29.999774
21990.856000	7340.912000	0.502363	30.004825
21992.906000	7344.878000	0.503420	30.000156
21994.996000	7348.763000	0.503710	29.998809
21997.086000	7352.709000	0.502853	30.009156
21999.096000	7357.424000	0.503569	30.003198
22001.126000	7361.350000	0.502752	30.005122
22003.186000	7365.579000	0.502885	30.018204
22005.266000	7369.930000	0.501820	30.008718
22007.296000	7374.159000	0.502121	29.994780
22009.326000	7377.822000	0.501576	29.999542
22011.336000	7381.484000	0.501667	30.004114
22013.366000	7385.754000	0.501478	29.998686
22015.406000	7389.821000	0.500600	30.000482
22017.436000	7393.646000	0.501775	29.991034
22019.456000	7398.442000	0.502310	29.994003
22021.526000	7402.044000	0.501666	30.004338
22023.556000	7406.334000	0.501362	30.004858
22025.546000	7410.482000	0.501111	30.000068
22027.566000	7414.226000	0.501961	30.009499
22029.596000	7418.212000	0.501988	30.005044
22031.636000	7422.502000	0.501806	30.002374
22033.706000	7426.286000	0.501889	29.997889
22035.736000	7430.151000	0.502385	30.001614
22037.846000	7434.421000	0.502063	30.002482
22039.876000	7438.408000	0.502382	30.001661
22041.856000	7442.819000	0.502119	29.995100
22043.926000	7446.947000	0.501516	30.002434
22045.946000	7451.014000	0.501854	30.005915
22047.976000	7455.487000	0.501582	30.003626
22050.006000	7459.554000	0.502265	30.001510
22052.006000	7463.379000	0.502215	30.004860
22054.036000	7467.426000	0.501621	30.006556
22056.016000	7471.372000	0.501369	30.001826
22058.016000	7475.803000	0.501156	29.991891
22060.036000	7479.365000	0.500724	30.006624
22062.066000	7483.149000	0.502203	30.002949
22064.136000	7487.581000	0.502364	30.012929
22066.156000	7491.688000	0.501604	30.015557
22068.206000	7495.857000	0.500815	30.010663
22070.216000	7499.924000	0.501890	29.997489
22072.276000	7503.971000	0.501779	30.009282
22074.276000	7507.149000	0.502403	29.997598
22076.266000	7511.479000	0.502592	30.002442
22078.326000	7515.607000	0.502298	30.004743
22080.326000	7519.978000	0.502372	30.002370
22082.346000	7523.762000	0.502747	29.997294
22084.386000	7527.829000	0.502075	29.994580
22086.376000	7532.160000	0.502757	30.005193
22088.396000	7536.065000	0.502613	30.001825
22090.466000	7540.497000	0.501833	30.004026
22092.456000	7544.605000	0.501902	30.009203
22094.496000	7548.652000	0.501448	29.999919
22096.516000	7552.537000	0.501323	29.999961
22098.516000	7556.746000	0.500771	30.009903
22100.536000	7560.166000	0.501026	30.004247
22102.556000	7564.315000	0.500919	29.997894
22104.586000	7568.665000	0.500665	29.995460
22106.616000	7572.530000	0.500509	30.002442
22108.696000	7576.739000	0.500020	29.995143
22110.756000	7580.665000	0.500921	30.000970
22112.826000	7584.834000	0.500499	29.998347
22114.866000	7588.861000	0.499707	30.013216
22116.886000	7592.867000	0.501125	30.009389
22118.916000	7596.995000	0.500807	29.995709
22120.896000	7601.225000	0.499837	30.000749
22122.926000	7604.928000	0.500472	29.998636
22124.956000	7608.894000	0.499770	30.000213
22126.976000	7612.334000	0.500602	29.994292
22129.036000	7616.604000	0.501965	30.000580
22131.066000	7621.197000	0.501949	29.994575
22133.066000	7625.224000	0.501720	29.998384
22135.136000	7630.202000	0.501019	30.007921
22137.126000	7634.168000	0.499688	29.999524
22139.156000	7637.932000	0.499900	30.010796
22141.186000	7641.878000	0.499620	29.998983
22143.216000	7646.128000	0.499661	29.996851
22145.256000	7650.094000	0.499965	29.999866
22147.276000	7653.959000	0.499433	29.997148
22149.266000	7657.925000	0.498925	30.000648
22151.366000	7661.426000	0.500236	30.002342
22153.356000	7665.008000	0.501023	30.000736
22155.386000	7669.541000	0.500593	30.003958
22157.416000	7673.750000	0.501717	30.001267
22159.466000	7677.999000	0.501534	30.004911
22161.516000	7682.087000	0.500290	29.994140
22163.546000	7685.790000	0.500656	30.001284
22165.586000	7689.878000	0.501867	29.996385
22167.606000	7694.208000	0.500947	30.000907
22169.636000	7698.498000	0.501150	30.003463
22171.666000	7702.525000	0.500922	30.003666
22173.696000	7706.896000	0.500683	30.009054
22175.736000	7711.064000	0.499594	30.006688
22177.747000	7714.646000	0.499492	30.007234
22179.847000	7719.321000	0.499897	30.004259
22181.887000	7723.489000	0.499143	30.000233
22183.887000	7727.213000	0.498875	30.001151
22185.937000	7731.159000	0.499347	29.994112
22187.967000	7734.801000	0.498429	30.010775
22189.997000	7739.152000	0.499129	29.997420
22192.007000	7743.199000	0.499611	29.993881
22194.007000	7746.983000	0.499700	29.991465
22196.087000	7751.394000	0.499395	29.997373
22198.097000	7755.543000	0.500146	30.002458
22200.147000	7759.711000	0.499562	29.999708
22202.127000	7763.394000	0.499454	29.998729
22204.157000	7767.138000	0.498708	30.003689
22206.227000	7771.711000	0.499319	30.006880
22208.217000	7775.859000	0.498855	29.998435
22210.247000	7779.542000	0.499738	30.011156
22212.277000	7783.711000	0.499374	30.002917
22214.317000	7787.798000	0.499220	29.996584
22216.337000	7791.704000	0.499417	29.995888
22218.367000	7795.832000	0.498909	30.003897
22220.397000	7800.001000	0.498803	29.997073
22222.457000	7804.351000	0.499479	30.000713
22224.497000	7808.459000	0.498647	30.001000
22226.517000	7812.709000	0.498816	30.002152
22228.557000	7816.371000	0.497484	29.995129
22230.577000	7820.338000	0.497596	30.007330
22232.607000	7824.284000	0.497010	30.003686
22234.627000	7828.513000	0.496717	30.002585
22236.657000	7832.661000	0.497162	30.006428
22238.727000	7836.526000	0.497648	30.004182
22240.757000	7840.836000	0.497091	30.010577
22242.807000	7844.782000	0.497809	30.003822
22244.827000	7848.951000	0.497732	30.001451
22246.847000	7852.776000	0.496873	29.996627
22248.897000	7856.904000	0.498438	30.009400
22250.987000	7860.951000	0.497865	30.010893
22253.007000	7865.322000	0.497482	29.996116
22255.017000	7868.661000	0.497503	30.005195
22257.077000	7873.072000	0.498370	29.996966
22259.107000	7877.443000	0.498949	29.993182
22261.087000	7881.551000	0.498997	30.002634
22263.117000	7885.800000	0.498209	29.999240
22265.147000	7890.090000	0.497614	30.007884
22267.217000	7893.996000	0.496881	30.002487
22269.237000	7897.760000	0.496036	30.006264
22271.237000	7902.029000	0.496499	29.996233
22273.217000	7905.712000	0.497490	29.990676
22275.247000	7909.658000	0.496625	30.000739
22277.287000	7913.786000	0.497509	29.998576
22279.317000	7917.773000	0.498536	29.998575
22281.377000	7921.699000	0.497343	30.007818
22283.417000	7925.766000	0.497626	29.998866
22285.397000	7930.117000	0.498218	30.007298
22287.497000	7934.305000	0.498168	30.001362
22289.537000	7938.373000	0.496836	30.010167
22291.577000	7942.278000	0.497138	30.004223
22293.587000	7946.366000	0.497255	30.002838
22295.617000	7950.413000	0.497095	30.012436
22297.657000	7954.157000	0.496956	30.001549
22299.717000	7958.346000	0.497598	30.004612
22301.797000	7962.777000	0.497692	30.011726
22303.807000	7966.905000	0.497729	29.996258
22305.877000	7970.831000	0.497307	30.003665
22307.947000	7975.000000	0.497672	30.010195
22309.977000	7979.755000	0.497330	30.003839
22312.057000	7983.640000	0.496114	30.011464
22314.067000	7987.728000	0.497068	30.002258
22316.097000	7991.613000	0.496717	30.005841
22318.157000	7995.802000	0.496215	30.002955
22319.527000	7998.210000	0.496434	30.008975