File: velstep3_TR2_exp013_sepiolite.txt
Time(s)	Displ(microns)	Friction	EffectiveNormalstress(MPa)
18054.432000	5347.405000	0.452937	29.994215
18058.230000	5348.194000	0.453145	29.994255
18062.008000	5348.943000	0.453380	30.013922
18065.796000	5349.671000	0.453427	30.000070
18069.624000	5350.480000	0.453077	29.997178
18073.372000	5351.229000	0.452655	30.013023
18077.160000	5351.958000	0.452984	29.996610
18080.978000	5352.443000	0.453331	30.001290
18084.766000	5353.597000	0.453036	30.011379
18088.604000	5354.568000	0.452719	30.008520
18092.432000	5354.993000	0.453056	29.998000
18096.210000	5355.519000	0.453164	30.002356
18099.968000	5356.511000	0.452609	30.004146
18103.866000	5357.340000	0.453250	29.997175
18107.584000	5357.927000	0.453151	30.015302
18111.452000	5358.413000	0.453739	30.008065
18115.270000	5359.445000	0.454068	30.001417
18119.018000	5360.295000	0.454253	30.008213
18122.806000	5361.044000	0.454470	29.999775
18126.594000	5361.671000	0.453367	30.002345
18130.432000	5362.703000	0.453655	29.997108
18134.200000	5363.350000	0.454189	30.001367
18137.958000	5364.160000	0.454044	30.004161
18141.796000	5365.070000	0.454649	29.998642
18145.514000	5366.001000	0.454673	29.997004
18149.312000	5366.264000	0.453987	30.011475
18153.100000	5367.337000	0.454114	30.003545
18156.908000	5367.964000	0.453619	30.002509
18160.686000	5368.551000	0.454071	29.997703
18164.504000	5369.482000	0.454618	29.995561
18168.252000	5370.069000	0.453670	30.004466
18172.060000	5370.656000	0.454069	30.005313
18175.868000	5371.586000	0.454118	30.010647
18179.696000	5372.598000	0.454024	29.994622
18183.534000	5373.246000	0.454119	29.988169
18187.312000	5373.954000	0.453847	30.004036
18191.110000	5374.581000	0.453957	29.993338
18194.898000	5375.492000	0.453153	30.013977
18198.646000	5376.241000	0.454058	30.001109
18202.414000	5376.949000	0.452920	29.998993
18206.202000	5377.576000	0.452979	30.003691
18210.040000	5378.649000	0.454184	29.992161
18213.838000	5379.418000	0.453122	29.992804
18217.566000	5379.924000	0.453613	29.993976
18221.354000	5380.895000	0.452155	30.007956
18225.222000	5381.421000	0.452802	29.993048
18228.970000	5382.615000	0.453074	29.995302
18232.758000	5383.323000	0.453103	29.989622
18236.466000	5383.890000	0.451979	30.002580
18240.255000	5384.861000	0.452227	29.996577
18244.033000	5385.347000	0.452292	29.995664
18247.821000	5386.136000	0.452295	29.985527
18251.649000	5386.925000	0.452427	29.999612
18255.517000	5387.613000	0.452078	29.986766
18259.305000	5388.605000	0.451162	30.003734
18263.084000	5389.171000	0.451307	29.991904
18266.892000	5389.859000	0.452006	29.990558
18270.710000	5390.972000	0.452146	29.991638
18274.448000	5391.397000	0.452127	30.004755
18278.246000	5392.267000	0.452027	29.991019
18282.064000	5393.117000	0.451072	29.997824
18285.862000	5393.886000	0.450635	29.999652
18289.740000	5394.797000	0.451411	29.995468
18293.538000	5394.938000	0.450710	30.001639
18297.366000	5395.869000	0.451569	29.994547
18301.134000	5396.780000	0.451948	29.990745
18304.942000	5397.691000	0.451518	30.000990
18308.690000	5398.217000	0.450868	30.004899
18312.518000	5399.249000	0.451179	29.992115
18316.377000	5399.694000	0.451313	29.989442
18320.175000	5400.746000	0.451774	29.995076
18323.913000	5401.272000	0.451921	29.997683
18327.711000	5402.284000	0.451168	30.002431
18331.499000	5403.013000	0.451147	30.006284
18335.277000	5403.458000	0.450613	30.002275
18339.035000	5404.267000	0.451910	29.993745
18342.813000	5404.996000	0.451701	30.003286
18346.641000	5405.562000	0.451702	30.003784
18350.439000	5406.109000	0.452104	30.011777
18354.217000	5407.606000	0.452446	30.002597
18358.045000	5408.092000	0.452763	29.988026
18361.863000	5408.658000	0.452610	29.993748
18365.671000	5409.609000	0.452233	30.004770
18369.461000	5410.560000	0.451996	30.001048
18373.259000	5411.410000	0.452046	29.999471
18377.147000	5411.957000	0.452314	29.998424
18380.915000	5412.888000	0.451540	30.007363
18384.723000	5413.414000	0.451466	29.999665
18388.531000	5413.940000	0.452967	29.995978
18392.329000	5415.336000	0.452789	30.002431
18396.107000	5415.680000	0.451675	29.999845
18399.985000	5416.854000	0.452206	29.999137
18403.723000	5417.157000	0.451881	30.002789
18407.471000	5417.906000	0.452339	30.004652
18411.279000	5418.554000	0.452490	30.014191
18415.087000	5419.343000	0.452743	29.993339
18418.945000	5420.334000	0.452156	30.001783
18422.733000	5420.820000	0.451627	30.010479
18426.601000	5421.973000	0.451728	29.997846
18430.340000	5422.459000	0.451836	29.987475
18434.148000	5423.613000	0.452269	29.991902
18437.966000	5424.017000	0.452851	30.001460
18441.704000	5425.049000	0.452016	29.998955
18445.512000	5425.697000	0.451783	30.004358
18449.310000	5426.506000	0.451846	30.007064
18453.068000	5427.053000	0.452121	29.991529
18456.856000	5427.842000	0.453026	29.993496
18460.704000	5428.570000	0.452688	30.006053
18464.464000	5429.602000	0.451991	30.007325
18468.232000	5430.088000	0.451962	29.998273
18472.080000	5430.999000	0.453334	29.994289
18475.918000	5431.747000	0.452304	30.010499
18479.726000	5432.354000	0.452861	30.005265
18483.514000	5433.366000	0.452861	29.995666
18487.262000	5433.690000	0.453142	29.990413
18491.170000	5434.641000	0.453555	29.999371
18494.998000	5435.491000	0.453051	29.994688
18498.786000	5436.483000	0.453292	30.010170
18502.584000	5436.624000	0.454013	29.994931
18506.372000	5438.081000	0.454506	29.996371
18510.160000	5438.587000	0.454059	29.995609
18514.008000	5439.316000	0.454192	29.996405
18517.886000	5439.963000	0.453749	29.988922
18521.704000	5441.056000	0.453844	30.007413
18525.492000	5441.622000	0.453651	29.995666
18529.290000	5442.735000	0.453766	29.997461
18533.068000	5443.120000	0.453303	29.998078
18536.856000	5443.970000	0.453361	30.003269
18540.694000	5444.354000	0.454038	29.996944
18544.463000	5445.346000	0.453287	30.002122
18548.291000	5445.750000	0.453727	29.996236
18552.079000	5447.005000	0.454544	29.998639
18555.827000	5447.835000	0.454255	29.992407
18559.665000	5448.462000	0.453650	30.005733
18563.503000	5449.170000	0.454620	29.992734
18567.251000	5449.858000	0.454464	30.009352
18571.069000	5450.809000	0.454782	29.997157
18574.917000	5451.578000	0.454987	30.004370
18578.686000	5452.206000	0.455764	29.994754
18582.464000	5452.853000	0.454652	29.994287
18586.212000	5453.865000	0.454956	29.992656
18589.990000	5454.513000	0.455086	29.996612
18593.778000	5455.484000	0.456686	29.990214
18597.566000	5455.889000	0.455306	29.999693
18601.394000	5456.799000	0.455176	29.998687
18605.172000	5457.528000	0.454618	29.989836
18608.930000	5458.216000	0.454494	29.991217
18612.748000	5458.823000	0.454829	29.993474
18616.496000	5459.713000	0.454715	29.992571
18620.334000	5460.401000	0.454397	29.998821
18624.072000	5461.453000	0.454120	29.995282
18627.880000	5462.020000	0.454179	30.001992
18631.728000	5463.113000	0.454304	29.998523
18635.506000	5463.821000	0.453421	30.002501
18639.254000	5464.367000	0.453566	30.011474
18643.002000	5465.238000	0.453871	29.982868
18646.760000	5465.966000	0.454179	29.991451
18650.548000	5466.674000	0.453647	29.996046
18654.346000	5467.383000	0.453480	29.987377
18658.154000	5468.192000	0.453758	29.991310
18661.992000	5469.103000	0.452915	29.999572
18665.810000	5469.710000	0.453123	30.004972
18669.558000	5470.195000	0.452079	30.013421
18673.346000	5471.329000	0.452419	29.995169
18677.154000	5471.834000	0.453406	29.991746
18680.882000	5472.947000	0.452953	30.000183
18684.670000	5473.474000	0.452102	29.997668
18688.518000	5474.404000	0.452694	29.992548
18692.296000	5475.072000	0.452444	29.998566
18696.064000	5475.983000	0.452196	29.999086
18699.912000	5476.387000	0.452415	29.995353
18703.770000	5477.217000	0.452883	29.999675
18707.548000	5478.006000	0.452656	29.999222
18711.346000	5479.140000	0.451956	30.009377
18715.094000	5479.585000	0.452255	29.998292
18718.882000	5480.333000	0.451977	29.995834
18722.660000	5480.920000	0.452323	29.989286
18726.478000	5481.892000	0.451877	29.997859
18730.326000	5482.843000	0.451846	29.990741
18734.104000	5483.470000	0.452115	29.989752
18737.892000	5483.875000	0.451660	30.006888
18741.680000	5485.048000	0.452051	30.001996
18745.438000	5485.595000	0.452339	29.994663
18749.216000	5486.526000	0.451992	30.003153
18753.044000	5487.173000	0.453506	29.996036
18756.862000	5488.408000	0.452460	30.007106
18760.620000	5488.650000	0.451829	29.991200
18764.438000	5489.419000	0.451372	29.998119
18768.236000	5490.370000	0.452123	30.003460
18772.024000	5491.018000	0.451672	30.000624
18775.832000	5491.706000	0.451914	29.992288
18779.590000	5492.455000	0.453007	29.992997
18783.378000	5493.163000	0.452278	30.004209
18787.196000	5494.134000	0.452696	29.995991
18790.954000	5494.681000	0.451912	30.005819
18794.742000	5495.794000	0.451960	30.002728
18798.570000	5496.239000	0.451997	30.013623
18802.318000	5496.846000	0.452262	30.009297
18806.106000	5497.999000	0.452368	30.009299
18809.934000	5498.384000	0.452492	29.998335
18813.712000	5499.719000	0.452280	29.988727
18817.540000	5499.922000	0.452268	29.996712
18821.328000	5500.812000	0.452551	29.998091
18825.176000	5501.783000	0.451846	30.003103
18828.984000	5502.229000	0.452064	29.994618
18832.812000	5503.018000	0.452252	30.002914
18836.560000	5503.524000	0.453356	29.997859
18840.358000	5504.596000	0.452059	30.000140
18844.166000	5505.264000	0.451521	30.009877
18847.924000	5506.175000	0.452572	29.992110
18851.702000	5506.620000	0.451208	30.000068
18855.510000	5507.530000	0.452264	29.999572
18859.298000	5508.400000	0.451610	30.003749
18863.126000	5509.331000	0.452749	30.001053
18866.854000	5509.857000	0.452144	30.003832
18870.702000	5510.647000	0.452784	29.994190
18874.480000	5511.618000	0.452546	29.995428
18878.268000	5512.124000	0.453422	29.993762
18882.096000	5512.812000	0.452994	29.998588
18885.884000	5513.844000	0.453407	30.004873
18889.752000	5514.593000	0.453083	30.000790
18893.620000	5515.139000	0.453576	29.990173
18897.398000	5516.131000	0.453776	29.994230
18901.146000	5516.616000	0.453202	30.004265
18904.934000	5517.547000	0.453182	29.997735
18908.762000	5518.296000	0.452906	30.005382
18912.550000	5519.388000	0.453113	29.994489
18916.358000	5520.097000	0.453385	29.989275
18920.156000	5520.421000	0.453901	29.984764
18923.924000	5521.655000	0.453189	29.996772
18927.652000	5522.363000	0.453147	29.999322
18931.440000	5522.829000	0.452860	29.999366
18935.318000	5523.355000	0.453267	29.990897
18939.146000	5524.306000	0.453595	30.002735
18942.934000	5525.034000	0.453190	29.992795
18946.692000	5525.823000	0.453390	30.003935
18950.460000	5526.936000	0.453637	29.995395
18954.228000	5527.604000	0.453395	29.993629
18958.066000	5528.191000	0.453175	30.001279
18961.874000	5528.940000	0.453260	30.001345
18965.692000	5529.729000	0.453410	30.010411
18969.510000	5530.457000	0.453205	30.002552
18973.308000	5531.348000	0.453471	29.997711
18977.126000	5532.036000	0.454567	29.992014
18980.924000	5532.481000	0.454186	30.002049
18984.702000	5533.655000	0.453298	29.997291
18988.590000	5534.383000	0.453656	29.998365
18992.358000	5534.970000	0.454304	30.006681
18996.177000	5535.597000	0.454746	30.009405
19000.015000	5536.427000	0.454299	30.003873
19003.793000	5537.115000	0.455268	29.998365
19007.551000	5538.127000	0.454663	29.995234
19011.369000	5538.855000	0.455473	30.000062
19015.117000	5539.564000	0.455357	30.009435
19018.985000	5540.677000	0.455234	30.007622
19022.733000	5541.101000	0.455364	30.001721
19026.521000	5541.810000	0.455123	29.998173
19030.279000	5542.680000	0.454849	30.000354
19034.067000	5543.429000	0.454524	30.015978
19037.885000	5544.117000	0.454849	30.002149
19041.653000	5545.007000	0.455187	29.997092
19045.411000	5545.776000	0.454435	30.006188
19049.209000	5546.444000	0.454697	29.997240
19053.037000	5547.395000	0.454352	29.992488
19056.855000	5547.880000	0.454880	29.996604
19060.723000	5549.014000	0.455091	30.006261
19064.591000	5549.600000	0.454240	30.006138
19068.370000	5550.572000	0.454075	30.005289
19072.168000	5551.118000	0.454155	30.007165
19075.986000	5551.806000	0.453756	29.999448
19079.834000	5552.778000	0.453432	30.013441
19083.602000	5553.546000	0.454423	29.997281
19087.510000	5554.255000	0.453546	30.005795
19091.318000	5554.963000	0.452889	30.002433
19095.036000	5555.894000	0.453228	30.000268
19098.824000	5556.501000	0.451860	30.017314
19102.632000	5556.987000	0.452307	30.007690
19106.440000	5557.776000	0.452358	29.999410
19110.228000	5558.970000	0.452299	29.999071
19113.976000	5559.415000	0.452292	29.992022
19117.744000	5560.285000	0.452247	29.996731
19121.562000	5561.256000	0.451953	29.997052
19125.380000	5562.025000	0.451234	30.001991
19129.128000	5562.491000	0.452379	29.994597
19132.926000	5563.361000	0.452064	30.008256
19136.784000	5564.150000	0.451979	29.995986
19140.582000	5564.717000	0.451850	29.991520
19144.420000	5565.567000	0.452260	30.001574
19148.238000	5566.234000	0.451880	29.996645
19152.027000	5567.084000	0.452009	29.999654
19155.915000	5568.035000	0.451531	29.997877
19159.703000	5568.602000	0.451333	29.992763
19163.451000	5569.128000	0.450460	30.009544
19167.229000	5569.917000	0.451693	29.998131
19171.087000	5570.767000	0.452005	30.003624
19174.925000	5571.577000	0.451446	30.001973
19178.673000	5572.325000	0.451504	30.002505
19182.471000	5573.135000	0.451616	30.000107
19186.329000	5573.742000	0.451238	29.989633
19190.097000	5574.612000	0.451254	29.999999
19193.885000	5575.158000	0.451601	30.001214
19197.753000	5576.453000	0.451359	29.989146
19201.561000	5576.757000	0.451514	30.022105
19205.459000	5577.566000	0.451653	29.990730
19209.257000	5578.517000	0.451911	29.997298
19213.045000	5579.145000	0.451706	29.995409
19216.833000	5580.035000	0.451820	30.001315
19220.621000	5580.824000	0.451408	30.002738
19224.419000	5581.674000	0.452117	30.002859
19228.267000	5582.342000	0.451784	29.997404
19232.125000	5583.394000	0.452504	29.988677
19235.923000	5584.001000	0.452051	30.003568
19239.711000	5584.548000	0.451738	29.991941
19243.549000	5585.195000	0.451781	30.006613
19247.327000	5586.146000	0.452765	29.994384
19251.135000	5586.571000	0.451950	29.987827
19254.903000	5587.543000	0.451817	29.994041
19258.732000	5588.291000	0.452013	30.011766
19262.530000	5588.919000	0.452872	29.991607
19266.308000	5589.708000	0.453312	29.994066
19270.126000	5590.881000	0.453380	29.997608
19273.954000	5591.408000	0.453475	30.001845
19277.782000	5592.237000	0.452395	30.001433
19281.620000	5592.986000	0.453269	29.999559
19285.428000	5593.694000	0.453156	29.997989
19289.226000	5594.605000	0.452453	29.987936
19293.024000	5595.273000	0.452696	29.990025
19296.752000	5595.961000	0.452372	30.003570
19300.590000	5596.770000	0.452522	30.001246
19304.368000	5597.741000	0.453449	29.995358
19308.116000	5598.389000	0.453548	29.994624
19311.904000	5598.753000	0.453703	29.992229
19315.772000	5599.583000	0.452996	29.997374
19319.640000	5600.413000	0.453169	29.993153
19323.458000	5601.222000	0.452747	29.995566
19327.226000	5602.234000	0.453592	29.990631
19331.004000	5602.861000	0.454181	29.998079
19334.772000	5603.347000	0.453880	29.998979
19338.540000	5604.197000	0.454024	29.997361
19342.358000	5605.047000	0.453799	29.998369
19346.196000	5605.694000	0.453734	30.003651
19349.984000	5606.483000	0.454182	29.990843
19353.722000	5607.111000	0.453944	29.995978
19357.510000	5607.920000	0.454184	29.992029
19361.388000	5608.770000	0.453377	29.994843
19365.166000	5609.620000	0.453282	30.003316
19368.964000	5610.369000	0.453435	30.011875
19372.702000	5611.239000	0.453923	30.003141
19376.530000	5611.947000	0.452872	29.997821
19380.358000	5612.331000	0.453809	29.992299
19384.106000	5613.181000	0.455176	29.990850
19387.954000	5613.991000	0.455427	30.009275
19391.732000	5615.144000	0.455703	30.001686
19395.550000	5615.691000	0.455249	30.001141
19399.328000	5616.298000	0.454624	30.001046
19403.116000	5617.309000	0.455710	29.993275
19406.914000	5617.815000	0.455325	30.002131
19410.672000	5618.766000	0.455916	30.008185
19414.480000	5619.373000	0.455706	30.010843
19418.268000	5620.122000	0.455868	30.005643
19422.056000	5621.174000	0.456220	30.000450
19425.844000	5621.680000	0.455822	29.993079
19429.632000	5622.045000	0.455907	30.014327
19433.451000	5623.178000	0.456519	30.003766
19437.249000	5623.765000	0.455960	30.003304
19441.037000	5624.959000	0.455851	29.993034
19444.875000	5625.424000	0.455419	29.998720
19448.713000	5626.395000	0.454597	30.003024
19452.541000	5626.901000	0.455547	30.001797
19456.329000	5627.690000	0.454950	30.000155
19460.117000	5628.277000	0.455296	30.011555
19463.905000	5628.985000	0.455907	29.996766
19467.703000	5629.916000	0.455493	30.006181
19471.441000	5630.584000	0.454796	29.993711
19475.199000	5631.596000	0.454359	29.998766
19478.997000	5632.608000	0.455265	30.010997
19482.855000	5633.498000	0.454547	30.001244
19486.643000	5633.700000	0.454938	30.002067
19490.471000	5634.328000	0.454381	30.007997
19494.219000	5635.522000	0.454453	30.010799
19498.017000	5636.230000	0.454463	30.007876
19501.785000	5636.776000	0.455524	29.990641
19505.634000	5637.748000	0.455044	30.007461
19509.482000	5638.294000	0.454589	29.999174
19513.270000	5639.265000	0.454127	29.996126
19517.008000	5639.791000	0.453543	29.992754
19520.806000	5640.540000	0.452992	29.992442
19524.584000	5641.613000	0.453877	30.001926
19528.373000	5642.139000	0.454096	30.006750
19532.191000	5642.705000	0.454222	29.996985
19536.059000	5644.061000	0.453224	30.002310
19539.848000	5644.648000	0.453740	29.996687
19543.716000	5645.397000	0.453914	29.993813
19547.504000	5646.125000	0.453160	30.007104
19551.292000	5646.955000	0.452973	30.002934
19555.050000	5647.906000	0.452696	30.000734
19558.818000	5648.412000	0.453333	30.004605
19562.606000	5649.181000	0.453925	30.003724
19566.414000	5649.970000	0.453479	30.000193
19570.212000	5650.395000	0.453513	30.005272
19574.010000	5651.609000	0.452750	30.006653
19577.758000	5652.378000	0.453239	29.985739
19581.556000	5652.661000	0.453321	30.011042
19585.324000	5653.471000	0.452877	30.002542
19589.192000	5654.624000	0.453033	30.000920
19592.980000	5655.555000	0.453204	30.010507
19596.838000	5655.919000	0.452910	30.011608
19600.596000	5656.668000	0.452757	29.996881
19604.374000	5657.235000	0.452405	29.999505
19608.172000	5658.449000	0.452469	30.007546
19612.030000	5659.015000	0.452690	30.009908
19615.858000	5659.663000	0.452381	30.001953
19619.646000	5660.412000	0.452581	29.997572
19623.434000	5661.302000	0.452557	30.001231
19627.232000	5662.152000	0.452170	29.992515
19631.010000	5662.759000	0.452001	30.006267
19634.848000	5663.649000	0.452797	30.000110
19638.676000	5664.337000	0.452369	30.001785
19642.514000	5665.228000	0.452529	29.995681
19646.282000	5665.916000	0.452443	30.009354
19650.170000	5666.664000	0.452901	29.999426
19653.888000	5667.211000	0.452246	30.001008
19657.716000	5668.081000	0.452626	30.005759
19661.514000	5668.708000	0.452801	29.996527
19665.322000	5669.417000	0.452083	29.992707
19669.160000	5670.449000	0.452455	30.002286
19672.908000	5670.975000	0.453326	29.989535
19676.696000	5671.703000	0.452490	30.001252
19680.494000	5672.472000	0.452714	29.997645
19684.272000	5673.464000	0.453991	29.998285
19688.070000	5674.071000	0.452730	30.008892
19691.848000	5675.022000	0.453315	30.002614
19695.676000	5675.811000	0.453062	29.999360
19699.464000	5676.479000	0.453226	30.005785
19703.252000	5677.389000	0.453151	30.008286
19707.030000	5677.956000	0.453892	30.006274
19710.858000	5678.806000	0.453248	29.996679
19714.697000	5679.534000	0.453484	30.000794
19718.475000	5680.283000	0.453104	29.998513
19722.243000	5680.850000	0.452780	30.002763
19726.001000	5681.760000	0.453695	29.991773
19729.759000	5682.550000	0.453260	29.998080
19733.567000	5683.157000	0.454165	29.986459
19737.395000	5684.108000	0.454083	29.995961
19741.163000	5684.937000	0.453286	29.993606
19744.951000	5685.565000	0.453523	29.997646
19748.729000	5686.111000	0.453759	29.993240
19752.597000	5686.840000	0.453755	29.991371
19756.425000	5687.811000	0.453320	30.005709
19760.243000	5688.823000	0.452962	29.989390
19764.001000	5689.531000	0.452747	29.989475
19767.799000	5689.733000	0.453679	29.994763
19771.567000	5690.887000	0.454677	29.983016
19775.315000	5691.494000	0.453865	29.992734
19779.113000	5692.222000	0.453899	30.002678
19782.971000	5693.011000	0.454766	30.001714
19786.769000	5694.205000	0.454352	29.999378
19790.517000	5694.651000	0.455299	30.005472
19794.335000	5695.419000	0.454666	29.992316
19798.153000	5695.925000	0.455356	29.994504
19801.961000	5696.796000	0.454727	29.997062
19805.779000	5697.848000	0.454601	30.007274
19809.577000	5698.273000	0.453965	29.995339
19813.355000	5699.244000	0.454484	29.999187
19817.173000	5699.790000	0.454947	30.005010
19820.941000	5700.762000	0.454772	29.998482
19824.719000	5701.551000	0.454901	30.000938
19828.507000	5702.057000	0.454750	30.003654
19832.295000	5702.947000	0.454972	30.000929
19836.073000	5703.716000	0.454867	29.991876
19839.881000	5704.303000	0.454148	30.004301
19843.659000	5704.951000	0.455871	30.005407
19847.467000	5705.598000	0.454947	29.999361
19851.285000	5706.630000	0.455079	29.989927
19855.053000	5707.419000	0.454913	30.001212
19858.841000	5708.006000	0.455353	30.007645
19862.679000	5708.896000	0.455696	29.994905
19866.447000	5709.504000	0.455717	29.991506
19870.295000	5710.394000	0.456238	30.002849
19874.133000	5711.446000	0.455894	30.003565
19877.951000	5711.932000	0.456019	30.006554
19881.769000	5712.964000	0.454972	29.994558
19885.617000	5713.692000	0.455215	30.006006
19889.416000	5714.380000	0.455415	30.007408
19893.234000	5715.291000	0.455212	30.013350
19897.022000	5715.999000	0.455894	29.994215
19900.820000	5716.627000	0.455339	30.000226
19904.638000	5717.396000	0.455409	29.999633
19908.386000	5718.124000	0.455459	30.006580
19912.154000	5718.994000	0.455101	30.003429
19915.972000	5719.682000	0.455633	29.995747
19919.760000	5720.390000	0.455602	30.009237
19923.568000	5721.200000	0.455156	30.007456
19927.396000	5721.989000	0.455414	29.997540
19931.224000	5723.183000	0.454943	29.998444
19935.012000	5723.911000	0.455081	30.007662
19938.800000	5724.175000	0.454606	29.995287
19942.589000	5724.863000	0.455135	29.994233
19946.387000	5725.834000	0.455068	29.989520
19950.155000	5726.684000	0.454920	29.995912
19953.953000	5727.068000	0.455502	29.998234
19957.741000	5727.999000	0.454072	30.000756
19961.529000	5729.051000	0.453149	30.003417
19965.307000	5729.760000	0.453770	29.992381
19969.105000	5730.427000	0.453679	30.003928
19972.923000	5731.621000	0.454419	30.005823
19976.671000	5731.945000	0.453570	29.996108
19980.499000	5733.058000	0.453085	29.999401
19984.317000	5733.301000	0.454307	29.996991
19988.105000	5734.191000	0.453889	29.999577
19991.973000	5734.940000	0.453353	29.997531
19995.761000	5735.830000	0.454007	29.995785
19999.599000	5736.660000	0.453182	29.994039
20003.417000	5737.065000	0.453433	29.992028
20007.285000	5738.178000	0.453205	30.013546
20011.073000	5738.825000	0.452418	30.009702
20014.861000	5739.655000	0.453304	30.004486
20018.649000	5740.323000	0.453852	29.994336
20022.467000	5741.173000	0.452952	29.988336
20026.235000	5741.921000	0.453044	30.002550
20030.123000	5742.690000	0.452327	29.999443
20033.921000	5743.318000	0.452800	29.993690
20037.789000	5744.087000	0.452667	29.992742
20041.527000	5744.592000	0.453125	30.001629
20045.275000	5745.989000	0.453846	29.999655
20049.103000	5746.231000	0.452802	30.004053
20052.971000	5746.899000	0.453587	30.005334
20056.719000	5748.093000	0.453322	30.009699
20060.507000	5748.660000	0.452752	30.000339
20064.255000	5749.166000	0.453145	30.000402
20068.043000	5750.137000	0.452133	30.004275
20071.841000	5750.906000	0.453040	29.998892
20075.659000	5751.634000	0.453538	30.007046
20079.447000	5752.100000	0.453324	30.001280
20083.235000	5752.828000	0.454004	30.010269
20087.033000	5753.678000	0.453985	30.005687
20090.851000	5754.528000	0.454502	29.992141
20094.649000	5755.297000	0.454005	30.001467
20098.437000	5756.127000	0.454955	29.995701
20102.175000	5756.896000	0.453981	29.997076
20105.953000	5757.867000	0.454890	30.002273
20109.741000	5758.575000	0.453486	29.992935
20113.489000	5759.263000	0.454559	30.006005
20117.277000	5759.992000	0.454688	29.988932
20121.115000	5760.821000	0.454105	29.994492
20124.973000	5761.631000	0.454117	29.996147
20128.821000	5762.319000	0.454191	30.001141
20132.699000	5762.865000	0.454536	29.991980
20136.457000	5764.059000	0.454061	29.995063
20140.285000	5764.646000	0.454655	30.005011
20144.063000	5765.557000	0.453752	30.000115
20147.881000	5766.103000	0.454500	29.993173
20151.689000	5766.892000	0.454001	29.996342
20155.477000	5767.843000	0.453736	30.000276
20159.335000	5768.511000	0.454284	29.999064
20163.163000	5769.300000	0.453958	29.991841
20166.911000	5769.523000	0.453950	29.994262
20170.749000	5770.312000	0.455379	30.004370
20174.527000	5771.202000	0.454949	29.996381
20178.315000	5772.093000	0.454292	29.994527
20182.093000	5772.801000	0.454154	29.996389
20185.891000	5773.712000	0.454398	29.995559
20189.639000	5774.359000	0.453994	29.989939
20193.417000	5775.229000	0.453921	29.998881
20197.205000	5775.938000	0.454350	29.999881
20200.963000	5776.808000	0.455228	29.984413
20204.731000	5777.395000	0.455104	29.995784
20208.529000	5778.285000	0.454584	30.007290
20212.377000	5778.933000	0.454079	29.996586
20216.205000	5779.803000	0.454143	29.990036
20220.044000	5780.430000	0.454678	29.997643
20223.872000	5780.956000	0.455896	29.993922
20227.660000	5781.867000	0.454594	30.001577
20231.418000	5782.757000	0.454589	30.013077
20235.146000	5783.647000	0.454946	29.993730
20238.944000	5784.214000	0.454265	30.001169
20242.762000	5784.841000	0.454759	29.992457
20246.560000	5785.833000	0.455067	29.992925
20250.418000	5786.420000	0.454868	29.994294
20254.246000	5787.472000	0.454422	29.998551
20258.034000	5788.120000	0.454795	29.992727
20261.832000	5788.949000	0.455016	29.992945
20265.610000	5789.556000	0.455342	30.002112
20269.398000	5790.507000	0.455042	30.006863
20273.227000	5791.256000	0.454940	29.997831
20277.035000	5791.944000	0.455616	30.002018
20280.793000	5792.673000	0.455592	29.999504
20284.601000	5793.502000	0.455663	30.002476
20288.419000	5793.887000	0.455941	30.010610
20292.207000	5795.162000	0.456197	30.002399
20295.985000	5795.789000	0.456212	29.994515
20299.733000	5796.153000	0.455371	30.009814
20303.591000	5797.347000	0.455681	30.002865
20307.389000	5797.732000	0.456364	30.000522
20311.187000	5798.521000	0.455702	29.999384
20314.975000	5799.553000	0.455989	29.995809
20318.783000	5800.241000	0.455281	29.993531
20322.531000	5800.726000	0.455339	29.996819
20326.359000	5801.718000	0.456561	29.997446
20330.117000	5802.649000	0.455082	29.997168
20333.905000	5803.296000	0.454980	30.004793
20337.683000	5803.802000	0.454932	29.991625
20341.481000	5804.834000	0.455636	29.991765
20345.299000	5805.482000	0.455933	29.993958
20349.147000	5806.514000	0.455844	29.996282
20352.985000	5807.182000	0.455664	30.000728
20356.773000	5807.789000	0.455276	30.009963
20360.572000	5808.679000	0.456409	29.991467
20364.430000	5809.590000	0.455710	30.009251
20368.208000	5810.298000	0.455337	30.002625
20371.996000	5811.047000	0.455605	29.994872
20375.824000	5811.613000	0.454344	30.000924
20379.612000	5812.423000	0.454431	30.004292
20383.450000	5813.596000	0.453861	30.005120
20387.278000	5814.062000	0.454306	30.014776
20391.056000	5814.750000	0.453932	29.990187
20394.824000	5815.316000	0.454300	29.999644
20398.652000	5816.328000	0.453888	29.995887
20402.450000	5817.401000	0.453926	29.997233
20406.238000	5817.927000	0.454203	29.996363
20410.026000	5818.514000	0.453185	29.988034
20413.855000	5819.364000	0.453954	29.995386
20417.683000	5820.072000	0.453794	29.994982
20421.421000	5821.003000	0.454267	29.998775
20425.269000	5821.387000	0.453151	29.998764
20429.047000	5822.500000	0.454006	30.008231
20432.835000	5823.107000	0.453980	29.993737
20436.613000	5823.795000	0.452928	30.015529
20440.361000	5824.908000	0.454174	30.002096
20444.149000	5825.374000	0.453438	30.009793
20447.937000	5826.345000	0.453600	29.989980
20451.695000	5826.851000	0.452435	30.006243
20455.473000	5827.640000	0.453100	29.992734
20459.261000	5828.105000	0.453649	30.002394
20463.049000	5829.259000	0.453165	30.000229
20466.917000	5830.068000	0.453206	29.997221
20470.645000	5830.615000	0.453236	30.004280
20474.443000	5831.647000	0.453670	29.992491
20478.321000	5832.193000	0.453583	29.997474
20482.100000	5833.063000	0.453176	30.012302
20485.928000	5833.913000	0.453618	30.009536
20489.786000	5834.520000	0.453960	30.015025
20493.624000	5835.188000	0.453992	30.004745
20497.402000	5835.896000	0.453755	30.000017
20501.240000	5836.827000	0.453309	29.989132
20505.058000	5837.636000	0.453882	29.997138
20508.806000	5837.819000	0.454494	29.993202
20512.614000	5838.810000	0.454685	29.990729
20516.392000	5840.045000	0.453911	30.008195
20520.170000	5840.955000	0.454780	29.994954
20523.958000	5841.137000	0.454146	30.006129
20527.766000	5842.230000	0.454126	29.996848
20531.534000	5842.716000	0.454252	30.005705
20535.322000	5843.363000	0.453905	29.999007
20539.160000	5844.577000	0.454091	30.002205
20542.928000	5845.124000	0.454131	29.999551
20546.726000	5846.055000	0.453736	30.006201
20550.544000	5846.864000	0.453738	29.992070
20554.403000	5847.350000	0.453980	30.000786
20558.191000	5848.078000	0.454690	30.000120
20562.019000	5848.645000	0.455212	30.000462
20565.807000	5849.737000	0.454714	30.014168
20569.635000	5850.486000	0.454616	30.000097
20573.463000	5851.437000	0.455222	29.994142
20577.251000	5851.903000	0.455509	29.989541
20581.039000	5852.692000	0.455532	29.992696
20584.837000	5853.663000	0.455341	29.999836
20588.646000	5854.210000	0.455410	30.000583
20592.354000	5855.039000	0.454055	29.999504
20596.142000	5855.909000	0.454436	30.000958
20599.930000	5856.759000	0.455218	29.989334
20603.759000	5857.366000	0.454668	29.992437
20607.537000	5858.237000	0.454959	30.008123
20611.355000	5858.823000	0.453831	30.003976
20615.123000	5859.592000	0.454895	29.995035
20618.901000	5860.321000	0.453986	30.000112
20622.719000	5861.211000	0.454585	29.997798
20626.477000	5861.879000	0.453981	29.997465
20630.265000	5862.709000	0.455329	29.991577
20634.103000	5863.215000	0.454327	29.995855
20637.871000	5864.064000	0.453881	29.997253
20641.689000	5864.874000	0.453863	30.000050
20645.457000	5865.440000	0.454168	29.996476
20649.235000	5866.169000	0.454516	29.995608
20653.023000	5866.958000	0.454158	29.998337
20656.781000	5867.828000	0.454359	30.004086
20660.569000	5868.800000	0.453631	30.006943
20664.347000	5869.366000	0.453654	29.989051
20668.175000	5870.196000	0.454858	30.011741
20671.963000	5871.086000	0.453921	30.007726
20675.771000	5871.734000	0.454704	29.988836
20679.619000	5872.543000	0.455103	29.992757
20683.417000	5872.988000	0.453888	29.992143
20687.285000	5874.041000	0.454576	29.993524
20691.094000	5874.810000	0.454552	30.015446
20694.962000	5875.396000	0.455048	30.012218
20698.750000	5876.348000	0.454661	30.003095
20702.588000	5876.975000	0.454292	30.005230
20706.366000	5877.885000	0.455849	30.002042
20710.164000	5878.452000	0.455785	30.001246
20714.022000	5879.484000	0.455961	29.993335
20717.820000	5880.030000	0.456481	30.000009
20721.648000	5880.860000	0.455716	30.000425
20725.416000	5881.427000	0.455342	29.994632
20729.264000	5882.358000	0.455934	30.004562
20733.062000	5883.369000	0.456158	30.001599
20736.850000	5884.138000	0.456118	29.991623
20740.658000	5884.685000	0.456447	29.994296
20744.446000	5885.393000	0.456465	30.010446
20748.234000	5886.162000	0.455576	30.010067
20752.052000	5887.093000	0.455760	30.006228
20755.840000	5887.902000	0.456227	29.991165
20759.708000	5888.651000	0.455822	29.993532
20763.496000	5889.359000	0.455401	30.004624
20767.394000	5889.905000	0.455904	30.002049
20771.182000	5890.755000	0.455437	30.005261
20774.940000	5891.706000	0.455063	29.999367
20778.728000	5892.415000	0.455494	30.009462
20782.546000	5892.981000	0.456078	29.995986
20786.334000	5893.791000	0.455398	29.997178
20790.082000	5894.317000	0.455066	29.996727
20793.880000	5895.410000	0.455472	29.996380
20797.668000	5896.057000	0.454679	29.996477
20801.446000	5896.786000	0.454882	30.000528
20805.225000	5897.656000	0.455074	29.997613
20809.053000	5898.364000	0.455177	29.990022
20812.881000	5899.153000	0.454929	29.994215
20816.669000	5899.861000	0.454705	30.002944
20820.457000	5900.610000	0.455602	30.002989
20824.265000	5901.743000	0.455198	29.987745
20828.113000	5902.391000	0.454267	29.997358
20831.901000	5902.958000	0.454538	29.992248
20835.689000	5903.706000	0.454392	29.997303
20839.517000	5904.779000	0.453771	29.998030
20843.265000	5905.042000	0.453841	30.001315
20847.063000	5905.730000	0.453499	30.001307
20850.851000	5907.005000	0.452995	29.996496
20854.629000	5907.875000	0.453468	29.987438
20858.407000	5907.996000	0.453501	29.998953
20862.195000	5908.947000	0.453651	30.011029
20865.993000	5909.433000	0.453947	29.998176
20869.771000	5910.688000	0.453352	30.011907
20873.559000	5911.538000	0.453065	29.998306
20877.357000	5911.922000	0.453603	30.004149
20881.155000	5912.934000	0.453393	30.000992
20884.974000	5913.521000	0.454067	30.001562
20888.742000	5914.209000	0.453462	29.998352
20892.530000	5915.200000	0.454042	29.995498
20896.388000	5916.212000	0.453349	30.000822
20900.206000	5916.556000	0.452696	29.990481
20903.974000	5917.527000	0.452813	30.002013
20907.772000	5918.053000	0.453609	29.992309
20911.590000	5918.883000	0.453168	29.988126
20915.398000	5919.591000	0.452395	29.999629
20919.166000	5920.401000	0.453540	29.994273
20922.914000	5920.846000	0.454333	29.994799
20926.702000	5922.020000	0.453344	30.005723
20930.530000	5922.728000	0.453783	29.996493
20934.299000	5923.456000	0.453134	29.998297
20938.067000	5924.063000	0.453575	29.989630
20941.796000	5925.075000	0.454313	30.000527
20945.544000	5925.419000	0.453507	29.995163
20949.353000	5926.269000	0.453992	30.008686
20953.131000	5926.896000	0.454530	29.996353
20956.899000	5927.908000	0.454820	29.994309
20960.697000	5928.657000	0.453923	30.000327
20964.525000	5929.426000	0.454968	30.005950
20968.333000	5930.296000	0.454787	30.006626
20972.211000	5930.964000	0.453942	30.007639
20976.059000	5931.773000	0.454008	30.002713
20979.877000	5932.421000	0.454758	30.007030
20983.655000	5933.149000	0.454282	29.999182
20987.483000	5933.918000	0.454342	30.002016
20991.261000	5934.809000	0.454293	29.994427
20995.049000	5935.375000	0.454964	30.007512
20998.837000	5936.185000	0.454075	30.002760
21002.655000	5936.974000	0.453067	30.016947
21006.454000	5938.127000	0.453518	30.001274
21010.292000	5938.411000	0.454553	29.995577
21014.100000	5939.362000	0.454237	30.006518
21017.888000	5939.908000	0.454276	30.002602
21021.686000	5940.859000	0.453967	30.006199
21025.504000	5941.891000	0.453732	30.007501
21029.302000	5942.397000	0.454355	30.002572
21033.090000	5943.227000	0.453452	30.003419
21036.908000	5943.793000	0.454025	29.997450
21040.676000	5944.522000	0.454361	30.000473
21044.445000	5945.392000	0.454066	30.006229
21048.223000	5946.141000	0.455411	30.008517
21052.061000	5946.910000	0.454324	30.007156
21055.879000	5947.537000	0.454313	30.010180
21059.667000	5948.346000	0.454825	30.008684
21063.495000	5949.419000	0.454496	30.003975
21067.243000	5950.107000	0.454220	30.013903
21071.041000	5950.694000	0.454864	30.006586
21074.849000	5951.260000	0.455549	30.012728
21078.667000	5952.414000	0.455506	30.003567
21082.425000	5952.819000	0.455195	30.006141
21086.263000	5953.851000	0.454932	30.006752
21090.081000	5954.559000	0.455121	30.002640
21093.919000	5955.146000	0.455922	30.005509
21097.757000	5955.935000	0.455093	30.010519
21101.575000	5956.845000	0.455780	30.004620
21105.353000	5957.270000	0.455321	29.997491
21109.181000	5958.181000	0.454934	29.990589
21113.000000	5958.950000	0.454737	29.997442
21116.838000	5959.861000	0.455814	29.998359
21120.656000	5960.832000	0.455029	29.998842
21124.434000	5961.398000	0.454309	30.004873
21128.202000	5962.289000	0.454942	30.012830
21131.990000	5962.997000	0.455748	30.008007
21135.738000	5963.705000	0.454966	29.989789
21139.546000	5964.373000	0.455136	30.002006
21143.334000	5965.284000	0.455580	30.006750
21147.132000	5966.134000	0.455600	30.002828
21150.910000	5966.781000	0.455548	30.007167
21154.698000	5967.307000	0.455728	29.998164
21158.526000	5967.894000	0.455914	29.999431
21162.324000	5968.987000	0.456169	29.990425
21166.092000	5969.918000	0.456746	29.997752
21169.930000	5970.464000	0.456062	30.006307
21173.728000	5971.031000	0.455451	30.001498
21177.546000	5971.982000	0.456128	29.990023
21181.375000	5972.731000	0.456293	29.998496
21185.223000	5973.277000	0.455573	30.006038
21189.031000	5974.167000	0.455778	30.012765
21192.849000	5975.058000	0.455766	30.006455
21196.627000	5975.685000	0.455705	30.013446
21200.395000	5976.616000	0.455048	29.990694
21204.163000	5977.526000	0.455732	29.992558
21207.971000	5978.194000	0.454991	30.016031
21211.739000	5978.801000	0.454733	30.001924
21215.527000	5979.874000	0.454923	30.010110
21219.365000	5980.380000	0.455170	29.999046
21223.153000	5981.047000	0.454947	29.994989
21226.931000	5981.958000	0.455742	29.986914
21230.729000	5982.848000	0.455920	29.993131
21234.547000	5983.192000	0.455382	29.984070
21238.415000	5984.467000	0.454822	30.003072
21242.203000	5984.933000	0.455177	29.994165
21245.981000	5985.641000	0.455175	30.000097
21249.769000	5986.572000	0.455337	29.995209
21253.597000	5987.078000	0.455083	30.003113
21257.445000	5988.009000	0.453703	30.004933
21261.223000	5988.757000	0.454122	29.999016
21265.001000	5989.486000	0.454085	29.999700
21268.789000	5990.234000	0.453353	29.994218
21272.587000	5991.044000	0.453339	29.998427
21276.335000	5992.035000	0.453638	29.992308
21280.203000	5992.804000	0.453238	29.991464
21283.981000	5993.594000	0.454083	29.984905
21287.729000	5994.019000	0.453381	29.992709
21291.477000	5994.848000	0.454077	29.995543
21295.265000	5995.739000	0.453509	29.997698
21299.079000	5996.548000	0.453500	29.995420
21302.818000	5996.932000	0.454054	29.992865
21306.646000	5997.904000	0.454271	29.992209
21310.494000	5998.531000	0.453501	30.001513
21314.252000	5999.543000	0.454064	29.995701
21318.200000	6000.170000	0.453858	29.998349
21321.988000	6002.983000	0.460841	29.988773
21325.826000	6010.207000	0.473096	30.010469
21329.614000	6017.108000	0.479052	30.023104
21333.442000	6024.979000	0.482098	30.027530
21337.250000	6032.972000	0.484885	30.042025
21341.068000	6041.026000	0.485839	30.037041
21344.866000	6048.412000	0.487633	30.036084
21348.664000	6055.373000	0.488727	30.041158
21352.482000	6063.670000	0.489801	30.051193
21356.310000	6072.027000	0.491486	30.034386
21360.098000	6079.879000	0.491095	30.038127
21363.906000	6087.265000	0.491284	30.022649
21367.684000	6094.692000	0.491822	30.031853
21371.462000	6101.875000	0.492912	30.023096
21375.250000	6108.857000	0.493845	30.021835
21378.998000	6116.910000	0.494321	30.022157
21382.826000	6124.438000	0.494336	30.025717
21386.684000	6131.986000	0.495784	30.022734
21390.482000	6139.453000	0.495924	30.026594
21394.230000	6147.244000	0.496446	30.028935
21398.018000	6155.338000	0.497006	30.025495
21401.796000	6163.028000	0.495642	30.026888
21405.584000	6170.515000	0.495621	30.024016
21409.412000	6178.164000	0.495896	30.029570
21413.280000	6185.510000	0.496847	30.025641
21417.068000	6192.956000	0.496229	30.029394
21420.886000	6200.747000	0.497908	30.032406
21424.644000	6208.315000	0.497313	30.033497
21428.392000	6215.519000	0.497993	30.031329
21432.140000	6223.209000	0.498308	30.036816
21435.928000	6230.352000	0.498803	30.037936
21439.666000	6237.799000	0.499268	30.041404
21443.434000	6246.075000	0.499166	30.036123
21447.222000	6254.230000	0.498895	30.036429
21451.050000	6261.394000	0.497396	30.035177
21454.818000	6268.416000	0.498463	30.030865
21458.616000	6276.105000	0.498638	30.033429
21462.444000	6283.633000	0.499600	30.029413
21466.242000	6291.221000	0.499446	30.020060
21470.020000	6299.073000	0.499558	30.019671
21473.798000	6306.601000	0.500209	30.013014
21477.676000	6314.108000	0.500912	30.010018
21481.524000	6322.142000	0.499796	30.015277
21485.432000	6330.135000	0.499779	30.015468
21489.260000	6337.662000	0.499723	30.006080
21493.048000	6345.231000	0.500294	30.003928
21496.876000	6353.082000	0.499306	30.009661
21500.664000	6360.671000	0.499713	30.006996
21504.542000	6367.733000	0.500671	30.002064
21508.280000	6375.584000	0.500287	30.012681
21512.178000	6383.436000	0.500492	30.007003
21515.997000	6390.660000	0.499620	30.007429
21519.795000	6398.228000	0.501247	30.001800
21523.593000	6405.978000	0.501699	30.006037
21527.381000	6413.789000	0.501155	30.015113
21531.159000	6421.702000	0.501173	30.003676
21534.987000	6429.492000	0.500895	30.009427
21538.835000	6436.777000	0.500187	30.004121
21542.633000	6443.657000	0.500878	30.003643
21546.431000	6451.833000	0.501537	30.005719
21550.259000	6459.623000	0.501133	30.003552
21554.007000	6467.111000	0.500778	30.003809
21557.825000	6474.659000	0.501699	30.000309
21561.653000	6482.186000	0.501179	29.997411
21565.411000	6489.896000	0.502121	30.005947
21569.219000	6497.626000	0.501165	30.010939
21573.017000	6505.761000	0.501251	30.003779
21576.815000	6513.370000	0.500185	29.999980
21580.613000	6520.047000	0.499701	30.007713
21584.421000	6527.575000	0.501715	30.003940
21588.219000	6535.508000	0.501303	30.009744
21592.007000	6543.400000	0.501028	29.996963
21595.745000	6550.300000	0.500830	30.003043
21599.583000	6558.091000	0.501238	30.002512
21603.331000	6565.922000	0.500670	30.002713
21607.149000	6572.822000	0.501534	30.006267
21610.937000	6580.856000	0.502080	30.004893
21614.755000	6588.627000	0.501929	30.005047
21618.513000	6596.336000	0.501396	30.013219
21622.411000	6604.451000	0.501024	29.996492
21626.209000	6611.796000	0.500674	30.003225
21629.987000	6618.778000	0.501471	30.006389
21633.825000	6626.629000	0.501747	29.998653
21637.603000	6634.117000	0.501377	30.004124
21641.381000	6641.786000	0.502495	30.000058
21645.169000	6649.192000	0.502467	29.998307
21648.957000	6656.518000	0.503306	30.002899
21652.745000	6664.329000	0.503895	30.004391
21656.493000	6672.200000	0.502788	29.999657
21660.291000	6679.748000	0.501842	30.010217
21664.069000	6687.458000	0.501727	30.005754
21667.867000	6694.945000	0.501907	29.999359
21671.645000	6702.493000	0.501885	29.993284
21675.393000	6710.001000	0.501716	29.996843
21679.211000	6717.771000	0.502305	29.999044
21682.999000	6725.036000	0.502370	30.001641
21686.797000	6732.705000	0.502325	30.013165
21690.546000	6739.403000	0.501829	30.003407
21694.324000	6747.639000	0.503758	30.002077
21698.102000	6754.863000	0.503393	30.009762
21701.860000	6763.059000	0.503026	30.006053
21705.648000	6771.012000	0.502038	29.997907
21709.436000	6778.377000	0.501838	29.996033
21713.214000	6786.026000	0.501889	30.000821
21717.042000	6793.251000	0.502929	30.000688
21720.830000	6800.778000	0.501713	30.002890
21724.598000	6808.650000	0.502340	29.999343
21728.446000	6816.340000	0.502110	30.001750
21732.194000	6823.321000	0.501785	29.999482
21736.012000	6830.950000	0.503445	30.002022
21739.800000	6838.518000	0.504195	30.001151
21743.558000	6846.592000	0.503828	29.993858
21747.346000	6854.565000	0.501999	30.005045
21751.134000	6861.202000	0.502344	30.007300
21754.912000	6869.155000	0.502312	29.999869
21758.750000	6876.460000	0.502685	30.003491
21762.538000	6884.109000	0.503955	30.004197
21766.316000	6891.941000	0.503621	30.005411
21770.074000	6899.590000	0.503048	30.012613
21773.812000	6906.591000	0.504313	30.004720
21777.560000	6913.714000	0.503538	29.999395
21781.398000	6921.201000	0.503861	30.008339
21785.176000	6929.377000	0.503818	29.997696
21788.964000	6936.763000	0.503964	30.002858
21792.752000	6945.059000	0.503403	29.999546
21796.510000	6952.405000	0.502298	30.001344
21800.288000	6959.872000	0.501885	30.009079
21804.116000	6967.035000	0.502449	30.007602
21807.884000	6974.624000	0.502486	29.994927
21811.612000	6982.637000	0.502033	30.003805
21815.400000	6989.477000	0.502298	30.005634
21819.158000	6996.782000	0.502884	30.008127
21822.926000	7005.058000	0.504381	29.999673
21826.674000	7012.505000	0.503619	30.000870
21830.472000	7020.073000	0.503136	30.015808
21834.260000	7027.824000	0.502496	30.003525
21838.088000	7035.311000	0.501967	29.993346
21841.876000	7042.717000	0.502082	30.006468
21845.654000	7050.387000	0.502401	30.010124
21849.402000	7058.117000	0.503339	29.995631
21853.210000	7065.240000	0.502802	29.997286
21856.948000	7072.970000	0.503555	30.000553
21860.756000	7080.639000	0.502909	29.992641
21864.625000	7088.187000	0.503130	29.997572
21868.373000	7095.087000	0.503752	29.999097
21872.171000	7103.303000	0.503236	30.006862
21875.969000	7111.499000	0.502463	30.003377
21879.777000	7118.844000	0.501234	30.011903
21883.575000	7126.858000	0.501522	30.003842
21887.473000	7133.879000	0.501203	29.999559
21891.281000	7141.731000	0.501018	29.998976
21895.119000	7149.380000	0.501935	29.989289
21898.907000	7156.584000	0.501300	29.989478
21902.665000	7164.618000	0.501726	29.998717
21906.443000	7171.619000	0.500935	30.001076
21910.211000	7179.106000	0.502181	30.004221
21914.019000	7186.978000	0.501985	29.992573
21917.767000	7194.688000	0.501160	30.009963
21921.635000	7202.681000	0.500860	30.003762
21925.453000	7210.006000	0.499461	29.999230
21929.221000	7217.413000	0.500966	29.996833
21933.070000	7225.163000	0.501151	30.002930
21936.858000	7233.095000	0.501369	30.009186
21940.726000	7240.562000	0.501522	30.002978
21944.474000	7247.888000	0.501438	30.003060
21948.272000	7255.658000	0.501281	30.002761
21952.110000	7263.024000	0.501685	30.000257
21955.918000	7269.985000	0.502262	30.005257
21959.706000	7277.837000	0.504069	30.004601
21963.484000	7286.842000	0.502607	30.016160
21967.312000	7294.167000	0.501895	30.014575
21971.140000	7301.533000	0.501444	30.000037
21974.938000	7308.717000	0.501208	30.009290
21978.686000	7316.426000	0.501622	29.999109
21982.464000	7324.136000	0.502277	30.004896
21986.252000	7331.482000	0.502278	30.003331
21990.040000	7339.374000	0.502457	29.997638
21993.878000	7346.800000	0.502525	29.993656
21997.746000	7354.490000	0.502606	30.004230
22001.554000	7362.382000	0.503493	29.997426
22005.402000	7370.658000	0.502091	30.010305
22009.200000	7377.680000	0.501728	29.999527
22012.968000	7384.985000	0.500885	30.006882
22016.746000	7392.472000	0.501966	29.990850
22020.584000	7400.142000	0.503098	29.995336
22024.352000	7407.892000	0.501513	30.005807
22028.110000	7415.136000	0.501677	30.006830
22031.908000	7422.806000	0.501926	30.007512
22035.736000	7430.151000	0.502385	30.001614
22039.604000	7438.165000	0.501777	30.009327
22043.352000	7445.692000	0.501801	30.000470
22047.170000	7453.605000	0.502195	30.002169
22050.948000	7461.456000	0.501698	30.005507
22054.686000	7468.903000	0.501173	30.001873
22058.414000	7476.431000	0.501262	29.996621
22062.212000	7483.250000	0.501647	30.003306
22066.020000	7491.709000	0.501496	30.015419
22069.808000	7499.034000	0.501060	29.997668
22073.626000	7506.460000	0.502017	30.000902
22077.344000	7513.705000	0.501629	30.006105
22081.152000	7521.516000	0.501947	30.004509
22084.930000	7528.882000	0.502408	29.992297
22088.678000	7536.470000	0.502323	30.001136
22092.456000	7544.605000	0.501902	30.009203
22096.264000	7552.072000	0.500894	29.999685
22100.002000	7559.033000	0.501031	29.995887
22103.770000	7566.662000	0.500330	30.001250
22107.578000	7574.271000	0.500626	29.998364
22111.436000	7582.304000	0.500585	30.000705
22115.264000	7589.346000	0.499915	30.008017
22119.052000	7597.258000	0.501146	29.994826
22122.790000	7604.786000	0.500936	29.997220
22126.558000	7611.525000	0.500373	29.993529
22130.366000	7619.761000	0.501736	30.000055
22134.154000	7627.531000	0.501053	30.004113
22137.942000	7635.322000	0.500485	30.002867
22141.730000	7642.769000	0.499943	29.998407
22145.528000	7650.843000	0.499948	30.002552
22149.266000	7657.925000	0.498925	30.000648
22153.094000	7664.380000	0.500620	30.000324
22156.872000	7672.839000	0.501166	30.008877
22160.680000	7680.731000	0.500715	30.002416
22164.488000	7688.016000	0.501067	30.008427
22168.296000	7695.625000	0.500845	30.003192
22172.084000	7703.092000	0.500831	30.000495
22175.862000	7711.085000	0.500201	30.007625
22179.681000	7719.037000	0.499498	30.006533
22183.499000	7726.565000	0.498447	30.002701
22187.297000	7733.971000	0.498074	30.002132
22191.085000	7741.297000	0.499325	29.997504
22194.823000	7748.946000	0.498776	30.008877
22198.631000	7756.676000	0.499610	30.002050
22202.399000	7763.940000	0.499717	29.992091
22206.227000	7771.711000	0.499319	30.006880
22209.985000	7779.117000	0.498765	30.013809
22213.763000	7786.483000	0.498946	30.002738
22217.561000	7794.031000	0.498924	30.001851
22221.369000	7802.125000	0.499253	29.999092
22225.157000	7809.673000	0.498344	30.002431
22228.965000	7817.120000	0.498138	29.999317
22232.733000	7824.810000	0.497577	30.004518
22236.521000	7832.398000	0.497221	30.004345
22240.349000	7840.270000	0.497906	30.005418
22244.137000	7847.575000	0.496960	29.997588
22247.905000	7855.285000	0.497858	30.002280
22251.813000	7862.873000	0.497176	29.998216
22255.581000	7869.693000	0.497482	30.005349
22259.379000	7877.868000	0.498608	29.992246
22263.117000	7885.800000	0.498209	29.999240
22266.945000	7893.045000	0.496364	30.008535
22270.703000	7900.856000	0.496827	29.997530
22274.461000	7908.181000	0.497036	29.995165
22278.219000	7915.769000	0.497708	29.998704
22282.057000	7922.872000	0.497814	29.998983
22285.835000	7931.128000	0.497692	30.013051
22289.663000	7938.474000	0.497096	30.012365
22293.451000	7946.083000	0.498038	30.004184
22297.239000	7953.529000	0.497304	30.003241
22301.107000	7961.523000	0.497458	30.007024
22304.905000	7968.888000	0.497909	30.000683
22308.773000	7976.962000	0.497944	30.003678
22312.591000	7984.551000	0.496304	29.999576
22316.369000	7992.200000	0.497220	30.008992
22320.197000	7999.242000	0.497088	30.004372
22321.557000	8002.095000	0.496546	29.993554