File: velstep7_BRAVA_expb819_basalt_Giacomel_et_al_2021.txt
Time(s)	Displ(microns)	Friction	Effective_Normal_stress(MPa)
11745.633000	9983.126742	0.608176	19.964652
11745.637000	9983.480753	0.608694	19.959540
11745.641000	9983.680740	0.609062	19.946496
11745.645000	9983.944126	0.608772	19.963225
11745.649000	9984.771854	0.608663	19.960502
11745.653000	9985.042843	0.608672	19.961226
11745.657000	9985.435895	0.608299	19.974927
11745.661000	9986.130586	0.608434	19.965178
11745.665000	9986.449660	0.608773	19.952545
11745.669000	9986.365863	0.607716	19.946954
11745.673000	9986.664807	0.607630	19.957252
11745.677000	9987.937484	0.607551	19.952072
11745.681000	9987.613321	0.607877	19.943925
11745.685000	9988.941291	0.607506	19.964560
11745.689000	9989.016025	0.607756	19.956001
11745.693000	9989.516572	0.607325	19.958961
11745.697000	9989.732523	0.606851	19.963141
11745.701000	9989.510429	0.606488	19.955253
11745.705000	9990.229526	0.607151	19.955772
11745.709000	9990.622135	0.607247	19.954300
11745.713000	9990.625418	0.608800	19.949792
11745.717000	9991.761367	0.608604	19.955749
11745.721000	9991.107353	0.607169	19.973630
11745.725000	9992.673575	0.607966	19.954788
11745.729000	9992.708902	0.608283	19.956100
11745.733000	9993.794702	0.608328	19.956710
11745.737000	9993.356758	0.608936	19.957069
11745.741000	9993.592961	0.608007	19.961158
11745.745000	9994.286300	0.608561	19.952744
11745.749000	9995.555078	0.608161	19.958549
11745.753000	9995.530193	0.608346	19.954384
11745.757000	9995.523512	0.607467	19.958282
11745.761000	9995.668079	0.606239	19.955177
11745.765000	9996.251636	0.607086	19.953857
11745.769000	9996.030161	0.607564	19.944871
11745.773000	9996.529180	0.607880	19.955818
11745.777000	9997.787546	0.608550	19.958907
11745.781000	9997.451726	0.608645	19.959686
11745.785000	9998.863223	0.609131	19.960349
11745.789000	9999.768685	0.608674	19.954788
11745.793000	9999.494386	0.608104	19.951828
11745.797000	9999.888990	0.607332	19.945123
11745.801000	9999.872991	0.606549	19.945520
11745.805000	9999.729708	0.606990	19.953011
11745.809000	10001.061816	0.606791	19.966963
11745.813000	10001.331300	0.608453	19.970144
11745.817000	10001.343460	0.608788	19.954140
11745.821000	10002.206984	0.607954	19.959411
11745.825000	10002.140844	0.609132	19.947137
11745.829000	10003.143356	0.608394	19.964118
11745.833000	10003.216285	0.608433	19.968817
11745.837000	10004.156792	0.608111	19.951874
11745.841000	10003.780455	0.607608	19.947251
11745.845000	10003.750453	0.607673	19.956024
11745.849000	10004.590364	0.607589	19.972234
11745.853000	10005.306678	0.608597	19.976636
11745.857000	10005.991139	0.609126	19.964995
11745.861000	10006.153388	0.608501	19.953659
11745.865000	10006.768595	0.608078	19.946130
11745.869000	10007.205800	0.607668	19.948090
11745.873000	10007.057470	0.608193	19.943903
11745.877000	10008.068311	0.607563	19.970136
11745.881000	10008.492067	0.607598	19.966124
11745.885000	10007.845979	0.608116	19.962531
11745.889000	10008.328074	0.607734	19.955185
11745.893000	10009.313855	0.608334	19.957916
11745.897000	10009.644740	0.609061	19.947510
11745.901000	10009.594732	0.608204	19.965712
11745.905000	10010.291111	0.608303	19.962782
11745.909000	10010.827358	0.608638	19.959113
11745.913000	10010.985584	0.608837	19.963370
11745.917000	10011.559669	0.608679	19.951660
11745.921000	10012.302390	0.608693	19.950341
11745.925000	10012.626634	0.609334	19.946549
11745.929000	10012.944169	0.608072	19.949997
11745.933000	10012.709715	0.607808	19.960883
11745.937000	10013.554562	0.607323	19.962493
11745.941000	10013.443982	0.607196	19.969450
11745.945000	10014.707769	0.608336	19.947999
11745.949000	10014.640666	0.608291	19.947038
11745.953000	10015.381428	0.608642	19.952004
11745.957000	10015.915351	0.608405	19.958320
11745.961000	10016.149509	0.607172	19.964011
11745.965000	10016.297152	0.607039	19.967070
11745.969000	10015.876198	0.607280	19.952683
11745.973000	10017.415208	0.608345	19.942529
11745.977000	10018.088307	0.608844	19.950394
11745.981000	10017.871954	0.607519	19.969259
11745.985000	10018.239259	0.607504	19.971105
11745.989000	10019.042030	0.607410	19.959396
11745.993000	10019.592518	0.608031	19.959617
11745.997000	10018.880017	0.608797	19.940187
11746.001000	10019.969260	0.608186	19.949708
11746.005000	10020.972423	0.608855	19.966795
11746.009000	10020.356739	0.608226	19.972928
11746.013000	10020.754941	0.608124	19.949410
11746.017000	10021.354404	0.608059	19.944848
11746.021000	10022.028666	0.607686	19.953491
11746.025000	10022.466920	0.608128	19.967139
11746.029000	10023.007727	0.608001	19.967429
11746.033000	10023.270610	0.608270	19.969076
11746.037000	10023.817830	0.608099	19.952751
11746.041000	10024.019336	0.608328	19.944497
11746.045000	10024.582970	0.607894	19.959922
11746.049000	10024.483189	0.608063	19.945336
11746.053000	10025.287080	0.608279	19.957649
11746.057000	10025.483466	0.608619	19.965605
11746.061000	10025.900333	0.607414	19.972020
11746.065000	10025.945759	0.608194	19.955131
11746.069000	10026.862605	0.608072	19.943826
11746.073000	10028.173926	0.608886	19.948197
11746.077000	10027.847196	0.608122	19.963721
11746.081000	10027.838837	0.606992	19.968786
11746.085000	10028.401456	0.607031	19.967680
11746.089000	10028.538503	0.607244	19.955704
11746.093000	10028.654074	0.607865	19.949914
11746.097000	10030.066219	0.608051	19.950677
11746.101000	10030.345802	0.608169	19.948014
11746.105000	10030.506539	0.607596	19.969931
11746.109000	10031.322525	0.606905	19.963370
11746.113000	10031.483623	0.607473	19.954574
11746.117000	10030.597352	0.607754	19.940515
11746.121000	10030.959675	0.607088	19.968672
11746.125000	10031.822934	0.609576	19.961715
11746.129000	10032.683095	0.609840	19.962882
11746.133000	10033.299085	0.610576	19.954651
11746.137000	10034.220556	0.609864	19.953980
11746.141000	10034.204427	0.608905	19.956238
11746.145000	10034.514361	0.608526	19.964751
11746.149000	10035.027666	0.607498	19.959686
11746.153000	10035.456597	0.608050	19.962401
11746.157000	10035.197131	0.608929	19.949662
11746.161000	10036.381794	0.607680	19.954124
11746.165000	10037.135717	0.608203	19.950387
11746.169000	10036.410877	0.607092	19.954544
11746.173000	10036.865162	0.607017	19.950913
11746.177000	10037.530565	0.607765	19.950951
11746.181000	10038.193864	0.607992	19.951294
11746.185000	10038.246141	0.608600	19.957496
11746.189000	10038.688755	0.608235	19.949814
11746.193000	10038.965970	0.608441	19.955841
11746.197000	10040.019129	0.608532	19.947320
11746.201000	10040.421175	0.608612	19.952599
11746.205000	10040.829418	0.608003	19.962066
11746.209000	10040.450158	0.607068	19.972097
11746.213000	10041.350624	0.607261	19.963034
11746.217000	10041.638568	0.607959	19.961448
11746.221000	10041.657505	0.608728	19.950142
11746.225000	10042.505217	0.609013	19.957275
11746.229000	10042.682902	0.609111	19.955688
11746.233000	10042.997223	0.609221	19.956886
11746.237000	10043.634899	0.608329	19.964507
11746.241000	10044.545716	0.607681	19.966551
11746.245000	10044.467155	0.607955	19.952858
11746.249000	10044.720972	0.607349	19.952523
11746.253000	10045.293279	0.607966	19.949959
11746.257000	10045.465704	0.608059	19.954628
11746.261000	10045.247625	0.607093	19.982937
11746.265000	10046.393437	0.608250	19.959907
11746.269000	10046.626414	0.608410	19.958137
11746.273000	10047.155189	0.610031	19.962516
11746.277000	10047.961081	0.609864	19.960136
11746.281000	10047.793714	0.608464	19.965132
11746.285000	10048.647124	0.607991	19.959640
11746.289000	10048.690991	0.607156	19.952889
11746.293000	10049.045654	0.607966	19.944825
11746.297000	10049.695546	0.607783	19.957328
11746.301000	10050.171402	0.607781	19.965880
11746.305000	10049.547683	0.607707	19.957283
11746.309000	10050.764698	0.607442	19.955047
11746.313000	10051.018433	0.608186	19.972410
11746.317000	10051.597749	0.608873	19.963072
11746.321000	10052.276830	0.608479	19.954178
11746.325000	10052.594210	0.608756	19.958755
11746.329000	10052.992475	0.607870	19.959952
11746.333000	10053.469529	0.607691	19.969267
11746.337000	10053.888451	0.607941	19.958625
11746.341000	10053.885392	0.607614	19.947572
11746.345000	10053.939845	0.607781	19.952774
11746.349000	10054.935841	0.607532	19.956008
11746.353000	10055.189663	0.608376	19.954674
11746.357000	10055.657507	0.608386	19.963317
11746.361000	10055.500879	0.608261	19.959312
11746.365000	10056.252525	0.608899	19.938570
11746.369000	10056.523320	0.608489	19.950135
11746.373000	10057.363944	0.608134	19.965926
11746.377000	10057.612436	0.608442	19.966963
11746.381000	10057.942573	0.608649	19.944276
11746.385000	10058.811657	0.608542	19.956642
11746.389000	10058.694400	0.608007	19.956505
11746.393000	10059.266683	0.608174	19.969198
11746.397000	10059.890340	0.608680	19.965163
11746.401000	10060.141197	0.608398	19.970015
11746.405000	10060.492629	0.608958	19.953438
11746.409000	10060.560258	0.608121	19.949837
11746.413000	10060.758446	0.608239	19.943910
11746.417000	10062.094338	0.608305	19.948243
11746.421000	10061.802697	0.607843	19.953796
11746.425000	10062.548460	0.607709	19.962775
11746.429000	10062.773819	0.607391	19.964118
11746.433000	10063.287903	0.607600	19.979039
11746.437000	10063.709162	0.608291	19.963164
11746.441000	10063.967909	0.608104	19.955520
11746.445000	10064.757935	0.608386	19.947274
11746.449000	10064.831978	0.607655	19.949410
11746.453000	10065.746032	0.607665	19.966399
11746.457000	10065.184833	0.607353	19.980725
11746.461000	10066.135731	0.607028	19.976079
11746.465000	10066.593265	0.608285	19.951401
11746.469000	10066.757375	0.608051	19.942179
11746.473000	10067.245274	0.608375	19.945481
11746.477000	10067.644968	0.608248	19.960685
11746.481000	10066.998056	0.607682	19.964347
11746.485000	10068.346191	0.608134	19.972760
11746.489000	10068.804802	0.608204	19.973119
11746.493000	10069.497479	0.609148	19.963119
11746.497000	10069.822052	0.609429	19.943719
11746.501000	10069.617967	0.608471	19.952400
11746.505000	10070.397841	0.608261	19.959830
11746.509000	10070.566011	0.608330	19.962432
11746.513000	10071.642505	0.608091	19.958144
11746.517000	10071.516030	0.607814	19.972448
11746.521000	10071.977735	0.608028	19.948197
11746.525000	10072.520289	0.608403	19.946534
11746.529000	10072.864096	0.608182	19.949410
11746.533000	10073.200843	0.608153	19.964369
11746.537000	10073.785689	0.608129	19.963751
11746.541000	10073.622633	0.608064	19.959960
11746.545000	10074.626640	0.607722	19.965239
11746.549000	10074.769192	0.608776	19.939295
11746.553000	10075.680334	0.609163	19.929050
11746.557000	10075.134227	0.608252	19.952515
11746.561000	10075.633793	0.607168	19.970968
11746.565000	10076.274131	0.607903	19.969938
11746.569000	10076.690514	0.607798	19.963790
11746.573000	10077.374364	0.609039	19.952385
11746.577000	10077.683545	0.608531	19.958564
11746.581000	10077.889652	0.608044	19.953675
11746.585000	10077.942256	0.608441	19.950257
11746.589000	10078.332798	0.608074	19.959548
11746.593000	10079.024886	0.609425	19.955330
11746.597000	10079.827046	0.609820	19.951226
11746.601000	10080.442966	0.608322	19.969168
11746.605000	10080.762067	0.608105	19.962851
11746.609000	10080.608238	0.607307	19.954765
11746.613000	10081.459229	0.607605	19.948929
11746.617000	10081.472137	0.607758	19.953377
11746.621000	10081.850244	0.607561	19.952354
11746.625000	10082.788816	0.608593	19.948968
11746.629000	10083.320345	0.607738	19.960380
11746.633000	10082.846004	0.607670	19.963301
11746.637000	10083.848186	0.607248	19.955734
11746.641000	10083.369142	0.606621	19.955993
11746.645000	10084.114257	0.607341	19.946664
11746.649000	10084.271555	0.607209	19.971701
11746.653000	10085.674092	0.608711	19.969221
11746.657000	10085.644293	0.609396	19.972890
11746.661000	10086.026457	0.608629	19.956367
11746.665000	10086.149600	0.608917	19.950318
11746.669000	10086.672858	0.608366	19.946481
11746.673000	10087.376874	0.609017	19.956314
11746.677000	10087.539855	0.608212	19.961913
11746.681000	10088.457548	0.607064	19.968535
11746.685000	10088.337045	0.608086	19.953087
11746.689000	10088.376877	0.607592	19.951531
11746.693000	10088.985056	0.608060	19.951455
11746.697000	10090.215239	0.608490	19.958061
11746.701000	10090.450155	0.608498	19.961814
11746.705000	10090.449501	0.608758	19.958564
11746.709000	10091.178743	0.608090	19.955071
11746.713000	10091.209451	0.608674	19.961845
11746.717000	10091.736215	0.608424	19.962241
11746.721000	10091.903342	0.607990	19.948655
11746.725000	10092.830575	0.608001	19.954132
11746.729000	10092.676166	0.608215	19.955742
11746.733000	10093.221632	0.608317	19.964049
11746.737000	10093.739101	0.608750	19.963957
11746.741000	10094.253866	0.608275	19.958381
11746.745000	10094.679321	0.609479	19.944947
11746.749000	10094.431663	0.608319	19.942651
11746.753000	10095.318692	0.608528	19.940241
11746.757000	10096.204436	0.607635	19.966704
11746.761000	10095.605509	0.607339	19.972913
11746.765000	10096.132995	0.608069	19.954651
11746.769000	10096.763609	0.607457	19.967520
11746.773000	10097.353170	0.608717	19.944230
11746.777000	10097.558480	0.608541	19.956764
11746.781000	10097.804580	0.607722	19.954842
11746.785000	10098.334741	0.608379	19.956008
11746.789000	10097.961587	0.609156	19.956360
11746.793000	10098.908550	0.609057	19.960624
11746.797000	10100.040723	0.609300	19.947633
11746.801000	10100.111561	0.608631	19.945344
11746.805000	10100.779151	0.608047	19.959777
11746.809000	10101.242070	0.607617	19.955063
11746.813000	10101.238788	0.607463	19.969687
11746.817000	10101.740165	0.607057	19.966498
11746.821000	10101.927196	0.607543	19.956459
11746.825000	10102.181274	0.608454	19.942865
11746.829000	10102.613934	0.608137	19.954445
11746.833000	10103.260167	0.608678	19.955902
11746.837000	10103.212988	0.609202	19.950692
11746.841000	10104.016667	0.608144	19.953354
11746.845000	10104.563453	0.608721	19.962279
11746.849000	10104.715898	0.608380	19.961860
11746.853000	10105.692252	0.608293	19.964034
11746.857000	10104.963414	0.608350	19.959594
11746.861000	10106.004338	0.607676	19.954987
11746.865000	10106.037098	0.609091	19.949341
11746.869000	10106.675200	0.608293	19.963561
11746.873000	10107.016630	0.609284	19.957092
11746.877000	10107.261035	0.608622	19.965720
11746.881000	10107.705640	0.608013	19.954674
11746.885000	10109.113836	0.608607	19.955902
11746.889000	10108.788436	0.608537	19.963850
11746.893000	10109.151039	0.607997	19.949570
11746.897000	10109.223622	0.608118	19.946305
11746.901000	10109.840628	0.607820	19.962501
11746.905000	10110.224866	0.608334	19.956939
11746.909000	10110.914983	0.608316	19.960921
11746.913000	10111.695235	0.608681	19.946847
11746.917000	10111.544999	0.608547	19.957313
11746.921000	10112.238996	0.607807	19.963736
11746.925000	10112.638019	0.608482	19.952980
11746.929000	10113.226100	0.607584	19.960113
11746.933000	10113.030150	0.608333	19.948380
11746.937000	10114.184066	0.607928	19.953301
11746.941000	10114.091449	0.607114	19.970411
11746.945000	10114.255588	0.607325	19.962935
11746.949000	10114.794430	0.606619	19.965872
11746.953000	10115.574782	0.607922	19.961066
11746.957000	10115.458124	0.608187	19.952690
11746.961000	10116.476649	0.607882	19.955505
11746.965000	10116.298209	0.607735	19.963522
11746.969000	10116.590684	0.607336	19.956070
11746.973000	10116.893375	0.608836	19.956550
11746.977000	10117.019098	0.610077	19.944284
11746.981000	10117.782024	0.609680	19.946420
11746.985000	10118.901606	0.610096	19.959701
11746.989000	10119.069326	0.608823	19.971860
11746.993000	10119.601484	0.608552	19.960853
11746.997000	10119.858760	0.607711	19.958603
11747.001000	10120.004232	0.607485	19.942460
11747.005000	10120.060604	0.608089	19.941316
11747.009000	10120.885072	0.607373	19.964583
11747.013000	10121.549306	0.608645	19.970777
11747.017000	10121.282619	0.608538	19.970671
11747.021000	10122.395221	0.608380	19.955727
11747.025000	10122.340019	0.609176	19.943109
11747.029000	10123.128834	0.607507	19.962782
11747.033000	10123.416106	0.607682	19.949929
11747.037000	10123.149356	0.607435	19.953949
11747.041000	10124.178057	0.606835	19.966399
11747.045000	10124.542863	0.607972	19.964858
11747.049000	10125.008516	0.608393	19.959617
11747.053000	10125.447868	0.609040	19.949624
11747.057000	10125.495725	0.608877	19.950104
11747.061000	10126.164460	0.608174	19.947015
11747.065000	10126.828596	0.609093	19.954971
11747.069000	10126.238823	0.608269	19.967505
11747.073000	10126.438559	0.608027	19.963675
11747.077000	10127.788047	0.608128	19.967077
11747.081000	10128.580293	0.609390	19.958747
11747.085000	10128.472802	0.609984	19.942033
11747.089000	10128.826175	0.608624	19.952698
11747.093000	10129.232697	0.607504	19.964415
11747.097000	10129.231836	0.607002	19.967955
11747.101000	10129.253583	0.607247	19.946122
11747.105000	10130.292961	0.607610	19.946427
11747.109000	10130.550848	0.608211	19.955032
11747.113000	10130.620951	0.608839	19.963103
11747.117000	10131.692508	0.609175	19.965689
11747.121000	10131.783024	0.609440	19.954262
11747.125000	10132.906272	0.609155	19.958030
11747.129000	10132.657682	0.608874	19.945268
11747.133000	10133.428285	0.607812	19.961463
11747.137000	10133.351610	0.607517	19.967032
11747.141000	10133.915573	0.607192	19.964835
11747.145000	10134.970950	0.608424	19.962363
11747.149000	10135.111488	0.608665	19.948251
11747.153000	10135.468382	0.608509	19.947457
11747.157000	10135.155473	0.607278	19.963019
11747.161000	10136.489433	0.606801	19.963835
11747.165000	10136.588031	0.607489	19.957824
11747.169000	10136.752452	0.607046	19.948335
11747.173000	10136.710030	0.607221	19.951226
11747.177000	10137.750846	0.607829	19.951698
11747.181000	10138.025475	0.607465	19.973760
11747.185000	10138.425453	0.608355	19.960914
11747.189000	10139.230585	0.607646	19.962806
11747.193000	10139.823024	0.608174	19.954155
11747.197000	10139.516105	0.608079	19.949807
11747.201000	10140.262422	0.607659	19.950531
11747.205000	10140.725829	0.608915	19.951783
11747.209000	10140.406097	0.607933	19.960059
11747.213000	10140.739612	0.608153	19.961021
11747.217000	10141.337494	0.608748	19.964842
11747.221000	10141.657166	0.608660	19.954994
11747.225000	10142.822649	0.609449	19.945245
11747.229000	10142.833267	0.608722	19.967291
11747.233000	10143.322866	0.608825	19.954193
11747.237000	10143.214914	0.608449	19.950173
11747.241000	10144.120334	0.607773	19.947350
11747.245000	10145.146514	0.607950	19.958793
11747.249000	10144.874251	0.607804	19.952805
11747.253000	10145.260418	0.607887	19.951981
11747.257000	10145.204432	0.607263	19.961059
11747.261000	10145.811638	0.606860	19.963797
11747.265000	10146.267082	0.607688	19.964644
11747.269000	10146.686115	0.607646	19.960555
11747.273000	10147.588644	0.608529	19.956604
11747.277000	10148.289710	0.608969	19.945596
11747.281000	10148.367765	0.607939	19.956566
11747.285000	10148.355487	0.607001	19.960723
11747.289000	10148.479770	0.606151	19.965681
11747.293000	10149.685380	0.607236	19.959999
11747.297000	10149.062272	0.607900	19.957595
11747.301000	10149.860240	0.607216	19.960220
11747.305000	10150.561500	0.607502	19.972020
11747.309000	10151.067287	0.607484	19.960837
11747.313000	10151.096243	0.607905	19.953957
11747.317000	10151.502824	0.608598	19.943330
11747.321000	10151.541572	0.608761	19.952995
11747.325000	10152.010463	0.609605	19.944688
11747.329000	10152.385619	0.608517	19.971364
11747.333000	10153.134681	0.608538	19.982533
11747.337000	10153.462949	0.609416	19.955589
11747.341000	10154.308286	0.608813	19.956863
11747.345000	10154.573943	0.609200	19.956741
11747.349000	10155.108786	0.608562	19.945535
11747.353000	10155.248047	0.608080	19.954758
11747.357000	10156.089599	0.607479	19.956863
11747.361000	10156.409455	0.606940	19.954796
11747.365000	10156.689994	0.606741	19.956093
11747.369000	10157.088672	0.605701	19.970602
11747.373000	10157.379760	0.606713	19.964080
11747.377000	10157.490438	0.607108	19.958724
11747.381000	10157.955507	0.607030	19.953804
11747.385000	10158.709686	0.608517	19.947045
11747.389000	10158.927739	0.607624	19.965430
11747.393000	10159.494844	0.608025	19.970053
11747.397000	10160.047606	0.608355	19.961829
11747.401000	10159.866539	0.607664	19.952797
11747.405000	10160.804531	0.608533	19.944116
11747.409000	10160.086065	0.607925	19.952393
11747.413000	10161.419757	0.608043	19.957595
11747.417000	10161.765530	0.608419	19.959762
11747.421000	10161.908893	0.607968	19.957016
11747.425000	10162.591292	0.607837	19.967566
11747.429000	10162.476507	0.608023	19.961867
11747.433000	10163.364258	0.608750	19.955467
11747.437000	10163.909585	0.609663	19.951134
11747.441000	10164.092614	0.609436	19.948655
11747.445000	10164.702920	0.609143	19.960601
11747.449000	10165.148915	0.608291	19.969228
11747.453000	10165.594495	0.609162	19.952271
11747.457000	10165.943267	0.608521	19.946626
11747.461000	10165.845141	0.607439	19.955429
11747.465000	10166.562150	0.606678	19.962058
11747.469000	10166.471847	0.607112	19.962355
11747.473000	10167.133366	0.608138	19.955673
11747.477000	10167.429730	0.608817	19.958000
11747.481000	10167.740082	0.608203	19.961616
11747.485000	10168.145351	0.609209	19.958701
11747.489000	10168.244152	0.609200	19.949196
11747.493000	10169.294345	0.609844	19.959174
11747.497000	10169.817242	0.610145	19.961234
11747.501000	10169.996707	0.609109	19.950920
11747.505000	10170.793658	0.608976	19.956283
11747.509000	10170.447033	0.607892	19.960448
11747.513000	10171.112580	0.607556	19.959815
11747.517000	10171.802866	0.608210	19.946618
11747.521000	10171.939264	0.607945	19.948166
11747.525000	10172.643384	0.607517	19.968611
11747.529000	10172.843526	0.606626	19.974042
11747.533000	10172.815251	0.607449	19.963492
11747.537000	10173.530643	0.608056	19.943368
11747.541000	10173.532411	0.607896	19.958144
11747.545000	10174.343592	0.608625	19.952477
11747.549000	10174.778931	0.608586	19.963988
11747.553000	10176.012836	0.608412	19.961806
11747.557000	10175.829846	0.608246	19.951386
11747.561000	10175.918246	0.606801	19.953018
11747.565000	10176.449053	0.606719	19.952309
11747.569000	10176.513414	0.606202	19.948754
11747.573000	10177.055978	0.607164	19.952622
11747.577000	10177.833853	0.607275	19.950036
11747.581000	10177.957639	0.608601	19.949265
11747.585000	10179.156809	0.612451	19.964072
11747.589000	10180.068562	0.614564	19.969610
11747.593000	10181.256204	0.618369	19.963423
11747.597000	10182.417279	0.618753	19.963187
11747.601000	10184.408627	0.617725	19.963530
11747.605000	10185.676347	0.617699	19.948403
11747.609000	10186.428497	0.614071	19.943948
11747.613000	10188.336312	0.613204	19.950127
11747.617000	10189.320979	0.611909	19.960975
11747.621000	10189.519095	0.610750	19.946984
11747.625000	10191.430889	0.611142	19.944139
11747.629000	10192.551451	0.610555	19.941301
11747.633000	10194.627176	0.611670	19.935168
11747.637000	10196.147622	0.610502	19.949883
11747.641000	10196.688561	0.608147	19.961242
11747.645000	10198.241163	0.608965	19.942048
11747.649000	10199.011973	0.607474	19.936983
11747.653000	10200.398659	0.608319	19.939173
11747.657000	10201.248075	0.607845	19.952034
11747.661000	10202.265101	0.607460	19.951271
11747.665000	10203.569053	0.609165	19.940485
11747.669000	10204.849439	0.607932	19.946023
11747.673000	10205.632570	0.609499	19.954552
11747.677000	10207.533073	0.609202	19.945695
11747.681000	10208.661081	0.608587	19.934146
11747.685000	10210.533402	0.608592	19.939775
11747.689000	10211.201422	0.606854	19.935771
11747.693000	10212.178087	0.607437	19.937144
11747.697000	10213.727884	0.607355	19.926540
11747.701000	10214.706545	0.606379	19.933940
11747.705000	10216.383613	0.608230	19.932712
11747.709000	10216.956088	0.606511	19.941736
11747.713000	10218.392275	0.607851	19.949265
11747.717000	10219.787750	0.607610	19.951500
11747.721000	10220.907051	0.607547	19.949952
11747.725000	10221.467150	0.608348	19.934535
11747.729000	10222.887420	0.606775	19.936373
11747.733000	10224.325010	0.608460	19.944291
11747.737000	10225.601330	0.607916	19.952072
11747.741000	10226.453935	0.607258	19.943109
11747.745000	10228.376903	0.608303	19.929180
11747.749000	10228.529960	0.606468	19.941240
11747.753000	10230.056049	0.607544	19.947541
11747.757000	10231.333457	0.607663	19.933535
11747.761000	10232.532785	0.607621	19.933261
11747.765000	10233.976973	0.608418	19.945687
11747.769000	10235.226187	0.607053	19.934832
11747.773000	10236.752526	0.608167	19.936312
11747.777000	10237.554135	0.607971	19.930530
11747.781000	10238.978778	0.605850	19.943269
11747.785000	10239.706416	0.607456	19.936381
11747.789000	10241.004383	0.605866	19.939951
11747.793000	10241.821969	0.608231	19.933985
11747.797000	10243.775719	0.607456	19.935717
11747.801000	10244.695373	0.606570	19.946618
11747.805000	10246.111975	0.607691	19.945756
11747.809000	10247.234285	0.606507	19.936304
11747.813000	10248.539263	0.607655	19.928935
11747.817000	10248.931703	0.606260	19.943735
11747.821000	10250.340199	0.606343	19.930805
11747.825000	10252.567797	0.607973	19.934603
11747.829000	10252.755770	0.606652	19.936289
11747.833000	10254.891518	0.607758	19.940813
11747.837000	10255.263137	0.607516	19.947930
11747.841000	10256.556073	0.605560	19.943208
11747.845000	10258.127954	0.607840	19.931438
11747.849000	10258.337835	0.606934	19.915052
11747.853000	10260.369965	0.608271	19.928203
11747.857000	10261.489677	0.608087	19.938852
11747.861000	10262.520728	0.607167	19.955650
11747.865000	10264.777970	0.608011	19.942697
11747.869000	10265.554872	0.606215	19.936671
11747.873000	10266.843413	0.606663	19.932124
11747.877000	10267.820074	0.605847	19.921330
11747.881000	10268.078386	0.604892	19.934168
11747.885000	10269.859455	0.606851	19.944299
11747.889000	10270.629262	0.606079	19.951905
11747.893000	10272.530094	0.608747	19.943285
11747.897000	10273.670791	0.608299	19.931346
11747.901000	10275.098771	0.606973	19.926723
11747.905000	10275.674804	0.607445	19.933055
11747.909000	10277.556668	0.605074	19.945977
11747.913000	10278.179423	0.606994	19.946084
11747.917000	10278.727750	0.606315	19.938913
11747.921000	10281.158906	0.606021	19.938570
11747.925000	10282.464432	0.608790	19.937251
11747.929000	10283.004793	0.606678	19.931941
11747.933000	10284.572080	0.607674	19.936320
11747.937000	10285.965817	0.607198	19.927753
11747.941000	10286.396373	0.606305	19.928485
11747.945000	10288.177401	0.606575	19.949921
11747.949000	10289.039060	0.605190	19.954414
11747.953000	10290.138161	0.607334	19.939013
11747.957000	10291.420600	0.606987	19.932803
11747.961000	10292.270391	0.607586	19.919202
11747.965000	10293.990138	0.607106	19.949502
11747.969000	10294.256701	0.606410	19.950730
11747.973000	10296.350824	0.607499	19.952622
11747.977000	10297.802675	0.607661	19.936449
11747.981000	10299.023351	0.606695	19.919682
11747.985000	10300.497539	0.607238	19.926586
11747.989000	10301.138069	0.605883	19.928584
11747.993000	10302.381888	0.606309	19.951462
11747.997000	10303.672191	0.606303	19.950021
11748.001000	10304.445641	0.606606	19.934359
11748.005000	10306.328854	0.607433	19.932925
11748.009000	10307.770937	0.606019	19.931636
11748.013000	10308.703813	0.607004	19.943086
11748.017000	10309.678860	0.606187	19.938608
11748.021000	10310.293650	0.605701	19.933284
11748.025000	10312.220615	0.607009	19.935068
11748.029000	10313.115140	0.606254	19.938227
11748.033000	10314.572758	0.607590	19.932780
11748.037000	10315.933079	0.607442	19.929050
11748.041000	10316.398919	0.606426	19.939661
11748.045000	10317.942573	0.607445	19.929195
11748.049000	10318.778145	0.606194	19.931758
11748.053000	10320.781519	0.607188	19.947610
11748.057000	10321.981136	0.607302	19.939569
11748.061000	10322.952910	0.606760	19.932162
11748.065000	10324.559774	0.606760	19.936213
11748.069000	10325.248049	0.604818	19.928821
11748.073000	10326.329693	0.606295	19.933154
11748.077000	10327.475283	0.606143	19.946305
11748.081000	10328.817750	0.606206	19.942018
11748.085000	10329.828318	0.607919	19.939569
11748.089000	10330.921964	0.606735	19.936938
11748.093000	10332.448832	0.607948	19.932917
11748.097000	10333.588171	0.607295	19.937296
11748.101000	10334.480758	0.605128	19.945657
11748.105000	10336.030472	0.606749	19.938707
11748.109000	10337.176088	0.605977	19.931949
11748.113000	10337.876331	0.607577	19.937388
11748.117000	10339.466283	0.606832	19.950486
11748.121000	10340.893903	0.607347	19.933238
11748.125000	10342.185217	0.607775	19.930957
11748.129000	10342.871980	0.605140	19.938669
11748.133000	10344.091295	0.606494	19.933749
11748.137000	10345.924669	0.607228	19.931323
11748.141000	10346.948475	0.606855	19.925297
11748.145000	10348.577419	0.607042	19.939524
11748.149000	10348.902097	0.604913	19.949562
11748.153000	10350.017207	0.606605	19.944055
11748.157000	10351.404684	0.607342	19.929553
11748.161000	10352.083045	0.607308	19.924046
11748.165000	10353.487572	0.607708	19.933482
11748.169000	10354.979491	0.606686	19.934290
11748.173000	10356.366080	0.607562	19.940020
11748.177000	10357.348294	0.606747	19.937876
11748.181000	10358.751591	0.605849	19.932948
11748.185000	10359.792140	0.606873	19.945222
11748.189000	10360.496669	0.605931	19.946115
11748.193000	10362.426425	0.607746	19.937762
11748.197000	10363.841243	0.607716	19.932887
11748.201000	10364.861043	0.606881	19.922161
11748.205000	10365.922320	0.606857	19.935733
11748.209000	10366.547004	0.605140	19.937655
11748.213000	10368.255299	0.606453	19.940058
11748.217000	10369.139051	0.606496	19.929836
11748.221000	10370.829728	0.605592	19.938829
11748.225000	10371.968197	0.606891	19.937167
11748.229000	10373.070466	0.605897	19.932917
11748.233000	10374.143779	0.606845	19.953293
11748.237000	10375.264563	0.607288	19.937838
11748.241000	10376.243497	0.607062	19.927906
11748.245000	10378.083807	0.608160	19.925983
11748.249000	10379.367159	0.606706	19.930339
11748.253000	10380.842361	0.607309	19.936274
11748.257000	10381.945476	0.606305	19.930934
11748.261000	10382.381973	0.605162	19.930949
11748.265000	10383.952580	0.606294	19.933230
11748.269000	10385.313519	0.605757	19.939981
11748.273000	10386.169659	0.607358	19.943444
11748.277000	10387.453538	0.607020	19.946648
11748.281000	10388.635285	0.606997	19.934123
11748.285000	10389.461312	0.608179	19.923626
11748.289000	10390.870782	0.606529	19.925396
11748.293000	10392.801179	0.607304	19.931537
11748.297000	10393.714333	0.606820	19.936923
11748.301000	10394.212955	0.605544	19.939303
11748.305000	10395.336450	0.607002	19.933398
11748.309000	10396.498790	0.606099	19.934054
11748.313000	10397.594846	0.608470	19.931186
11748.317000	10399.627710	0.607898	19.939089
11748.321000	10400.856456	0.608084	19.932132
11748.325000	10402.293878	0.608095	19.936014
11748.329000	10403.428085	0.605678	19.938303
11748.333000	10404.700762	0.606447	19.934069
11748.337000	10405.706014	0.605612	19.946511
11748.341000	10406.479294	0.605059	19.938692
11748.345000	10407.937959	0.606264	19.934031
11748.349000	10409.256881	0.605862	19.931369
11748.353000	10410.440895	0.607179	19.943750
11748.357000	10411.433472	0.606644	19.942644
11748.361000	10412.465139	0.605532	19.947083
11748.365000	10414.328310	0.607465	19.931659
11748.369000	10415.083064	0.606960	19.928508
11748.373000	10416.530643	0.607216	19.944619
11748.377000	10417.317187	0.607282	19.941202
11748.381000	10418.717719	0.606832	19.943323
11748.385000	10419.954815	0.607908	19.942682
11748.389000	10421.122869	0.606739	19.944315
11748.393000	10422.702212	0.607534	19.933406
11748.397000	10423.618858	0.606835	19.929233
11748.401000	10424.111846	0.605984	19.916425
11748.405000	10425.685425	0.606708	19.944543
11748.409000	10427.036382	0.605945	19.949776
11748.413000	10429.212464	0.607270	19.939478
11748.417000	10430.284100	0.607291	19.929523
11748.421000	10430.839505	0.605534	19.932894
11748.425000	10431.871026	0.606266	19.923984
11748.429000	10432.910134	0.605065	19.930087
11748.433000	10434.463217	0.606949	19.943697
11748.437000	10435.333888	0.607464	19.940828
11748.441000	10436.089553	0.607680	19.927456
11748.445000	10437.762607	0.608241	19.939775
11748.449000	10439.007871	0.606495	19.940393
11748.453000	10440.463073	0.607796	19.938295
11748.457000	10441.216140	0.607279	19.931399
11748.461000	10442.729895	0.606716	19.931133
11748.465000	10444.252326	0.607155	19.932399
11748.469000	10445.458043	0.605076	19.940752
11748.473000	10446.393753	0.606408	19.938837
11748.477000	10447.300944	0.606903	19.923962
11748.481000	10448.280817	0.607127	19.916204
11748.485000	10449.572269	0.607398	19.943803
11748.489000	10451.093869	0.606121	19.950722
11748.493000	10452.286866	0.607789	19.961425
11748.497000	10454.235883	0.607691	19.941332
11748.501000	10455.308514	0.606305	19.917005
11748.505000	10456.253292	0.606307	19.922512
11748.509000	10457.107586	0.604437	19.933123
11748.513000	10457.756888	0.606493	19.944924
11748.517000	10459.652105	0.606979	19.931338
11748.521000	10460.745777	0.607478	19.916112
11748.525000	10462.055043	0.607299	19.935740
11748.529000	10462.490417	0.606033	19.943384
11748.533000	10464.747628	0.607637	19.941255
11748.537000	10466.498917	0.607252	19.937845
11748.541000	10466.444207	0.606585	19.930805
11748.545000	10468.200439	0.606128	19.937273
11748.549000	10468.600605	0.605253	19.940096
11748.553000	10470.713457	0.607893	19.926487
11748.557000	10471.522849	0.608246	19.927593
11748.561000	10472.372504	0.606337	19.945283
11748.565000	10474.132118	0.607022	19.944330
11748.569000	10475.177404	0.605995	19.945138
11748.573000	10476.270813	0.607713	19.920308
11748.577000	10476.897374	0.607494	19.918286
11748.581000	10478.269011	0.606436	19.929843
11748.585000	10480.068155	0.607574	19.938570
11748.589000	10481.003708	0.605992	19.945077
11748.593000	10482.710937	0.607042	19.953194
11748.597000	10483.333198	0.607221	19.941202
11748.601000	10484.562323	0.606611	19.919476
11748.605000	10485.876835	0.608018	19.919721
11748.609000	10487.162454	0.605891	19.934115
11748.613000	10489.212838	0.607013	19.942773
11748.617000	10489.374807	0.606582	19.936091
11748.621000	10490.383755	0.605943	19.929271
11748.625000	10491.584582	0.607007	19.925198
11748.629000	10493.027153	0.605814	19.939791
11748.633000	10494.231167	0.607486	19.953881
11748.637000	10495.477722	0.607127	19.950013
11748.641000	10496.598240	0.606845	19.931201
11748.645000	10497.913506	0.607328	19.929126
11748.649000	10498.929384	0.606055	19.934725
11748.653000	10500.524246	0.607586	19.940111
11748.657000	10501.406209	0.607294	19.937311
11748.661000	10502.800141	0.606887	19.931849
11748.665000	10503.884440	0.607575	19.930980
11748.669000	10505.619704	0.605648	19.925045
11748.673000	10506.789724	0.607365	19.931247
11748.677000	10507.767471	0.606333	19.950890
11748.681000	10508.547261	0.605487	19.944017
11748.685000	10510.124168	0.606773	19.923176
11748.689000	10510.811350	0.605559	19.928165
11748.693000	10512.260299	0.606642	19.933368
11748.697000	10513.084834	0.606924	19.940729
11748.701000	10513.856383	0.606577	19.943910
11748.705000	10515.923209	0.607644	19.939745
11748.709000	10516.695101	0.607234	19.932399
11748.713000	10517.705464	0.608463	19.928119
11748.717000	10519.108863	0.607869	19.941942
11748.721000	10520.688957	0.607488	19.945962
11748.725000	10522.544797	0.608091	19.944612
11748.729000	10523.011724	0.606023	19.934107
11748.733000	10524.749920	0.606953	19.923840
11748.737000	10525.462356	0.606692	19.924732
11748.741000	10526.541066	0.606214	19.927677
11748.745000	10527.993439	0.607253	19.928134
11748.749000	10528.681306	0.605293	19.944917
11748.753000	10530.550445	0.607108	19.938837
11748.757000	10531.920051	0.607126	19.935976
11748.761000	10532.320631	0.606338	19.946664
11748.765000	10534.171373	0.607418	19.932673
11748.769000	10535.308395	0.606184	19.942422
11748.773000	10536.855501	0.607526	19.943971
11748.777000	10537.649884	0.606791	19.944085
11748.781000	10538.526482	0.605863	19.937510
11748.785000	10539.601137	0.607555	19.919850
11748.789000	10540.597000	0.606004	19.932109
11748.793000	10542.148373	0.607882	19.944230
11748.797000	10543.312683	0.608462	19.933017
11748.801000	10545.007605	0.607228	19.930370
11748.805000	10545.974190	0.606920	19.943651
11748.809000	10547.025243	0.605786	19.928218
11748.813000	10548.699147	0.607536	19.916501
11748.817000	10549.351362	0.607142	19.930331
11748.821000	10550.544857	0.605605	19.940828
11748.825000	10551.754726	0.606583	19.945520
11748.829000	10552.672630	0.605832	19.934954
11748.833000	10554.230879	0.606790	19.940149
11748.837000	10555.855433	0.606998	19.929538
11748.841000	10556.416407	0.606774	19.936426
11748.845000	10558.501211	0.607342	19.938715
11748.849000	10559.399923	0.605601	19.943406
11748.853000	10560.475143	0.606564	19.945436
11748.857000	10561.757439	0.606471	19.938921
11748.861000	10562.818135	0.606282	19.932368
11748.865000	10564.140041	0.607328	19.932307
11748.869000	10565.380388	0.606229	19.933482
11748.873000	10566.316700	0.607408	19.931346
11748.877000	10567.354080	0.606708	19.940241
11748.881000	10568.480158	0.606467	19.936709
11748.885000	10569.964887	0.607337	19.944025
11748.889000	10570.755055	0.606364	19.938150
11748.893000	10572.602021	0.607592	19.942529
11748.897000	10573.493708	0.607050	19.951554
11748.901000	10575.100582	0.606236	19.937609
11748.905000	10576.226110	0.607469	19.920216
11748.909000	10577.154920	0.605987	19.927738
11748.913000	10578.205064	0.607098	19.937884
11748.917000	10579.229280	0.606799	19.948571
11748.921000	10580.200641	0.606670	19.946191
11748.925000	10581.825479	0.608442	19.931270
11748.929000	10583.116607	0.607114	19.921696
11748.933000	10584.663612	0.607966	19.926990
11748.937000	10586.014811	0.606772	19.920903
11748.941000	10586.653838	0.605373	19.941019
11748.945000	10588.684770	0.606209	19.936426
11748.949000	10589.427541	0.605049	19.932902
11748.953000	10590.541751	0.606308	19.940142
11748.957000	10591.581486	0.606475	19.934779
11748.961000	10592.215780	0.606045	19.938845
11748.965000	10594.150871	0.607550	19.933070
11748.969000	10594.779607	0.606791	19.933299
11748.973000	10596.128369	0.607243	19.948365
11748.977000	10597.445561	0.607476	19.943094
11748.981000	10598.589302	0.607140	19.934397
11748.985000	10599.915580	0.608014	19.931392
11748.989000	10600.890715	0.606431	19.938097
11748.993000	10602.146413	0.607763	19.936732
11748.997000	10603.738408	0.606680	19.940500
11749.001000	10604.756253	0.606258	19.937067
11749.005000	10606.013668	0.606778	19.930713
11749.009000	10606.971892	0.606085	19.922047
11749.013000	10608.677252	0.607789	19.926533
11749.017000	10609.599782	0.607177	19.931933
11749.021000	10610.454603	0.605777	19.947732
11749.025000	10612.014430	0.606810	19.946153
11749.029000	10613.157087	0.606072	19.941759
11749.033000	10614.098808	0.608690	19.910108
11749.037000	10615.702853	0.608161	19.920483
11749.041000	10617.429403	0.606311	19.947175
11749.045000	10618.370750	0.606665	19.940836
11749.049000	10619.202085	0.605476	19.931537
11749.053000	10620.172139	0.606623	19.938555
11749.057000	10620.932368	0.606885	19.931308
11749.061000	10622.437605	0.606895	19.926883
11749.065000	10623.991268	0.607789	19.943856
11749.069000	10624.702097	0.605574	19.955170
11749.073000	10626.509984	0.607751	19.939791
11749.077000	10627.858498	0.607022	19.943635
11749.081000	10628.780368	0.606772	19.921605
11749.085000	10629.709261	0.607136	19.930560
11749.089000	10629.910032	0.606130	19.934901
11749.093000	10632.358189	0.607660	19.931773
11749.097000	10633.729927	0.607973	19.939013
11749.101000	10634.533370	0.606444	19.933878
11749.105000	10636.445733	0.607309	19.928622
11749.109000	10636.581314	0.605557	19.930248
11749.113000	10638.040678	0.606780	19.941072
11749.117000	10639.341965	0.606976	19.930492
11749.121000	10640.430174	0.606576	19.923161
11749.125000	10642.121038	0.608111	19.931438
11749.129000	10642.928743	0.606820	19.927791
11749.133000	10644.478819	0.607474	19.934077
11749.137000	10645.541281	0.606840	19.935320
11749.141000	10646.441568	0.606188	19.937716
11749.145000	10647.721801	0.607544	19.925861
11749.149000	10649.241848	0.606314	19.934908
11749.153000	10650.369183	0.608036	19.940286
11749.157000	10652.106167	0.606843	19.934290
11749.161000	10652.793763	0.605198	19.934367
11749.165000	10654.075243	0.606502	19.918126
11749.169000	10654.895179	0.605185	19.919148
11749.173000	10655.851018	0.606694	19.942712
11749.177000	10658.283175	0.606644	19.949250
11749.181000	10658.734418	0.606873	19.944093
11749.185000	10659.758932	0.607546	19.931186
11749.189000	10660.963233	0.605455	19.942117
11749.193000	10662.364168	0.607469	19.941515
11749.197000	10663.497718	0.606794	19.943078
11749.201000	10664.108197	0.606550	19.934946
11749.205000	10666.499432	0.608231	19.928798
11749.209000	10666.735007	0.606316	19.942728
11749.213000	10668.296380	0.606786	19.947953
11749.217000	10669.621414	0.607785	19.924099
11749.221000	10670.057999	0.606727	19.934199
11749.225000	10672.199856	0.607784	19.936801
11749.229000	10673.360651	0.606298	19.941499
11749.233000	10674.492123	0.607403	19.936762
11749.237000	10675.781003	0.606600	19.942842
11749.241000	10676.500995	0.605985	19.926769
11749.245000	10678.237009	0.606960	19.923565
11749.249000	10679.018006	0.606168	19.933184
11749.253000	10679.711950	0.607514	19.937662
11749.257000	10681.904641	0.607289	19.938776
11749.261000	10682.792087	0.607045	19.937121
11749.265000	10683.961826	0.607907	19.928318
11749.269000	10684.716224	0.605903	19.944780
11749.273000	10686.573579	0.607675	19.942003
11749.277000	10687.792766	0.606960	19.935115
11749.281000	10688.469798	0.606624	19.938685
11749.285000	10690.269523	0.607186	19.924816
11749.289000	10690.788350	0.606152	19.922596
11749.293000	10692.676935	0.606616	19.936884
11749.297000	10693.564621	0.606939	19.942835
11749.301000	10694.522701	0.605965	19.938013
11749.305000	10695.947435	0.606823	19.937281
11749.309000	10696.816051	0.605727	19.927776
11749.313000	10698.554862	0.607641	19.934039
11749.317000	10699.545015	0.607110	19.939478
11749.321000	10700.687052	0.606703	19.937929
11749.325000	10701.936685	0.607331	19.930408
11749.329000	10702.938428	0.605757	19.924091
11749.333000	10704.225574	0.607924	19.927898
11749.337000	10705.625597	0.607357	19.944505
11749.341000	10706.945383	0.606560	19.944459
11749.345000	10707.580157	0.607539	19.941698
11749.349000	10709.282498	0.605508	19.925304
11749.353000	10710.506098	0.607499	19.920224
11749.357000	10710.853647	0.606477	19.945085
11749.361000	10712.984132	0.605816	19.943697
11749.365000	10713.685313	0.607384	19.951683
11749.369000	10714.657294	0.606023	19.934832
11749.373000	10716.189227	0.607685	19.930942
11749.377000	10717.017183	0.607778	19.933863
11749.381000	10718.667432	0.606676	19.938624
11749.385000	10720.177000	0.607156	19.948426
11749.389000	10720.810969	0.605997	19.939325
11749.393000	10722.295117	0.607512	19.926746
11749.397000	10723.251746	0.607544	19.921414
11749.401000	10724.231332	0.607093	19.926495
11749.405000	10726.034088	0.608171	19.941362
11749.409000	10727.288742	0.606806	19.941171
11749.413000	10728.774295	0.607248	19.949715
11749.417000	10729.931420	0.607117	19.925144
11749.421000	10731.250773	0.606993	19.914655
11749.425000	10731.869973	0.606846	19.929309
11749.429000	10732.825884	0.604683	19.946298
11749.433000	10734.383182	0.606505	19.948350
11749.437000	10735.390509	0.607405	19.930568
11749.441000	10736.326231	0.606410	19.935061
11749.445000	10738.343022	0.607641	19.942415
11749.449000	10739.037853	0.606693	19.928424
11749.453000	10740.509493	0.607565	19.921338
11749.457000	10741.411252	0.606615	19.937754
11749.461000	10742.592768	0.605386	19.947587
11749.465000	10744.355266	0.607392	19.927631
11749.469000	10744.970623	0.606721	19.925144
11749.473000	10746.449484	0.607038	19.942117
11749.477000	10748.247404	0.607448	19.938616
11749.481000	10749.246732	0.607008	19.938013
11749.485000	10749.857935	0.606897	19.941553
11749.489000	10750.939462	0.605430	19.929859
11749.493000	10752.210356	0.607353	19.930835
11749.497000	10753.678221	0.607034	19.930972
11749.501000	10754.393426	0.606589	19.936045
11749.505000	10755.991444	0.607860	19.940447
11749.509000	10757.062438	0.606842	19.940630
11749.513000	10757.939365	0.607786	19.939455
11749.517000	10759.749730	0.607619	19.929393
11749.521000	10760.768360	0.606486	19.934992
11749.525000	10761.867344	0.606936	19.931140
11749.529000	10762.916278	0.605981	19.932223
11749.533000	10764.353287	0.607497	19.932597
11749.537000	10765.665928	0.607723	19.934313
11749.541000	10766.367370	0.606901	19.946191
11749.545000	10768.162518	0.607334	19.941324
11749.549000	10769.220125	0.606276	19.935038
11749.553000	10770.551194	0.608117	19.922261
11749.557000	10771.750388	0.607344	19.923664
11749.561000	10772.640178	0.606301	19.936190
11749.565000	10773.600648	0.606624	19.942232
11749.569000	10774.671721	0.606065	19.942186
11749.573000	10775.602492	0.607867	19.937228
11749.577000	10776.671457	0.607883	19.925823
11749.580000	10778.083078	0.606847	19.934199