File: velstep1_TR2_exp013_sepiolite.txt
Time(s)	Displ(microns)	Friction	EffectiveNormalstress(MPa)
8105.381000	1554.674000	0.536278	29.999476
8108.187000	1555.079000	0.534542	29.999406
8111.063000	1555.808000	0.535023	29.997608
8113.909000	1556.253000	0.535014	30.002082
8116.745000	1556.637000	0.535782	29.996589
8119.561000	1557.204000	0.534790	29.989957
8122.367000	1558.114000	0.534541	29.998520
8125.183000	1558.580000	0.535038	29.996338
8128.049000	1558.964000	0.535348	29.998030
8130.905000	1559.753000	0.535546	29.992253
8133.711000	1560.118000	0.534891	29.995120
8136.627000	1560.826000	0.535808	29.994892
8139.463000	1561.676000	0.535554	29.994642
8142.309000	1561.979000	0.535684	29.990661
8145.165000	1562.465000	0.535570	29.994308
8148.031000	1562.850000	0.535950	29.998915
8150.887000	1563.517000	0.536472	29.994096
8153.723000	1564.286000	0.535893	30.005263
8156.529000	1564.914000	0.536123	29.995437
8159.315000	1565.399000	0.536048	29.998191
8162.191000	1565.784000	0.537331	30.007584
8165.067000	1566.209000	0.535616	30.003305
8167.913000	1567.342000	0.538112	29.990365
8170.749000	1567.423000	0.538829	29.986075
8173.605000	1568.050000	0.538616	29.993471
8176.391000	1568.758000	0.538309	30.012071
8179.237000	1569.082000	0.538677	29.998622
8182.093000	1569.932000	0.538360	30.011090
8185.029000	1570.580000	0.539663	29.987136
8187.875000	1571.328000	0.538236	30.011019
8190.671000	1571.510000	0.539132	29.992299
8193.517000	1572.300000	0.539059	29.994442
8196.333000	1572.644000	0.538215	29.999737
8199.159000	1573.352000	0.539394	29.992460
8201.965000	1573.878000	0.539348	29.991693
8204.841000	1574.526000	0.539358	29.991574
8207.657000	1575.133000	0.538235	29.991949
8210.483000	1575.598000	0.538094	30.005618
8213.329000	1575.942000	0.538282	30.003057
8216.155000	1576.509000	0.538566	29.993536
8218.991000	1577.318000	0.539646	29.999011
8221.797000	1577.763000	0.539474	30.009784
8224.633000	1578.714000	0.538945	29.993043
8227.489000	1579.119000	0.538949	29.996029
8230.355000	1579.746000	0.538247	29.992791
8233.201000	1580.151000	0.537491	29.991848
8236.117000	1580.778000	0.538054	29.993622
8238.953000	1581.365000	0.537706	29.994854
8241.769000	1582.175000	0.536956	29.992462
8244.575000	1582.499000	0.536332	29.997130
8247.401000	1583.227000	0.535978	30.001272
8250.247000	1583.591000	0.536090	29.981880
8253.093000	1584.077000	0.536102	29.991409
8255.939000	1584.684000	0.534795	29.989536
8258.815000	1585.230000	0.534854	29.997434
8261.641000	1585.999000	0.535545	29.992022
8264.479000	1586.323000	0.535250	29.988380
8267.275000	1587.092000	0.536085	30.001021
8270.151000	1587.537000	0.535256	29.995233
8273.057000	1588.205000	0.534522	29.998568
8275.913000	1588.853000	0.534864	29.989451
8278.769000	1589.642000	0.535223	30.001501
8281.595000	1589.905000	0.535396	29.990903
8284.441000	1590.552000	0.535203	29.989205
8287.277000	1591.342000	0.535258	29.995233
8290.113000	1591.524000	0.533642	30.005005
8292.959000	1592.434000	0.534648	30.002750
8295.865000	1592.556000	0.534449	29.992271
8298.761000	1593.304000	0.534334	30.001883
8301.607000	1594.013000	0.534315	29.991315
8304.453000	1594.458000	0.533661	29.997952
8307.289000	1595.328000	0.534027	30.000835
8310.165000	1595.389000	0.534576	30.002087
8313.001000	1596.421000	0.534350	30.000479
8315.847000	1596.846000	0.534240	29.994062
8318.653000	1597.635000	0.533149	29.994841
8321.479000	1597.797000	0.531977	29.989452
8324.315000	1598.363000	0.532179	29.996436
8327.131000	1599.416000	0.532637	29.999481
8329.967000	1599.395000	0.532515	30.006372
8332.833000	1600.043000	0.532871	30.009551
8335.659000	1600.873000	0.532929	29.989567
8338.485000	1601.034000	0.533843	29.986862
8341.321000	1601.581000	0.532849	29.987964
8344.197000	1602.370000	0.533259	29.995128
8347.003000	1602.694000	0.533370	29.997998
8349.869000	1603.321000	0.533408	29.994957
8352.775000	1604.131000	0.533490	29.993842
8355.561000	1604.616000	0.533224	30.001360
8358.417000	1605.284000	0.533637	29.997897
8361.233000	1605.790000	0.533617	29.995739
8364.049000	1606.093000	0.532563	30.000721
8366.895000	1606.964000	0.534221	29.989734
8369.741000	1607.672000	0.533779	29.991574
8372.607000	1608.077000	0.533497	29.998300
8375.453000	1608.684000	0.534118	29.995223
8378.329000	1609.028000	0.532328	29.998711
8381.205000	1609.614000	0.532617	29.987975
8384.021000	1610.545000	0.533083	29.990378
8386.857000	1610.687000	0.532392	29.987047
8389.823000	1611.395000	0.533232	30.002155
8392.609000	1612.002000	0.533220	29.997152
8395.445000	1612.630000	0.532894	30.007062
8398.281000	1613.237000	0.532962	29.998294
8401.147000	1613.985000	0.533879	29.989117
8404.033000	1614.188000	0.533857	30.011565
8406.849000	1615.119000	0.534467	30.001559
8409.695000	1615.604000	0.533971	29.998214
8412.541000	1616.130000	0.533391	29.998866
8415.407000	1616.656000	0.533524	29.995739
8418.294000	1616.980000	0.532840	29.999597
8421.090000	1618.053000	0.533705	29.992226
8423.936000	1618.275000	0.534119	29.986550
8426.772000	1618.923000	0.534173	29.990908
8429.608000	1619.672000	0.532828	29.996639
8432.454000	1620.279000	0.533557	29.996934
8435.330000	1620.481000	0.532747	29.988222
8438.176000	1621.270000	0.532711	29.989874
8441.022000	1621.675000	0.532942	30.002125
8443.858000	1622.201000	0.533469	30.005842
8446.694000	1622.909000	0.533766	30.003362
8449.580000	1623.294000	0.533741	29.998662
8452.386000	1623.860000	0.533794	30.001501
8455.212000	1624.710000	0.533730	29.997575
8458.038000	1625.196000	0.533629	29.997494
8460.894000	1625.540000	0.533610	30.006339
8463.760000	1626.188000	0.533364	29.995370
8466.576000	1626.855000	0.533185	29.994126
8469.452000	1627.462000	0.533579	29.985028
8472.298000	1628.069000	0.533228	29.993606
8475.154000	1628.292000	0.533719	29.998551
8477.970000	1629.425000	0.533473	29.994036
8480.816000	1629.547000	0.533910	30.001121
8483.652000	1630.134000	0.534606	30.002901
8486.488000	1630.619000	0.534750	29.995079
8489.354000	1631.469000	0.534935	29.991379
8492.180000	1631.793000	0.534418	29.992125
8495.026000	1632.623000	0.534554	30.001272
8497.892000	1633.149000	0.534396	29.994225
8500.748000	1633.655000	0.534456	29.994311
8503.584000	1634.565000	0.533824	30.004237
8506.470000	1634.606000	0.533409	30.007533
8509.366000	1635.435000	0.534514	29.997485
8512.222000	1635.961000	0.533952	29.990505
8515.058000	1636.690000	0.534033	29.986409
8517.894000	1637.135000	0.534198	29.991588
8520.740000	1637.722000	0.533631	29.993116
8523.586000	1638.147000	0.532467	29.994929
8526.462000	1638.633000	0.533448	29.992646
8529.258000	1639.624000	0.533937	29.993076
8532.114000	1639.725000	0.533997	29.988974
8534.980000	1640.110000	0.533908	29.987485
8537.856000	1640.798000	0.535239	29.989676
8540.772000	1641.749000	0.534828	30.002077
8543.628000	1642.214000	0.534191	29.997269
8546.464000	1642.821000	0.534537	29.995804
8549.300000	1643.347000	0.535201	29.997376
8552.156000	1643.995000	0.534271	30.001820
8555.022000	1644.359000	0.535611	30.000123
8557.908000	1644.724000	0.535204	30.005369
8560.744000	1645.796000	0.535593	29.997550
8563.600000	1646.423000	0.535814	30.006720
8566.461000	1646.686000	0.535808	29.994346
8569.247000	1647.273000	0.536254	29.998863
8572.093000	1647.779000	0.536162	29.992245
8574.939000	1648.386000	0.536228	29.990013
8577.785000	1648.811000	0.537118	29.990055
8580.651000	1649.540000	0.536482	29.994124
8583.497000	1650.349000	0.536524	29.998793
8586.313000	1650.734000	0.537554	29.996605
8589.129000	1651.199000	0.535503	29.993986
8591.985000	1651.604000	0.535934	29.996059
8594.812000	1652.474000	0.537186	30.000495
8597.728000	1653.101000	0.537448	29.992242
8600.624000	1653.526000	0.536659	29.998996
8603.450000	1654.315000	0.536937	30.002325
8606.326000	1654.821000	0.535613	30.001881
8609.182000	1655.388000	0.535796	30.008344
8612.018000	1655.853000	0.536236	30.000855
8614.934000	1656.541000	0.535925	29.994202
8617.820000	1657.108000	0.534771	30.011307
8620.696000	1657.330000	0.536292	29.999444
8623.532000	1658.261000	0.536313	29.991906
8626.368000	1658.767000	0.536407	29.994074
8629.225000	1659.374000	0.535820	29.990043
8632.091000	1659.961000	0.535327	29.998566
8634.937000	1660.406000	0.535655	29.989280
8637.783000	1661.175000	0.535467	29.995387
8640.659000	1661.701000	0.534554	29.989420
8643.485000	1662.531000	0.534393	29.996197
8646.341000	1662.733000	0.533096	30.005821
8649.177000	1663.138000	0.534151	29.994791
8652.013000	1663.867000	0.534103	29.989057
8654.849000	1664.615000	0.532810	29.993794
8657.695000	1665.162000	0.532746	29.994877
8660.571000	1665.546000	0.532829	30.006605
8663.417000	1666.254000	0.532766	29.989297
8666.263000	1667.044000	0.532522	29.999838
8669.099000	1667.448000	0.533112	29.993194
8671.905000	1667.671000	0.532865	29.992626
8674.741000	1668.824000	0.532158	29.998880
8677.697000	1669.229000	0.531679	29.988991
8680.613000	1669.634000	0.532444	29.990317
8683.459000	1670.342000	0.532283	29.992203
8686.355000	1670.888000	0.531899	29.990173
8689.181000	1671.253000	0.531665	30.005972
8692.017000	1672.183000	0.532447	29.989462
8694.803000	1672.386000	0.532400	29.991430
8697.640000	1673.094000	0.532361	29.994454
8700.456000	1673.620000	0.532010	29.998181
8703.292000	1674.106000	0.532000	29.998973
8706.208000	1674.430000	0.531852	29.994134
8709.054000	1675.340000	0.531784	29.993581
8711.890000	1676.170000	0.531577	30.019006
8714.702000	1676.554000	0.531917	30.006284
8717.518000	1676.959000	0.531850	29.997235
8720.384000	1677.505000	0.532577	30.010989
8723.200000	1678.254000	0.532733	30.010423
8726.036000	1678.740000	0.531655	30.006187
8728.842000	1679.226000	0.531941	29.995237
8731.688000	1679.994000	0.533614	29.991451
8734.524000	1680.258000	0.532486	30.005889
8737.370000	1681.209000	0.532753	29.999016
8740.216000	1681.553000	0.533096	29.989070
8743.042000	1682.342000	0.532154	29.992703
8745.898000	1682.767000	0.532578	29.990778
8748.724000	1683.070000	0.532189	29.996200
8751.622000	1683.839000	0.531449	29.990569
8754.498000	1684.487000	0.532508	29.984993
8757.314000	1685.013000	0.532215	29.990498
8760.160000	1685.600000	0.532990	29.996736
8762.956000	1686.389000	0.532270	29.994304
8765.752000	1686.652000	0.531919	29.989389
8768.568000	1687.300000	0.531563	30.004507
8771.404000	1687.886000	0.531787	30.002638
8774.210000	1688.615000	0.532085	29.993712
8777.056000	1688.959000	0.532134	29.993758
8779.882000	1689.161000	0.531531	30.006515
8782.678000	1690.193000	0.531685	30.002054
8785.534000	1690.638000	0.531869	29.993363
8788.400000	1691.246000	0.531986	29.988716
8791.266000	1691.731000	0.531464	29.991348
8794.092000	1692.480000	0.531216	30.003268
8796.888000	1692.783000	0.531279	30.003238
8799.764000	1693.451000	0.531645	29.991363
8802.570000	1694.099000	0.532707	29.991260
8805.416000	1694.807000	0.532142	29.989565
8808.252000	1695.333000	0.532093	29.988964
8811.098000	1696.021000	0.532201	29.991663
8813.924000	1696.284000	0.531285	30.002037
8816.770000	1696.932000	0.531680	29.998657
8819.646000	1697.397000	0.532559	29.999637
8822.522000	1698.025000	0.531926	29.995847
8825.368000	1698.470000	0.532408	29.994972
8828.244000	1699.320000	0.532290	29.992179
8831.090000	1699.623000	0.531796	29.997977
8833.936000	1700.453000	0.532290	29.985642
8836.772000	1700.898000	0.533102	29.992462
8839.608000	1701.404000	0.532719	29.995708
8842.484000	1702.031000	0.532738	29.990277
8845.410000	1702.497000	0.532769	29.994962
8848.286000	1703.306000	0.532265	29.994440
8851.092000	1703.792000	0.533433	29.997244
8853.928000	1704.277000	0.534153	29.997364
8856.784000	1705.168000	0.534454	30.011933
8859.620000	1705.552000	0.533145	30.011637
8862.486000	1706.200000	0.534043	29.993410
8865.332000	1706.706000	0.533654	30.006027
8868.168000	1707.171000	0.533733	30.006971
8870.974000	1707.940000	0.533779	29.988069
8873.830000	1708.102000	0.534034	29.995118
8876.656000	1708.972000	0.532896	30.001142
8879.492000	1709.154000	0.532001	29.997239
8882.338000	1710.287000	0.531984	30.004181
8885.174000	1710.470000	0.532703	29.989442
8888.040000	1711.481000	0.532289	30.003425
8890.866000	1711.805000	0.532062	29.996612
8893.652000	1712.331000	0.532612	29.990656
8896.498000	1712.938000	0.532142	29.992930
8899.424000	1713.444000	0.532457	29.993964
8902.260000	1714.051000	0.532012	29.996974
8905.136000	1714.598000	0.532347	30.000077
8907.992000	1715.245000	0.532043	29.999591
8910.828000	1715.670000	0.532046	29.995088
8913.624000	1716.237000	0.531714	29.999675
8916.450000	1716.844000	0.532326	29.998936
8919.306000	1717.410000	0.532777	29.991665
8922.142000	1718.119000	0.531941	29.992948
8924.978000	1718.200000	0.532012	29.993498
8927.824000	1719.070000	0.531399	30.001314
8930.660000	1719.738000	0.531896	30.002582
8933.546000	1720.183000	0.531772	29.996847
8936.332000	1720.587000	0.532248	29.995692
8939.148000	1721.741000	0.531532	29.989894
8942.034000	1721.842000	0.531144	30.000248
8944.860000	1722.651000	0.532397	29.992093
8947.786000	1723.319000	0.532970	29.993332
8950.622000	1723.643000	0.532339	29.992938
8953.458000	1723.906000	0.531901	29.989947
8956.314000	1724.695000	0.532170	29.990139
8959.180000	1725.242000	0.532713	29.996883
8962.036000	1725.707000	0.532886	30.001486
8964.902000	1726.355000	0.534101	30.010099
8967.708000	1726.901000	0.534303	30.001594
8970.554000	1727.447000	0.534317	30.001815
8973.440000	1728.317000	0.534253	30.007516
8976.266000	1728.925000	0.534371	30.007414
8979.102000	1729.127000	0.534514	29.999015
8981.938000	1729.876000	0.534924	29.999111
8984.814000	1730.786000	0.535114	30.012950
8987.650000	1730.867000	0.534523	30.013897
8990.466000	1731.515000	0.534507	30.007202
8993.312000	1732.061000	0.534293	30.000854
8996.139000	1732.567000	0.534169	30.002333
8998.945000	1732.992000	0.534142	29.993722
9001.821000	1733.700000	0.534650	30.001677
9004.657000	1734.105000	0.535340	29.996623
9007.513000	1735.036000	0.534945	29.998701
9010.349000	1735.440000	0.534786	30.001870
9013.145000	1736.048000	0.534348	29.993677
9015.981000	1736.837000	0.534928	29.987868
9018.827000	1737.545000	0.534539	29.994404
9021.663000	1737.505000	0.534362	29.992757
9024.539000	1738.314000	0.534408	29.991604
9027.385000	1738.840000	0.533606	29.994522
9030.201000	1739.609000	0.534250	29.995702
9033.027000	1740.014000	0.534996	30.000256
9035.913000	1740.924000	0.534192	29.998254
9038.779000	1741.147000	0.533913	29.998608
9041.585000	1741.673000	0.534782	29.993101
9044.431000	1742.159000	0.533650	30.001046
9047.277000	1742.988000	0.534487	29.991677
9050.133000	1743.373000	0.534605	29.991009
9052.959000	1744.263000	0.533252	29.996923
9055.785000	1744.769000	0.534259	29.991962
9058.631000	1745.396000	0.534433	29.993187
9061.467000	1745.579000	0.533840	29.996498
9064.313000	1746.408000	0.533339	29.989683
9067.149000	1746.934000	0.533995	29.990896
9070.025000	1747.582000	0.533419	30.000060
9072.831000	1747.865000	0.533506	30.001046
9075.707000	1748.837000	0.533938	30.003081
9078.543000	1749.363000	0.533093	30.004563
9081.429000	1749.788000	0.533091	30.004412
9084.275000	1750.617000	0.532349	30.003953
9087.111000	1751.083000	0.531377	30.006105
9089.987000	1751.670000	0.531845	29.997885
9092.833000	1751.993000	0.531941	29.996438
9095.709000	1752.803000	0.531974	30.001314
9098.545000	1753.835000	0.532018	29.992867
9101.361000	1753.794000	0.531033	29.999449
9104.227000	1754.543000	0.531334	29.992087
9107.073000	1754.988000	0.531762	29.988557
9109.929000	1755.393000	0.531263	29.996423
9112.765000	1755.899000	0.532023	29.989387
9115.551000	1756.668000	0.531625	29.997165
9118.418000	1757.315000	0.532534	29.999300
9121.234000	1758.024000	0.531976	30.003329
9124.070000	1758.590000	0.530325	30.007928
9126.926000	1759.035000	0.531096	29.996038
9129.802000	1759.602000	0.530487	30.002184
9132.628000	1759.926000	0.530639	29.993043
9135.525000	1760.715000	0.531124	29.986069
9138.311000	1761.302000	0.531414	29.994462
9141.187000	1761.990000	0.530742	30.000814
9144.033000	1762.354000	0.531246	29.999285
9146.919000	1763.184000	0.530227	29.987880
9149.755000	1763.730000	0.530486	29.988909
9152.592000	1764.175000	0.530058	29.987881
9155.518000	1764.681000	0.530119	29.997418
9158.374000	1765.531000	0.530243	29.992902
9161.200000	1765.652000	0.529891	29.990728
9164.076000	1766.523000	0.529416	29.989840
9166.912000	1767.433000	0.529918	29.995392
9169.768000	1767.777000	0.530252	30.000324
9172.604000	1768.040000	0.530148	29.991121
9175.410000	1768.485000	0.529637	29.998588
9178.236000	1769.072000	0.529502	30.008773
9181.042000	1769.760000	0.529266	29.997127
9183.848000	1770.246000	0.529501	30.000257
9186.674000	1770.570000	0.529794	29.989118
9189.570000	1771.420000	0.529977	30.001996
9192.396000	1772.128000	0.529362	29.995038
9195.232000	1772.553000	0.529552	29.997344
9198.088000	1773.099000	0.529753	29.997012
9200.954000	1773.909000	0.529441	29.993823
9203.790000	1774.131000	0.529622	29.993210
9206.686000	1775.022000	0.530021	29.999195
9209.522000	1775.467000	0.529436	29.995146
9212.358000	1775.811000	0.529857	30.002617
9215.194000	1776.742000	0.529899	29.999440
9218.050000	1777.126000	0.530018	29.995455
9220.876000	1777.571000	0.529361	30.004103
9223.752000	1778.280000	0.529991	29.995570
9226.588000	1778.765000	0.529788	29.989611
9229.434000	1779.514000	0.530433	29.996792
9232.280000	1780.242000	0.530581	29.999630
9235.126000	1780.809000	0.529598	29.996859
9237.952000	1781.092000	0.530332	30.007048
9240.748000	1781.942000	0.530237	29.995513
9243.564000	1782.185000	0.529995	30.004650
9246.360000	1782.974000	0.530872	30.003649
9249.206000	1783.500000	0.529758	30.001687
9252.082000	1783.946000	0.529740	29.995311
9254.958000	1785.038000	0.530096	29.993068
9257.765000	1784.917000	0.530092	29.991449
9260.601000	1785.484000	0.529031	29.990466
9263.477000	1786.030000	0.529729	29.998800
9266.333000	1786.839000	0.529785	30.006958
9269.139000	1787.406000	0.529081	30.008060
9271.965000	1787.973000	0.528981	29.983979
9274.841000	1788.559000	0.529748	29.988727
9277.687000	1788.883000	0.529207	29.995138
9280.563000	1789.753000	0.529742	29.995347
9283.409000	1790.542000	0.529325	29.995679
9286.335000	1790.765000	0.529341	29.998177
9289.161000	1791.736000	0.528806	29.990993
9292.007000	1792.121000	0.529608	29.993734
9294.843000	1792.364000	0.529042	29.992040
9297.711000	1793.031000	0.529096	29.993508
9300.647000	1793.720000	0.528850	29.999785
9303.483000	1794.590000	0.529297	29.998481
9306.319000	1794.731000	0.528787	29.997909
9309.155000	1795.116000	0.529221	29.992538
9312.011000	1796.087000	0.528680	30.014131
9314.847000	1796.249000	0.529325	30.006616
9317.684000	1797.058000	0.528999	30.002089
9320.580000	1797.645000	0.529678	29.989784
9323.366000	1798.192000	0.529502	29.986739
9326.192000	1799.042000	0.529597	29.994939
9329.038000	1799.203000	0.529305	29.994552
9331.894000	1799.730000	0.529740	30.001094
9334.690000	1800.681000	0.529729	30.003970
9337.526000	1801.126000	0.529385	30.004142
9340.362000	1801.551000	0.530063	29.992580
9343.198000	1802.380000	0.530111	29.993821
9346.044000	1802.623000	0.528666	29.997912
9348.840000	1803.493000	0.528953	29.989407
9351.686000	1803.817000	0.529746	29.993174
9354.452000	1804.667000	0.529591	30.008421
9357.278000	1804.890000	0.529783	29.993589
9360.164000	1805.294000	0.529438	29.989528
9363.041000	1806.266000	0.530265	30.001279
9365.947000	1806.853000	0.529955	29.995025
9368.773000	1807.460000	0.530427	29.998916
9371.599000	1807.419000	0.530619	30.001931
9374.445000	1808.127000	0.531571	29.996973
9377.331000	1808.714000	0.531750	29.996866
9380.207000	1809.483000	0.531199	29.991542
9383.043000	1810.252000	0.531296	29.994786
9385.919000	1810.637000	0.531352	29.999898
9388.725000	1811.143000	0.531173	29.994798
9391.571000	1812.073000	0.531333	30.014080
9394.417000	1812.336000	0.531881	29.995704
9397.263000	1812.822000	0.530520	30.003287
9400.089000	1813.429000	0.530953	29.996886
9402.965000	1814.239000	0.531923	30.000998
9405.821000	1814.704000	0.532428	30.002696
9408.647000	1814.866000	0.531578	29.994847
9411.573000	1815.898000	0.531933	29.988067
9414.409000	1816.465000	0.533132	29.991540
9417.245000	1816.930000	0.533668	29.994223
9420.101000	1817.132000	0.533624	29.990842
9422.937000	1818.448000	0.533429	29.996411
9425.763000	1818.812000	0.533118	29.999011
9428.649000	1819.298000	0.532790	30.006984
9431.505000	1819.763000	0.532723	30.011025
9434.351000	1820.208000	0.533982	30.000666
9437.157000	1820.755000	0.533242	29.994965
9440.013000	1821.604000	0.532765	30.003299
9442.869000	1822.211000	0.532756	29.996567
9445.695000	1822.920000	0.532226	30.001158
9448.651000	1823.122000	0.532374	29.998519
9451.497000	1823.749000	0.533443	29.996042
9454.343000	1824.316000	0.533050	29.988297
9457.179000	1824.721000	0.532467	29.987613
9460.045000	1825.328000	0.532642	29.987971
9462.841000	1826.077000	0.532507	29.998463
9465.637000	1826.562000	0.532175	29.997648
9468.513000	1827.230000	0.532359	29.999464
9471.359000	1828.060000	0.532616	29.997490
9474.175000	1828.282000	0.532402	29.992283
9477.021000	1828.889000	0.532027	29.989597
9479.897000	1829.476000	0.531991	29.990184
9482.693000	1830.002000	0.531915	29.991190
9485.539000	1830.711000	0.531865	29.993723
9488.375000	1831.338000	0.531189	29.997351
9491.231000	1831.763000	0.530674	29.994903
9494.077000	1832.592000	0.531441	29.998657
9496.893000	1833.098000	0.531407	30.003438
9499.789000	1833.463000	0.531070	29.996469
9502.675000	1833.888000	0.530803	29.998276
9505.541000	1835.102000	0.529414	30.015969
9508.377000	1834.899000	0.530468	29.998951
9511.203000	1835.446000	0.530881	29.992613
9514.069000	1836.073000	0.529944	29.992257
9516.875000	1837.145000	0.529819	29.994604
9519.721000	1837.489000	0.529456	29.987983
9522.517000	1838.198000	0.529262	30.007718
9525.343000	1838.623000	0.528554	29.998745
9528.149000	1839.189000	0.528828	29.996484
9531.005000	1839.614000	0.528568	29.997268
9533.831000	1840.464000	0.529154	30.000306
9536.667000	1840.828000	0.528818	29.991107
9539.513000	1841.233000	0.529596	29.984893
9542.309000	1842.285000	0.530455	29.993119
9545.156000	1842.528000	0.529700	29.996579
9548.062000	1843.075000	0.528975	29.995739
9550.898000	1844.026000	0.528489	29.997042
9553.774000	1844.309000	0.528353	30.008874
9556.620000	1844.592000	0.529053	29.991386
9559.436000	1845.159000	0.529104	29.999104
9562.272000	1845.806000	0.528373	30.001382
9565.228000	1846.555000	0.528865	30.004033
9568.104000	1847.061000	0.528403	29.999850
9570.900000	1847.891000	0.528029	29.988285
9573.796000	1848.457000	0.527296	29.996793
9576.622000	1848.639000	0.528211	29.993755
9579.548000	1849.530000	0.528801	29.989497
9582.384000	1850.218000	0.528605	29.992522
9585.260000	1850.602000	0.528242	30.004408
9588.096000	1851.371000	0.527908	30.002909
9590.942000	1851.857000	0.528505	29.991899
9593.808000	1852.423000	0.527911	29.995937
9596.704000	1852.626000	0.527777	29.994595
9599.580000	1853.557000	0.528449	29.993841
9602.426000	1854.063000	0.528163	30.006067
9605.282000	1854.508000	0.527237	30.004011
9608.068000	1855.418000	0.528088	29.992790
9610.944000	1855.540000	0.527838	29.991281
9613.820000	1856.612000	0.528007	29.988654
9616.626000	1856.693000	0.527526	29.992336
9619.502000	1857.321000	0.527322	29.996792
9622.348000	1857.907000	0.527658	30.003834
9625.204000	1858.373000	0.527725	30.008226
9628.070000	1859.243000	0.527931	30.003507
9630.936000	1859.607000	0.528625	29.995638
9633.692000	1860.032000	0.529297	29.989617
9636.588000	1860.923000	0.529368	30.001003
9639.424000	1861.408000	0.528431	29.993335
9642.310000	1861.833000	0.528754	29.998892
9645.186000	1862.703000	0.528536	29.989437
9648.052000	1863.270000	0.528788	30.000979
9650.918000	1863.958000	0.528682	29.993810
9653.754000	1864.383000	0.528764	29.988023
9656.600000	1864.565000	0.529296	29.992339
9659.436000	1865.577000	0.528046	30.006679
9662.312000	1866.062000	0.528880	29.999493
9665.108000	1866.609000	0.527875	29.996456
9667.954000	1867.337000	0.527801	29.993830
9670.720000	1867.580000	0.528420	29.987946
9673.586000	1868.390000	0.528151	30.004303
9676.482000	1868.997000	0.528436	30.005270
9679.368000	1869.543000	0.528342	30.008210
9682.194000	1870.029000	0.527793	30.003516
9685.040000	1870.555000	0.527102	30.001302
9687.906000	1870.838000	0.528415	29.987783
9690.712000	1872.153000	0.528128	29.987918
9693.548000	1872.133000	0.528706	29.988172
9696.434000	1873.287000	0.527856	29.991471
9699.300000	1873.165000	0.528087	29.991702
9702.126000	1874.116000	0.528966	29.995146
9704.922000	1874.298000	0.528549	29.996313
9707.768000	1875.067000	0.528233	30.005134
9710.594000	1875.674000	0.528058	30.015355
9713.450000	1876.221000	0.528072	29.988228
9716.276000	1876.686000	0.529100	29.987788
9719.092000	1877.253000	0.529131	29.993156
9721.918000	1877.759000	0.527817	30.005930
9724.794000	1878.609000	0.528272	29.989623
9727.650000	1879.195000	0.528214	29.999594
9730.516000	1879.802000	0.527927	29.991937
9733.322000	1880.167000	0.528952	29.990895
9736.208000	1880.875000	0.528129	29.990863
9739.014000	1881.259000	0.528375	29.992262
9741.880000	1881.867000	0.527741	29.997476
9744.746000	1882.453000	0.529166	29.990794
9747.523000	1883.060000	0.528832	29.994022
9750.369000	1883.465000	0.528385	29.991036
9753.225000	1884.133000	0.528154	29.999552
9756.041000	1884.639000	0.528856	30.001246
9758.917000	1885.185000	0.529653	29.997389
9761.723000	1885.732000	0.528421	30.005440
9764.519000	1886.258000	0.528668	29.998171
9767.415000	1887.067000	0.528508	30.006300
9770.241000	1887.877000	0.528811	30.002059
9773.177000	1887.755000	0.529183	29.997793
9776.003000	1888.666000	0.528883	29.992696
9778.849000	1889.293000	0.528927	29.996679
9781.735000	1889.819000	0.528617	29.998259
9784.561000	1890.629000	0.529479	29.993607
9787.457000	1891.195000	0.528910	29.996781
9790.293000	1891.762000	0.528505	29.999716
9793.119000	1891.782000	0.527357	29.997148
9795.925000	1892.531000	0.528671	30.001315
9798.771000	1893.381000	0.528639	30.007904
9801.587000	1893.887000	0.528488	29.996683
9804.403000	1894.190000	0.527949	29.992807
9807.249000	1894.959000	0.528941	29.993479
9810.165000	1895.404000	0.527500	29.998089
9812.971000	1896.072000	0.528743	30.009183
9815.827000	1896.355000	0.528473	30.003412
9818.703000	1896.881000	0.528328	29.992370
9821.529000	1898.035000	0.528654	29.988881
9824.405000	1898.642000	0.528484	30.002969
9827.291000	1899.209000	0.528565	30.000394
9830.137000	1899.553000	0.528439	30.003359
9832.973000	1900.362000	0.528730	30.003815
9835.819000	1900.747000	0.529754	29.986857
9838.655000	1901.435000	0.529127	29.992274
9841.491000	1901.657000	0.528091	29.988840
9844.367000	1902.143000	0.528779	29.991556
9847.213000	1902.750000	0.528620	29.999315
9850.049000	1903.094000	0.528825	29.994912
9852.895000	1904.106000	0.529487	29.989432
9855.741000	1904.551000	0.529334	30.007210
9858.577000	1905.502000	0.528675	30.003820
9861.423000	1905.886000	0.529385	29.992175
9864.249000	1906.453000	0.529314	29.996866
9867.166000	1906.493000	0.529648	29.996164
9869.952000	1907.586000	0.529441	30.004611
9872.758000	1907.768000	0.529661	29.991158
9875.574000	1908.517000	0.529779	29.992457
9878.450000	1909.144000	0.528883	29.996491
9881.256000	1909.792000	0.528386	29.994479
9884.102000	1910.318000	0.528265	30.006049
9886.938000	1910.561000	0.528973	29.996124
9889.774000	1911.512000	0.528383	29.991723
9892.610000	1912.139000	0.528787	30.006429
9895.456000	1912.423000	0.529773	30.002715
9898.332000	1913.333000	0.529956	29.996745
9901.178000	1914.163000	0.529734	29.990074
9904.015000	1914.203000	0.528038	29.998727
9906.861000	1915.073000	0.528649	29.992017
9909.697000	1915.559000	0.528642	29.992434
9912.563000	1916.288000	0.527814	29.992704
9915.489000	1916.652000	0.528070	29.997165
9918.365000	1917.340000	0.529069	29.988999
9921.221000	1917.826000	0.527974	30.000923
9924.097000	1918.210000	0.527844	29.989839
9926.973000	1919.141000	0.527208	29.996217
9929.819000	1919.384000	0.526786	29.993375
9932.695000	1920.031000	0.527129	29.999207
9935.541000	1920.800000	0.527315	29.991095
9938.377000	1921.144000	0.527152	30.004753
9941.283000	1921.508000	0.527057	30.002203
9944.139000	1922.318000	0.526988	30.008234
9946.985000	1922.945000	0.526538	29.989036
9949.811000	1923.734000	0.527238	30.010505
9952.617000	1923.694000	0.526800	29.997286
9955.493000	1924.766000	0.526739	29.985536
9958.360000	1925.373000	0.526062	29.992044
9961.176000	1925.738000	0.526290	29.996721
9964.022000	1926.385000	0.527642	29.990541
9966.868000	1926.952000	0.527624	29.993119
9969.694000	1927.437000	0.526582	29.998309
9972.570000	1928.146000	0.526144	30.006245
9975.416000	1928.652000	0.526829	30.005289
9978.262000	1929.441000	0.526431	29.996338
9981.098000	1929.542000	0.525658	30.001006
9983.934000	1930.412000	0.525522	30.005231
9986.851000	1931.444000	0.525539	30.006156
9989.657000	1931.201000	0.524585	29.996220
9992.513000	1931.991000	0.525167	30.002085
9995.339000	1932.496000	0.525907	29.989724
9998.185000	1933.043000	0.526161	29.989429
10001.051000	1933.711000	0.525239	29.989720
10003.957000	1934.500000	0.525977	29.992598
10006.773000	1934.824000	0.525618	29.993528
10009.659000	1935.451000	0.525751	29.991620
10012.545000	1936.058000	0.526572	29.992862
10015.441000	1936.746000	0.525786	29.998966
10018.297000	1937.130000	0.525381	29.995276
10021.173000	1937.879000	0.524917	30.011582
10023.971000	1938.304000	0.526220	29.986559
10026.798000	1938.931000	0.525503	30.003910
10029.654000	1939.296000	0.525303	30.007669
10032.460000	1940.065000	0.525213	29.988015
10035.286000	1940.753000	0.524680	30.004977
10038.142000	1940.975000	0.526273	29.990732
10040.978000	1941.663000	0.525234	29.995020
10043.814000	1942.129000	0.525858	29.990659
10046.660000	1943.221000	0.525588	30.001231
10049.546000	1943.667000	0.524484	29.993857
10052.382000	1944.213000	0.524964	29.993586
10055.218000	1944.739000	0.524705	30.004063
10058.054000	1945.245000	0.524897	30.001257
10060.920000	1945.771000	0.525497	29.993615
10063.796000	1946.237000	0.525327	29.984938
10066.612000	1946.763000	0.525010	29.991605
10069.438000	1947.673000	0.525377	29.987573
10072.294000	1947.471000	0.525115	29.992025
10075.130000	1948.442000	0.525715	29.993350
10077.936000	1949.373000	0.525825	29.992631
10080.782000	1949.656000	0.524879	30.000500
10083.618000	1950.142000	0.525034	30.000168
10086.474000	1950.810000	0.525686	29.997189
10089.310000	1951.478000	0.525153	30.001623
10092.216000	1951.923000	0.525786	29.993071
10095.052000	1952.166000	0.527218	30.003593
10097.928000	1952.935000	0.525255	29.997188
10100.734000	1953.663000	0.526134	29.995174
10103.580000	1954.472000	0.525027	29.989751
10106.456000	1954.655000	0.524647	29.992110
10109.302000	1955.505000	0.524984	30.002786
10112.138000	1955.889000	0.525572	29.993883
10115.084000	1956.678000	0.524580	30.009044
10117.900000	1957.144000	0.525080	30.008618
10120.786000	1957.629000	0.525174	29.995613
10123.622000	1958.115000	0.525357	29.991618
10126.468000	1958.843000	0.524957	29.989842
10129.334000	1959.349000	0.525015	29.991813
10132.180000	1959.754000	0.524110	29.996569
10135.026000	1960.503000	0.525265	29.997984
10137.842000	1961.130000	0.524787	29.996662
10140.718000	1961.515000	0.524804	30.003925
10143.514000	1961.757000	0.524702	29.989658
10146.350000	1962.526000	0.525984	29.989691
10149.146000	1963.376000	0.525815	30.008319
10151.992000	1963.943000	0.525778	30.005142
10154.868000	1964.611000	0.525570	29.989955
10157.744000	1964.894000	0.524861	29.996471
10160.560000	1965.805000	0.525520	29.997950
10163.436000	1966.027000	0.525188	30.002129
10166.272000	1966.978000	0.524977	30.009342
10169.108000	1967.565000	0.525096	29.997665
10171.914000	1967.808000	0.524946	30.000160
10174.770000	1968.314000	0.524949	29.999287
10177.596000	1968.880000	0.525472	29.994082
10180.442000	1969.892000	0.524668	30.009407
10183.268000	1970.216000	0.524689	30.000265
10186.204000	1971.046000	0.525012	30.004561
10189.070000	1971.551000	0.525922	30.003049
10191.926000	1971.936000	0.525315	29.993566
10194.832000	1972.604000	0.524922	30.007107
10197.678000	1972.948000	0.525483	29.986024
10200.514000	1973.899000	0.525344	29.989125
10203.391000	1974.465000	0.525107	29.989130
10206.267000	1974.789000	0.525295	29.999798
10209.113000	1975.518000	0.524500	30.004234
10211.999000	1975.862000	0.524527	29.996868
10214.815000	1976.529000	0.524531	30.002204
10217.681000	1977.197000	0.525328	29.996677
10220.517000	1977.865000	0.524033	30.003671
10223.393000	1977.946000	0.524163	29.999639
10226.309000	1979.099000	0.524958	29.998618
10229.169000	1979.443000	0.525391	29.998813
10232.035000	1980.152000	0.525632	29.988818
10234.861000	1980.435000	0.525411	30.006756
10237.787000	1981.305000	0.524966	30.006699
10240.613000	1981.588000	0.525649	29.992034
10243.429000	1981.953000	0.524869	30.000038
10246.245000	1982.964000	0.525892	30.010620
10249.101000	1983.248000	0.525722	29.996465
10251.907000	1983.754000	0.525466	30.006326
10254.704000	1984.158000	0.524955	30.002290
10257.550000	1985.231000	0.525837	30.015584
10260.396000	1985.838000	0.525640	29.997231
10263.212000	1986.040000	0.525294	29.994325
10266.098000	1986.809000	0.526281	29.996742
10268.974000	1987.315000	0.526386	29.993679
10271.870000	1987.922000	0.526487	29.990171
10274.696000	1988.529000	0.525828	29.992299
10277.542000	1989.238000	0.525392	29.993112
10280.378000	1989.865000	0.525406	29.997319
10283.224000	1990.148000	0.525159	30.007552
10286.070000	1990.492000	0.525355	29.997937
10288.946000	1991.403000	0.525065	30.007391
10291.792000	1991.990000	0.525941	29.997001
10294.628000	1992.293000	0.525892	29.999352
10297.514000	1993.001000	0.524239	30.012983
10300.350000	1993.507000	0.525930	29.995369
10303.156000	1994.418000	0.524942	30.001936
10305.982000	1994.539000	0.525478	29.997467
10308.828000	1995.146000	0.524796	29.993579
10311.704000	1995.895000	0.524866	30.006020
10314.560000	1996.441000	0.525394	29.991130
10317.346000	1997.069000	0.524811	30.002029
10320.182000	1997.433000	0.524932	29.994394
10323.068000	1998.040000	0.524407	29.993026
10325.924000	1998.789000	0.524488	30.008474
10328.750000	1999.092000	0.523921	30.008544
10331.586000	1999.821000	0.524106	29.995923
10334.492000	2000.711000	0.524533	29.989588
10337.348000	2004.637000	0.534885	30.000235
10340.184000	2009.797000	0.545222	30.002909
10343.030000	2014.593000	0.552369	30.005748
10345.886000	2021.372000	0.557504	30.015506
10348.672000	2027.342000	0.560511	30.031330
10351.518000	2032.481000	0.562449	30.037076
10354.394000	2038.309000	0.563737	30.047566
10357.190000	2044.036000	0.565064	30.041508
10360.036000	2049.560000	0.566455	30.043867
10362.882000	2054.963000	0.566234	30.045138
10365.758000	2060.690000	0.566763	30.038077
10368.614000	2065.830000	0.567702	30.042571
10371.430000	2070.990000	0.569049	30.039672
10374.286000	2076.899000	0.569201	30.038896
10377.152000	2083.233000	0.569115	30.039425
10380.008000	2089.627000	0.566748	30.050773
10382.804000	2094.949000	0.566031	30.026156
10385.631000	2100.595000	0.565116	30.026511
10388.477000	2106.140000	0.563946	30.032945
10391.323000	2111.401000	0.563685	30.028841
10394.159000	2117.310000	0.564595	30.026380
10397.035000	2122.207000	0.564468	30.022402
10399.871000	2128.055000	0.564909	30.021749
10402.727000	2133.154000	0.566332	30.013331
10405.553000	2138.132000	0.566463	30.018087
10408.379000	2144.102000	0.567342	30.026703
10411.246000	2151.286000	0.566296	30.019128
10414.072000	2158.226000	0.562201	30.027342
10416.918000	2163.650000	0.558041	30.016407
10419.754000	2169.275000	0.555446	30.020425
10422.590000	2175.184000	0.555270	30.007031
10425.456000	2180.749000	0.555283	30.004209
10428.282000	2186.354000	0.554640	30.001333
10431.118000	2191.919000	0.553606	29.998523
10433.924000	2197.646000	0.553231	30.006973
10436.730000	2203.089000	0.551992	30.005007
10439.636000	2209.099000	0.551121	30.001508
10442.522000	2214.522000	0.550680	29.997226
10445.358000	2219.561000	0.550403	30.001888
10448.194000	2225.045000	0.550918	29.998526
10451.040000	2230.752000	0.550684	29.993539
10453.846000	2237.692000	0.549749	29.995311
10456.762000	2243.844000	0.547736	30.001701
10459.598000	2249.085000	0.545524	29.995910
10462.444000	2254.448000	0.545348	30.004966
10465.280000	2260.073000	0.545485	29.990812
10468.126000	2266.144000	0.543442	29.999054
10471.002000	2271.850000	0.543402	29.992037
10473.848000	2277.253000	0.542587	30.004744
10476.694000	2282.960000	0.542151	30.007096
10479.620000	2289.031000	0.542097	29.991400
10482.448000	2294.353000	0.541572	29.996033
10485.354000	2299.067000	0.541687	29.988088
10488.200000	2304.936000	0.543833	29.985438
10491.036000	2311.209000	0.542518	29.999359
10493.992000	2318.190000	0.541299	29.997731
10496.828000	2323.877000	0.541184	29.993810
10499.704000	2329.158000	0.541456	29.989078
10502.520000	2334.946000	0.540773	29.992282
10505.356000	2340.187000	0.540520	29.995107
10508.202000	2346.197000	0.541108	29.988464
10511.078000	2352.227000	0.540692	29.988929
10513.954000	2357.792000	0.539990	29.990752
10516.820000	2363.397000	0.539021	29.996901
10519.676000	2369.265000	0.538213	30.004822
10522.522000	2374.810000	0.538969	29.994106
10525.308000	2379.525000	0.539014	29.990744
10528.144000	2385.049000	0.539569	29.993848
10531.000000	2391.039000	0.539022	30.002203
10533.786000	2397.251000	0.538257	29.993607
10536.592000	2403.261000	0.537963	29.987571
10539.418000	2409.110000	0.536852	29.994409
10542.244000	2414.877000	0.535391	29.991562
10545.090000	2420.401000	0.534498	29.988808
10547.926000	2425.723000	0.534528	29.988695
10550.772000	2431.126000	0.534543	29.991995
10553.688000	2437.602000	0.534702	29.991507
10556.604000	2442.802000	0.534218	29.996268
10559.460000	2448.306000	0.534437	30.005392
10562.326000	2454.316000	0.534020	29.989353
10565.202000	2460.428000	0.533797	30.005311
10568.028000	2465.304000	0.533316	30.001687
10570.904000	2470.869000	0.533598	29.983512
10573.730000	2477.082000	0.533913	29.986139
10576.606000	2483.051000	0.532836	29.982086
10579.462000	2489.425000	0.531790	29.988333
10582.298000	2495.112000	0.530719	29.987075
10585.164000	2500.838000	0.530449	29.989688
10587.970000	2505.756000	0.530176	29.985901
10590.856000	2511.482000	0.529481	29.991989
10593.702000	2517.290000	0.529328	29.991188
10596.558000	2522.997000	0.529246	29.992731
10599.454000	2528.946000	0.529721	29.995714
10602.300000	2534.915000	0.528775	29.998968
10605.226000	2540.521000	0.528771	29.998808
10608.052000	2545.903000	0.527430	29.991331
10610.858000	2551.671000	0.527356	29.991775
10613.694000	2556.912000	0.527701	29.991082
10616.540000	2562.315000	0.528094	29.991046
10619.406000	2568.891000	0.526972	29.993443
10622.214000	2574.922000	0.527626	29.987485
10625.050000	2580.972000	0.526757	29.998502
10627.896000	2586.496000	0.525809	29.992349
10630.732000	2592.952000	0.525024	29.983902
10633.568000	2598.456000	0.524740	29.980512
10636.434000	2604.162000	0.524486	29.987564
10639.280000	2609.869000	0.523691	29.986077
10642.056000	2616.041000	0.522662	29.987993
10644.892000	2621.261000	0.522048	29.986706
10647.748000	2627.150000	0.521670	29.991041
10650.584000	2632.715000	0.521075	29.993457
10653.440000	2638.138000	0.521076	29.994625
10656.297000	2644.047000	0.520477	29.998986
10659.143000	2649.288000	0.520523	29.986263
10662.009000	2654.226000	0.521793	29.976085
10664.815000	2659.507000	0.523037	29.981929
10667.761000	2664.687000	0.524450	29.990958
10670.617000	2670.657000	0.525703	29.989709
10673.433000	2676.869000	0.526023	29.984840
10676.299000	2682.900000	0.525060	29.994915
10679.145000	2688.363000	0.524075	29.995425
10681.981000	2693.523000	0.523090	29.990858
10684.817000	2699.716000	0.522840	29.991743
10687.653000	2704.977000	0.523182	29.989610
10690.469000	2711.007000	0.523336	29.998037
10693.355000	2715.742000	0.524450	30.005336
10696.181000	2721.853000	0.524185	30.007398
10699.057000	2727.823000	0.522821	30.008208
10701.903000	2733.469000	0.523206	30.006388
10704.749000	2738.508000	0.522812	30.003432
10707.585000	2743.749000	0.523490	29.992143
10710.421000	2749.556000	0.525131	29.997435
10713.267000	2755.364000	0.524956	30.007440
10716.103000	2762.042000	0.524604	29.995628
10719.019000	2768.335000	0.522840	29.993991
10721.895000	2773.940000	0.521490	29.994798
10724.711000	2780.052000	0.520241	29.998022
10727.547000	2785.535000	0.519458	29.996176
10730.433000	2790.655000	0.518539	29.999235
10733.309000	2796.058000	0.519179	30.009047
10736.135000	2802.190000	0.518792	29.994248
10738.961000	2807.734000	0.519080	30.006345
10741.777000	2813.481000	0.518981	30.002451
10744.643000	2819.228000	0.519074	29.987908
10747.469000	2824.105000	0.518531	29.988841
10750.305000	2829.447000	0.518940	29.986829
10753.171000	2835.437000	0.519460	29.992269
10756.027000	2841.326000	0.519662	30.000897
10758.903000	2846.992000	0.519207	29.996094
10761.759000	2853.528000	0.518233	29.997246
10764.585000	2859.295000	0.517148	30.014822
10767.431000	2865.264000	0.516318	29.992925
10770.268000	2870.849000	0.516269	29.999187
10773.114000	2876.091000	0.516538	29.996030
10776.020000	2881.979000	0.517416	29.990996
10778.876000	2887.686000	0.515060	29.989812
10781.732000	2893.129000	0.514971	29.985982
10784.578000	2898.573000	0.515166	29.995279
10787.384000	2904.279000	0.514956	29.988702
10790.230000	2909.722000	0.515022	29.994713
10793.136000	2914.741000	0.515554	29.995160
10795.992000	2920.083000	0.516829	29.999934
10798.828000	2926.700000	0.516368	30.002680
10801.744000	2933.257000	0.515400	30.005959
10804.590000	2939.226000	0.514351	30.002140
10807.436000	2944.912000	0.513614	29.994150
10810.272000	2950.376000	0.512823	29.994767
10813.108000	2956.042000	0.513231	29.994678
10815.964000	2962.113000	0.513060	29.993438
10818.750000	2967.496000	0.512414	29.991567
10821.626000	2973.202000	0.512365	29.986246
10824.472000	2978.747000	0.512216	29.989442
10827.318000	2984.655000	0.512914	29.988696
10830.154000	2989.795000	0.512148	29.994347
10832.990000	2994.895000	0.513187	29.988856
10835.826000	3000.095000	0.513755	29.996055
10838.682000	3005.923000	0.513758	30.015532
10841.508000	3012.055000	0.514386	29.996828
10844.394000	3018.996000	0.513232	30.007788
10847.270000	3024.722000	0.511827	29.996320
10850.156000	3030.732000	0.511502	29.992042
10852.962000	3036.156000	0.511098	29.987561
10855.848000	3042.267000	0.510211	29.997454
10858.684000	3047.488000	0.510132	29.993690
10861.510000	3052.911000	0.510512	29.990358
10864.366000	3059.204000	0.510239	29.988750
10867.232000	3065.133000	0.509681	29.981606
10870.078000	3070.597000	0.509409	29.988856
10872.964000	3076.303000	0.509153	29.983577
10875.840000	3081.524000	0.509552	29.989230
10878.716000	3086.016000	0.509329	29.994738
10881.602000	3091.925000	0.510930	30.001313
10884.478000	3098.138000	0.511109	30.006534
10887.314000	3104.694000	0.511418	30.007927
10890.160000	3111.149000	0.509228	30.014385
10892.996000	3116.532000	0.508382	29.999938
10895.812000	3121.975000	0.508824	29.986665
10898.648000	3127.803000	0.508136	29.989424
10901.455000	3132.417000	0.508073	29.984234
10904.301000	3138.306000	0.509225	29.990325
10907.087000	3143.688000	0.507830	29.993144
10909.963000	3149.759000	0.509534	29.992780
10912.799000	3155.547000	0.507865	30.002396
10915.605000	3160.929000	0.508637	30.001375
10918.481000	3166.676000	0.508296	29.999834
10921.307000	3171.513000	0.508774	29.994223
10924.145000	3177.401000	0.509202	29.994554
10927.001000	3183.249000	0.509805	29.993657
10929.837000	3190.453000	0.509176	29.994945
10932.713000	3196.484000	0.507529	29.995126
10935.569000	3201.785000	0.506014	29.999657
10938.435000	3207.209000	0.505006	29.992998
10941.351000	3213.380000	0.505850	29.993758
10944.167000	3218.966000	0.505075	29.993577
10947.034000	3224.510000	0.505331	29.987193
10949.870000	3230.378000	0.504273	29.982066
10952.756000	3235.417000	0.504837	29.980768
10955.562000	3241.286000	0.505462	29.988347
10958.408000	3246.709000	0.505525	29.992068
10961.244000	3252.172000	0.504723	30.000832
10964.060000	3257.434000	0.505492	30.001081
10966.916000	3262.108000	0.506413	29.997849
10969.752000	3268.928000	0.507433	29.989807
10972.558000	3275.646000	0.506801	29.994472
10975.424000	3281.636000	0.504773	29.999263
10978.300000	3287.302000	0.503830	29.985564
10981.076000	3293.049000	0.503363	29.995566
10983.902000	3298.492000	0.502258	29.989472
10986.728000	3304.037000	0.501636	30.002884
10989.564000	3309.561000	0.501571	29.998405
10992.450000	3315.268000	0.502908	29.981757
10995.326000	3321.379000	0.502598	29.990629
10998.162000	3327.105000	0.501927	29.999743
11001.008000	3332.670000	0.501610	29.994641
11003.904000	3337.830000	0.501778	29.986159
11006.731000	3342.970000	0.502395	29.988893
11009.567000	3348.576000	0.503107	29.998357
11012.413000	3354.039000	0.503321	29.994069
11015.249000	3359.928000	0.503435	29.998322
11018.075000	3366.525000	0.502850	30.011623
11020.991000	3372.757000	0.500825	30.004163
11023.857000	3378.484000	0.501005	29.986799
11026.683000	3384.616000	0.499499	29.992447
11029.529000	3390.342000	0.499471	29.991733
11032.335000	3395.563000	0.498521	29.986317
11035.161000	3401.148000	0.498586	29.987465
11038.037000	3406.875000	0.498852	29.991299
11040.923000	3412.662000	0.499336	29.983955
11043.749000	3417.822000	0.500259	29.983940
11046.525000	3423.529000	0.500641	29.983720
11049.361000	3429.154000	0.499857	29.990228
11052.247000	3434.274000	0.499475	29.997304
11055.163000	3439.232000	0.500077	29.999797
11058.020000	3444.250000	0.502262	29.994490
11060.886000	3450.483000	0.502751	30.014434
11063.712000	3457.302000	0.503081	30.011369
11066.528000	3463.758000	0.501897	30.006408
11069.374000	3469.262000	0.500142	30.010369
11072.210000	3475.555000	0.498390	29.993478
11075.046000	3480.796000	0.497093	29.990613
11077.882000	3486.725000	0.497162	29.998739
11080.738000	3491.966000	0.496647	29.996473
11083.604000	3497.531000	0.497477	29.999139
11086.450000	3503.177000	0.497404	29.994386
11089.366000	3508.560000	0.497522	29.991794
11092.252000	3514.226000	0.498132	29.985604
11095.088000	3519.669000	0.498362	29.985060
11097.974000	3524.789000	0.499448	29.995304
11100.820000	3530.050000	0.500101	29.997228
11103.646000	3535.858000	0.500308	29.998258
11106.482000	3542.414000	0.499666	30.003638
11109.338000	3549.051000	0.498589	30.006168
11112.214000	3555.163000	0.496823	30.006608
11115.050000	3560.485000	0.496570	30.005440
11117.886000	3566.394000	0.495719	29.993182
11120.742000	3571.837000	0.495193	29.995428
11123.608000	3577.462000	0.495522	30.010121
11126.502000	3583.108000	0.495970	29.991432
11129.348000	3589.139000	0.495380	29.984845
11132.144000	3594.359000	0.494859	29.986776
11134.990000	3600.086000	0.495125	29.990614
11137.826000	3605.489000	0.495013	29.986713
11140.672000	3610.872000	0.495472	29.994479
11143.498000	3615.890000	0.495770	29.989264
11146.314000	3620.888000	0.496991	29.988792
11149.110000	3627.081000	0.497878	30.005283
11151.986000	3634.365000	0.497519	30.003500
11154.862000	3640.112000	0.494299	30.001607
11157.708000	3645.880000	0.493935	30.011634
11160.584000	3652.072000	0.492837	29.993345
11163.440000	3656.989000	0.493524	29.991562
11166.316000	3662.918000	0.494282	29.998491
11169.162000	3668.483000	0.493814	29.998810
11171.988000	3673.967000	0.493720	30.000083
11174.824000	3679.653000	0.494053	29.990770
11177.680000	3685.360000	0.493678	29.998249
11180.516000	3691.349000	0.493586	30.005495
11183.402000	3696.975000	0.493477	29.993822
11186.188000	3701.811000	0.492647	29.996061
11188.994000	3707.073000	0.494969	29.994437
11191.870000	3713.022000	0.494927	29.994595
11194.716000	3719.679000	0.494370	30.003716
11197.632000	3725.811000	0.494116	29.997801
11200.478000	3731.720000	0.493027	29.993048
11203.324000	3737.305000	0.491418	30.003143
11206.180000	3742.849000	0.492035	29.989792
11209.037000	3748.637000	0.491239	30.001659
11211.902000	3754.101000	0.491331	29.990936
11214.718000	3760.131000	0.491066	29.988225
11217.564000	3765.574000	0.490588	29.986957
11220.440000	3771.584000	0.490626	29.990259
11223.276000	3776.502000	0.490459	29.986504
11226.113000	3782.795000	0.490545	29.984264
11228.999000	3788.279000	0.490233	29.991149
11231.836000	3793.398000	0.489783	30.001898
11234.722000	3798.741000	0.492315	29.984344
11237.608000	3804.386000	0.491435	29.998337
11240.474000	3810.720000	0.492186	29.997215
11243.330000	3817.398000	0.491230	30.012211
11246.196000	3822.659000	0.490314	30.003057
11249.032000	3828.487000	0.489053	30.005248
11251.848000	3833.850000	0.489532	29.994354
11254.674000	3839.313000	0.489538	29.991252
11257.520000	3845.303000	0.489624	29.995777
11260.356000	3850.888000	0.490034	29.989595
11263.282000	3856.595000	0.489147	29.990433
11266.088000	3862.099000	0.489099	29.996617
11268.964000	3867.846000	0.487914	29.991613
11271.800000	3873.633000	0.488678	29.992196
11274.656000	3878.712000	0.489836	29.986799
11277.482000	3883.670000	0.490407	29.994396
11280.288000	3888.709000	0.491131	29.993697
11283.124000	3895.063000	0.493005	30.003096
11285.970000	3901.801000	0.491474	30.001889
11288.866000	3907.832000	0.490539	29.995277
11291.772000	3913.680000	0.487842	30.007255
11294.618000	3919.649000	0.487155	30.003599
11297.484000	3925.255000	0.487959	30.007248
11300.330000	3930.759000	0.487596	30.013972
11303.166000	3936.081000	0.487612	29.995707
11306.012000	3942.313000	0.487862	30.009960
11308.858000	3947.818000	0.487079	29.994029
11311.701000	3953.180000	0.487313	30.000934
11314.537000	3957.956000	0.487822	30.000696
11317.383000	3963.885000	0.489081	29.994079
11320.180000	3968.883000	0.488466	29.994656
11323.036000	3975.156000	0.489641	29.998837
11325.862000	3981.025000	0.489588	29.998885
11328.668000	3987.439000	0.489338	29.995767
11331.010000	3992.478000	0.489103	29.991793