File: velstep4_BRAVA_expb819_basalt.txt
Time(s)	Displ(microns)	Friction	Normal_stress(MPa)
11607.700000	8503.602000	0.607016	19.969273
11608.300000	8505.370000	0.607193	19.968445
11608.900000	8507.172000	0.606874	19.969819
11609.500000	8508.948000	0.607688	19.969408
11610.100000	8510.793000	0.606509	19.968440
11610.700000	8512.579000	0.607056	19.969039
11611.300000	8514.410000	0.606094	19.969406
11611.900000	8516.157000	0.608589	19.969600
11612.500000	8518.021000	0.607443	19.969005
11613.100000	8519.826000	0.608056	19.969092
11613.700000	8521.554000	0.606657	19.969122
11614.300000	8523.382000	0.606842	19.969075
11614.900000	8525.295000	0.606888	19.968860
11615.500000	8526.941000	0.606239	19.968760
11616.100000	8528.705000	0.607849	19.968499
11616.700000	8530.610000	0.606769	19.968725
11617.300000	8532.375000	0.607302	19.969116
11617.900000	8534.178000	0.607361	19.968767
11618.500000	8535.982000	0.607447	19.968763
11619.100000	8537.779000	0.606735	19.969190
11619.700000	8539.606000	0.606337	19.968968
11620.300000	8541.356000	0.607450	19.969444
11620.900000	8543.153000	0.606182	19.969628
11621.500000	8545.043000	0.608522	19.968938
11622.100000	8546.830000	0.607987	19.969058
11622.700000	8548.581000	0.607469	19.968836
11623.300000	8550.389000	0.608371	19.969026
11623.900000	8552.187000	0.607785	19.969057
11624.500000	8554.022000	0.607167	19.969096
11625.100000	8555.780000	0.606964	19.968935
11625.700000	8557.618000	0.607293	19.968664
11626.300000	8559.359000	0.606772	19.969101
11626.900000	8561.139000	0.607601	19.969218
11627.500000	8562.939000	0.605805	19.968025
11628.100000	8564.825000	0.607273	19.968964
11628.700000	8566.555000	0.606031	19.968292
11629.300000	8568.396000	0.607191	19.968370
11629.900000	8570.201000	0.608988	19.968787
11630.500000	8571.990000	0.608635	19.968899
11631.100000	8573.747000	0.607519	19.968816
11631.700000	8575.542000	0.607723	19.969368
11632.300000	8577.359000	0.607137	19.968482
11632.900000	8579.139000	0.607076	19.968573
11633.500000	8580.988000	0.607843	19.968522
11634.100000	8582.822000	0.608416	19.968463
11634.700000	8584.505000	0.607047	19.968198
11635.300000	8586.400000	0.607772	19.968360
11635.900000	8588.181000	0.607168	19.967997
11636.500000	8590.020000	0.606898	19.968424
11637.100000	8591.870000	0.607268	19.968335
11637.700000	8593.601000	0.607459	19.968307
11638.300000	8596.287000	0.607970	19.969126
11638.900000	8598.112000	0.607626	19.968899
11639.500000	8599.891000	0.607607	19.968688
11640.100000	8601.671000	0.607342	19.968493
11640.700000	8603.506000	0.607659	19.968152
11641.300000	8605.252000	0.607802	19.969070
11641.900000	8607.054000	0.607638	19.968859
11642.500000	8608.904000	0.608405	19.968725
11643.100000	8610.673000	0.607274	19.968481
11643.700000	8612.483000	0.607123	19.968081
11644.300000	8614.290000	0.606580	19.968180
11644.900000	8616.070000	0.607849	19.968160
11645.500000	8617.887000	0.607042	19.968183
11646.100000	8619.684000	0.605993	19.968014
11646.700000	8621.483000	0.608719	19.968630
11647.300000	8623.304000	0.606053	19.968508
11647.900000	8625.112000	0.607607	19.967777
11648.500000	8626.906000	0.609218	19.968481
11649.100000	8628.668000	0.607850	19.968225
11649.700000	8630.488000	0.607716	19.967740
11650.300000	8632.310000	0.608548	19.968050
11650.900000	8634.059000	0.607181	19.968122
11651.500000	8635.870000	0.607652	19.968620
11652.100000	8637.647000	0.607541	19.968225
11652.700000	8639.523000	0.607366	19.968360
11653.300000	8641.264000	0.607467	19.967796
11653.900000	8643.100000	0.607517	19.967639
11654.500000	8644.937000	0.607444	19.969219
11655.100000	8646.659000	0.607367	19.968082
11655.700000	8648.486000	0.608199	19.968218
11656.300000	8650.300000	0.607652	19.968208
11656.900000	8652.106000	0.607991	19.967749
11657.500000	8653.882000	0.607370	19.968402
11658.100000	8655.700000	0.608475	19.967703
11658.700000	8657.534000	0.607408	19.967208
11659.300000	8659.337000	0.606617	19.967300
11659.900000	8661.067000	0.607331	19.967817
11660.500000	8662.858000	0.608140	19.968151
11661.100000	8664.737000	0.608359	19.967410
11661.700000	8666.478000	0.607767	19.967070
11662.300000	8668.338000	0.607750	19.967464
11662.900000	8670.074000	0.607386	19.967207
11663.500000	8671.902000	0.608126	19.967270
11664.100000	8673.676000	0.607264	19.968157
11664.700000	8675.530000	0.608482	19.967563
11665.300000	8677.302000	0.607847	19.968109
11665.900000	8679.123000	0.608260	19.968225
11666.500000	8680.896000	0.607842	19.967886
11667.100000	8682.751000	0.608190	19.967668
11667.700000	8684.506000	0.607625	19.967660
11668.300000	8686.316000	0.608296	19.968014
11668.900000	8688.141000	0.607868	19.967975
11669.500000	8689.896000	0.607850	19.967832
11670.100000	8691.709000	0.607772	19.967460
11670.700000	8693.477000	0.608144	19.967268
11671.300000	8695.292000	0.608350	19.967981
11671.900000	8697.050000	0.607095	19.967615
11672.500000	8698.931000	0.608230	19.967765
11673.100000	8700.701000	0.607231	19.967825
11673.700000	8702.491000	0.608177	19.967132
11674.210000	8703.896000	0.607034	19.967635
11674.270000	8703.720000	0.607143	19.970458
11674.330000	8704.237000	0.607629	19.972530
11674.390000	8704.483000	0.607749	19.969586
11674.450000	8704.575000	0.607863	19.966436
11674.510000	8704.848000	0.607940	19.972525
11674.570000	8705.092000	0.607917	19.967000
11674.630000	8705.212000	0.606796	19.969130
11674.690000	8705.366000	0.608008	19.969816
11674.750000	8705.796000	0.609157	19.965012
11674.810000	8705.911000	0.609229	19.969951
11674.870000	8705.935000	0.608189	19.968753
11674.930000	8705.917000	0.607527	19.964052
11674.990000	8706.159000	0.606572	19.971017
11675.050000	8706.234000	0.605794	19.968825
11675.110000	8706.429000	0.606826	19.970983
11675.170000	8706.605000	0.607316	19.968303
11675.230000	8707.099000	0.608281	19.965587
11675.290000	8706.972000	0.607956	19.961841
11675.350000	8707.098000	0.607487	19.964756
11675.410000	8707.151000	0.607327	19.968297
11675.470000	8707.544000	0.606780	19.961418
11675.530000	8708.030000	0.607093	19.970578
11675.590000	8708.043000	0.609895	19.968345
11675.650000	8708.283000	0.608667	19.965252
11675.710000	8708.535000	0.608229	19.968963
11675.770000	8708.360000	0.607101	19.966550
11675.830000	8708.715000	0.607934	19.964887
11675.890000	8709.050000	0.608117	19.967135
11675.950000	8709.368000	0.608146	19.964521
11676.010000	8709.359000	0.608275	19.963611
11676.070000	8709.774000	0.609524	19.968977
11676.130000	8709.635000	0.607796	19.969328
11676.190000	8709.746000	0.609027	19.966541
11676.250000	8710.080000	0.608826	19.965977
11676.310000	8709.919000	0.607517	19.971556
11676.370000	8710.192000	0.608422	19.968732
11676.430000	8710.932000	0.610800	19.970988
11676.490000	8711.442000	0.612117	19.970695
11676.550000	8712.186000	0.613162	19.971895
11676.610000	8712.741000	0.615045	19.967595
11676.670000	8713.028000	0.616482	19.964327
11676.730000	8714.123000	0.618133	19.967174
11676.790000	8714.744000	0.618473	19.968088
11676.850000	8715.110000	0.617092	19.962406
11676.910000	8715.993000	0.618082	19.970603
11676.970000	8716.018000	0.614394	19.967394
11677.030000	8716.920000	0.613675	19.970791
11677.090000	8717.403000	0.614671	19.962401
11677.150000	8718.322000	0.614583	19.965487
11677.210000	8718.961000	0.614111	19.968271
11677.270000	8719.401000	0.612803	19.968483
11677.330000	8719.723000	0.612917	19.964655
11677.390000	8720.583000	0.611829	19.972850
11677.450000	8721.132000	0.611438	19.967541
11677.510000	8721.807000	0.610754	19.973440
11677.570000	8722.348000	0.610324	19.972483
11677.630000	8722.877000	0.610888	19.964794
11677.690000	8723.465000	0.610460	19.969366
11677.750000	8724.105000	0.609521	19.963997
11677.810000	8724.894000	0.609193	19.972649
11677.870000	8725.404000	0.610005	19.964140
11677.930000	8725.922000	0.610192	19.969620
11677.990000	8726.512000	0.609696	19.973778
11678.050000	8727.297000	0.610151	19.973728
11678.110000	8727.706000	0.608090	19.974379
11678.170000	8728.222000	0.607914	19.961200
11678.230000	8728.600000	0.608659	19.969819
11678.290000	8729.448000	0.608689	19.974048
11678.350000	8729.857000	0.607890	19.966294
11678.410000	8730.765000	0.608867	19.969762
11678.470000	8731.016000	0.608887	19.959497
11678.530000	8731.605000	0.607971	19.966632
11678.590000	8732.223000	0.606245	19.964367
11678.650000	8733.219000	0.608437	19.969250
11678.710000	8733.784000	0.608041	19.966320
11678.770000	8734.585000	0.608103	19.969335
11678.830000	8734.858000	0.607494	19.963584
11678.890000	8735.291000	0.608619	19.969946
11678.950000	8736.218000	0.608188	19.962163
11679.010000	8736.679000	0.607842	19.970016
11679.070000	8737.422000	0.606989	19.968077
11679.130000	8737.999000	0.607391	19.966399
11679.190000	8738.711000	0.608763	19.969938
11679.250000	8738.988000	0.608592	19.969371
11679.310000	8739.961000	0.608763	19.966900
11679.370000	8740.430000	0.608455	19.966846
11679.430000	8740.931000	0.607196	19.966118
11679.490000	8741.559000	0.607404	19.964194
11679.550000	8742.096000	0.608383	19.963173
11679.610000	8743.195000	0.608269	19.974498
11679.670000	8743.461000	0.608535	19.966058
11679.730000	8743.959000	0.608361	19.972511
11679.790000	8744.462000	0.606453	19.969467
11679.850000	8745.149000	0.607380	19.972306
11679.910000	8746.070000	0.608216	19.967267
11679.970000	8746.323000	0.606909	19.963969
11680.030000	8746.762000	0.607061	19.965247
11680.090000	8747.404000	0.607713	19.965434
11680.150000	8748.430000	0.608914	19.967727
11680.210000	8748.390000	0.607078	19.966010
11680.270000	8749.027000	0.607132	19.967257
11680.330000	8749.895000	0.607324	19.974161
11680.390000	8750.468000	0.607527	19.964952
11680.450000	8751.002000	0.606820	19.964998
11680.510000	8752.741000	0.607990	19.966927
11680.570000	8753.348000	0.608199	19.965189
11680.630000	8753.956000	0.608712	19.972299
11680.690000	8754.758000	0.608349	19.964324
11680.750000	8755.309000	0.608933	19.968953
11680.810000	8755.756000	0.608027	19.962325
11680.870000	8756.523000	0.608603	19.967319
11680.930000	8756.893000	0.608376	19.962819
11680.990000	8757.561000	0.609478	19.971265
11681.050000	8758.131000	0.607086	19.963777
11681.110000	8758.539000	0.606968	19.965757
11681.170000	8759.119000	0.609022	19.968103
11681.230000	8759.834000	0.607183	19.964662
11681.290000	8760.731000	0.609795	19.965675
11681.350000	8761.160000	0.607978	19.968043
11681.410000	8761.461000	0.606423	19.965369
11681.470000	8762.698000	0.608864	19.965425
11681.530000	8763.074000	0.606242	19.968917
11681.590000	8763.447000	0.607308	19.968523
11681.650000	8765.191000	0.608418	19.965350
11681.710000	8765.563000	0.607286	19.966867
11681.770000	8766.309000	0.606996	19.970729
11681.830000	8766.928000	0.607511	19.968293
11681.890000	8767.475000	0.608489	19.964885
11681.950000	8769.161000	0.608214	19.970936
11682.010000	8769.448000	0.607275	19.966771
11682.070000	8770.175000	0.607228	19.964965
11682.130000	8770.767000	0.609343	19.969458
11682.190000	8771.560000	0.607650	19.972486
11682.250000	8772.045000	0.608020	19.967505
11682.310000	8772.652000	0.607452	19.966175
11682.370000	8773.089000	0.606178	19.964203
11682.430000	8773.888000	0.608792	19.965788
11682.490000	8774.586000	0.607960	19.969664
11682.550000	8775.127000	0.608335	19.969763
11682.610000	8775.860000	0.608341	19.961048
11682.670000	8776.207000	0.606669	19.967219
11682.730000	8776.850000	0.607436	19.963664
11682.790000	8777.472000	0.607655	19.962885
11682.850000	8777.898000	0.609256	19.968855
11682.910000	8778.979000	0.609183	19.972628
11682.970000	8779.495000	0.607413	19.968222
11683.030000	8780.033000	0.606584	19.963310
11683.090000	8780.624000	0.606545	19.960622
11683.150000	8781.214000	0.607553	19.959958
11683.210000	8781.972000	0.607425	19.966666
11683.270000	8782.423000	0.606245	19.975371
11683.330000	8782.852000	0.606938	19.969048
11683.390000	8783.436000	0.607767	19.967184
11683.450000	8784.016000	0.607022	19.971373
11683.510000	8784.762000	0.608491	19.967938
11683.570000	8785.294000	0.606808	19.964989
11683.630000	8785.724000	0.607792	19.964030
11683.690000	8786.383000	0.608176	19.969916
11683.750000	8786.908000	0.607937	19.967369
11683.810000	8787.664000	0.608437	19.972900
11683.870000	8788.205000	0.606568	19.970318
11683.930000	8788.925000	0.608080	19.974443
11683.990000	8789.611000	0.608047	19.969590
11684.050000	8790.201000	0.607283	19.971652
11684.110000	8790.779000	0.607393	19.966470
11684.170000	8791.220000	0.607511	19.960650
11684.230000	8792.040000	0.608147	19.975276
11684.290000	8792.423000	0.606422	19.968782
11684.350000	8793.526000	0.609328	19.973975
11684.410000	8793.463000	0.607601	19.966215
11684.470000	8794.239000	0.607702	19.966660
11684.530000	8794.744000	0.607021	19.971735
11684.590000	8795.699000	0.608937	19.965669
11684.650000	8796.130000	0.606864	19.965133
11684.710000	8796.590000	0.607743	19.970632
11684.770000	8797.700000	0.608884	19.967181
11684.830000	8797.782000	0.607272	19.968746
11684.890000	8798.528000	0.607708	19.963606
11684.950000	8799.235000	0.607890	19.968234
11685.010000	8799.761000	0.606737	19.968686
11685.070000	8800.421000	0.606995	19.966408
11685.130000	8801.099000	0.607928	19.965704
11685.190000	8801.513000	0.606676	19.970655
11685.250000	8802.060000	0.607380	19.966549
11685.310000	8802.761000	0.608013	19.968315
11685.370000	8803.089000	0.607394	19.960805
11685.430000	8803.689000	0.606424	19.961216
11685.490000	8804.735000	0.607772	19.969891
11685.550000	8804.854000	0.607299	19.969583
11685.610000	8805.727000	0.605768	19.966314
11685.670000	8806.226000	0.607629	19.968057
11685.730000	8807.129000	0.605898	19.964515
11685.790000	8807.354000	0.606957	19.961450
11685.850000	8807.890000	0.607147	19.962905
11685.910000	8808.820000	0.607610	19.967282
11685.970000	8809.059000	0.607706	19.964410
11686.030000	8810.241000	0.607578	19.968428
11686.090000	8810.386000	0.607873	19.965352
11686.150000	8811.019000	0.606664	19.962619
11686.210000	8811.442000	0.606476	19.962948
11686.270000	8812.461000	0.607534	19.968411
11686.330000	8813.019000	0.608177	19.967967
11686.390000	8813.413000	0.608261	19.964214
11686.450000	8813.951000	0.607309	19.964972
11686.510000	8814.619000	0.606364	19.967559
11686.570000	8815.546000	0.608766	19.968306
11686.630000	8815.885000	0.607682	19.967651
11686.690000	8816.414000	0.606416	19.961985
11686.750000	8817.055000	0.606359	19.969280
11686.810000	8817.745000	0.607400	19.966397
11686.870000	8818.329000	0.606878	19.961870
11686.930000	8818.753000	0.607020	19.967129
11686.990000	8819.641000	0.606956	19.969611
11687.050000	8820.016000	0.606776	19.969270
11687.110000	8820.508000	0.607857	19.965138
11687.170000	8821.045000	0.607464	19.962479
11687.230000	8822.193000	0.607729	19.967672
11687.290000	8822.424000	0.606404	19.965404
11687.350000	8822.970000	0.605779	19.966464
11687.410000	8823.627000	0.608026	19.968233
11687.470000	8823.876000	0.607221	19.963013
11687.530000	8824.768000	0.606792	19.970239
11687.590000	8825.639000	0.607600	19.972858
11687.650000	8826.178000	0.606986	19.971597
11687.710000	8826.895000	0.606603	19.964604
11687.770000	8827.201000	0.607017	19.967995
11687.830000	8827.999000	0.606964	19.966186
11687.890000	8828.360000	0.607620	19.972245
11687.950000	8829.058000	0.608166	19.967126
11688.010000	8829.529000	0.607395	19.966878
11688.070000	8830.215000	0.607778	19.966905
11688.130000	8831.098000	0.606744	19.971846
11688.190000	8831.178000	0.605728	19.962558
11688.250000	8832.110000	0.607500	19.971976
11688.310000	8832.800000	0.607256	19.965045
11688.370000	8832.868000	0.606824	19.963745
11688.430000	8833.495000	0.607245	19.968834
11688.490000	8834.425000	0.607843	19.970305
11688.550000	8834.918000	0.608148	19.968235
11688.610000	8835.847000	0.608186	19.969950
11688.670000	8836.399000	0.608588	19.967525
11688.730000	8836.838000	0.606683	19.969261
11688.790000	8837.826000	0.608959	19.969386
11688.850000	8838.118000	0.608120	19.970253
11688.910000	8839.008000	0.608297	19.963937
11688.970000	8839.439000	0.608340	19.970195
11689.030000	8839.819000	0.608569	19.964017
11689.090000	8840.546000	0.606527	19.967731
11689.150000	8841.125000	0.606101	19.964123
11689.210000	8841.708000	0.606550	19.966705
11689.270000	8842.384000	0.606374	19.965843
11689.330000	8842.668000	0.607108	19.965874
11689.390000	8843.739000	0.607736	19.965730
11689.450000	8844.184000	0.607442	19.967872
11689.510000	8844.821000	0.606886	19.958133
11689.570000	8845.092000	0.606138	19.966279
11689.630000	8845.735000	0.608002	19.970167
11689.690000	8846.578000	0.607076	19.966839
11689.750000	8847.079000	0.607250	19.970895
11689.810000	8847.884000	0.606831	19.966220
11689.870000	8848.053000	0.606762	19.963361
11689.930000	8848.811000	0.606908	19.963813
11689.990000	8849.555000	0.606293	19.966727
11690.050000	8850.285000	0.607523	19.966288
11690.110000	8850.523000	0.606867	19.968930
11690.170000	8851.189000	0.607145	19.970157
11690.230000	8852.198000	0.609596	19.964717
11690.290000	8852.585000	0.608506	19.965109
11690.350000	8853.304000	0.606349	19.963574
11690.410000	8853.761000	0.606629	19.967837
11690.470000	8854.365000	0.608210	19.964441
11690.530000	8855.179000	0.609023	19.965301
11690.590000	8855.255000	0.607218	19.967662
11690.650000	8856.289000	0.607674	19.966447
11690.710000	8856.973000	0.607728	19.972440
11690.770000	8857.210000	0.607438	19.965905
11690.830000	8858.156000	0.608905	19.969718
11690.890000	8858.870000	0.607062	19.970981
11690.950000	8859.052000	0.607697	19.965435
11691.010000	8859.761000	0.607708	19.967354
11691.070000	8860.468000	0.608304	19.963955
11691.130000	8860.737000	0.607061	19.968272
11691.190000	8861.659000	0.607622	19.971094
11691.250000	8862.266000	0.607387	19.963625
11691.310000	8862.618000	0.607166	19.970454
11691.370000	8863.179000	0.607652	19.965291
11691.430000	8863.853000	0.607696	19.971739
11691.490000	8864.608000	0.606814	19.966451
11691.550000	8864.997000	0.607483	19.969358
11691.610000	8865.816000	0.606593	19.968309
11691.670000	8866.538000	0.607465	19.965377
11691.730000	8867.041000	0.607142	19.968695
11691.790000	8867.357000	0.606359	19.967010
11691.850000	8868.363000	0.608615	19.969200
11691.910000	8868.764000	0.608444	19.966140
11691.970000	8869.404000	0.608362	19.969755
11692.030000	8869.907000	0.607180	19.965337
11692.090000	8870.709000	0.608229	19.962597
11692.150000	8871.097000	0.607583	19.965799
11692.210000	8871.601000	0.607720	19.964189
11692.270000	8872.486000	0.607514	19.966386
11692.330000	8872.820000	0.606825	19.963908
11692.390000	8873.692000	0.607916	19.962977
11692.450000	8874.108000	0.607255	19.967206
11692.510000	8874.702000	0.607872	19.973433
11692.570000	8875.564000	0.608975	19.964022
11692.630000	8875.895000	0.608090	19.970638
11692.690000	8876.573000	0.607167	19.963400
11692.750000	8877.279000	0.608339	19.968182
11692.810000	8877.588000	0.606526	19.968845
11692.870000	8878.385000	0.606779	19.967788
11692.930000	8879.036000	0.607464	19.971764
11692.990000	8879.896000	0.607782	19.969594
11693.050000	8880.466000	0.609221	19.965368
11693.110000	8880.552000	0.609250	19.959592
11693.170000	8881.281000	0.606697	19.971758
11693.230000	8881.925000	0.608130	19.968549
11693.290000	8882.635000	0.608833	19.970489
11693.350000	8883.100000	0.609031	19.962265
11693.410000	8883.724000	0.607883	19.959921
11693.470000	8884.306000	0.607382	19.968301
11693.530000	8884.719000	0.606872	19.971317
11693.590000	8885.666000	0.607862	19.970715
11693.650000	8886.048000	0.607185	19.967516
11693.710000	8886.947000	0.606752	19.967005
11693.770000	8887.263000	0.607240	19.965093
11693.830000	8887.991000	0.608177	19.959270
11693.890000	8888.563000	0.607009	19.974546
11693.950000	8889.339000	0.607210	19.967767
11694.010000	8889.877000	0.610323	19.970514
11694.070000	8890.320000	0.607987	19.964020
11694.130000	8890.995000	0.608113	19.968180
11694.190000	8891.846000	0.607555	19.964328
11694.250000	8891.802000	0.604903	19.969947
11694.310000	8892.799000	0.606810	19.967640
11694.370000	8893.154000	0.607265	19.964392
11694.430000	8893.952000	0.608973	19.967720
11694.490000	8894.368000	0.608021	19.967332
11694.550000	8895.194000	0.607112	19.971734
11694.610000	8895.625000	0.608604	19.964556
11694.670000	8896.441000	0.608700	19.967122
11694.730000	8897.027000	0.607543	19.968061
11694.790000	8897.871000	0.607885	19.967200
11694.850000	8898.111000	0.608733	19.957545
11694.910000	8898.367000	0.605958	19.967688
11694.970000	8899.101000	0.607222	19.961294
11695.030000	8900.173000	0.606905	19.964052
11695.090000	8900.569000	0.607339	19.970763
11695.150000	8901.074000	0.606411	19.964537
11695.210000	8901.832000	0.608466	19.968510
11695.270000	8902.101000	0.607324	19.963694
11695.330000	8902.779000	0.608094	19.963658
11695.390000	8903.473000	0.607732	19.969097
11695.450000	8904.058000	0.608449	19.966891
11695.510000	8904.688000	0.608521	19.966556
11695.570000	8905.344000	0.608616	19.966037
11695.630000	8905.976000	0.608314	19.961735
11695.690000	8906.618000	0.608426	19.963427
11695.750000	8907.258000	0.608770	19.964671
11695.810000	8907.637000	0.606863	19.965171
11695.870000	8908.341000	0.607495	19.970287
11695.930000	8908.949000	0.607318	19.972386
11695.990000	8909.624000	0.608431	19.965743
11696.050000	8910.084000	0.607588	19.965964
11696.110000	8910.979000	0.608285	19.962968
11696.170000	8911.535000	0.607073	19.959931
11696.230000	8911.850000	0.606335	19.968172
11696.290000	8912.370000	0.607111	19.968358
11696.350000	8912.977000	0.607269	19.971040
11696.410000	8913.571000	0.606749	19.965366
11696.470000	8914.602000	0.608197	19.962942
11696.530000	8915.111000	0.606757	19.962303
11696.590000	8915.471000	0.606431	19.963520
11696.650000	8916.001000	0.606732	19.961984
11696.710000	8916.853000	0.608259	19.963197
11696.770000	8917.311000	0.607372	19.966360
11696.830000	8918.137000	0.608345	19.969750
11696.890000	8918.515000	0.608388	19.969888
11696.950000	8919.102000	0.607566	19.967091
11697.010000	8919.800000	0.608837	19.972329
11697.070000	8920.397000	0.607401	19.973830
11697.130000	8920.892000	0.607351	19.969551
11697.190000	8921.449000	0.607719	19.968619
11697.250000	8922.150000	0.607975	19.968268
11697.310000	8922.643000	0.607608	19.964328
11697.370000	8923.161000	0.605886	19.970937
11697.430000	8923.843000	0.606099	19.959014
11697.490000	8924.507000	0.607031	19.962198
11697.550000	8925.084000	0.607405	19.968999
11697.610000	8925.242000	0.606663	19.961721
11697.670000	8926.417000	0.607812	19.966305
11697.730000	8927.033000	0.609104	19.965009
11697.790000	8927.324000	0.606390	19.960083
11697.850000	8928.337000	0.607972	19.964428
11697.910000	8928.916000	0.609276	19.961982
11697.970000	8929.332000	0.609089	19.964284
11698.030000	8929.834000	0.607584	19.965459
11698.090000	8930.413000	0.608204	19.966105
11698.150000	8931.048000	0.608844	19.965346
11698.210000	8931.519000	0.607598	19.963504
11698.270000	8932.227000	0.606831	19.967131
11698.330000	8933.214000	0.607687	19.964665
11698.390000	8933.527000	0.607513	19.968736
11698.450000	8934.014000	0.607942	19.969386
11698.510000	8934.455000	0.607437	19.967914
11698.570000	8935.509000	0.608876	19.965193
11698.630000	8936.026000	0.608089	19.966248
11698.690000	8936.772000	0.607666	19.964915
11698.750000	8937.312000	0.608145	19.969736
11698.810000	8937.369000	0.607827	19.967348
11698.870000	8938.466000	0.607343	19.965220
11698.930000	8939.260000	0.607163	19.962071
11698.990000	8939.310000	0.606147	19.967298
11699.050000	8940.100000	0.607178	19.969980
11699.110000	8940.587000	0.608073	19.965567
11699.170000	8941.337000	0.607883	19.966138
11699.230000	8942.013000	0.609532	19.968005
11699.290000	8942.520000	0.609030	19.967058
11699.350000	8942.834000	0.607471	19.972238
11699.410000	8943.504000	0.606271	19.966160
11699.470000	8944.304000	0.608175	19.958223
11699.530000	8944.632000	0.607760	19.963569
11699.590000	8944.981000	0.606304	19.964325
11699.650000	8946.079000	0.606989	19.969006
11699.710000	8946.623000	0.608111	19.972547
11699.770000	8947.303000	0.607641	19.964533
11699.830000	8947.849000	0.607430	19.963570
11699.890000	8948.569000	0.607727	19.966361
11699.950000	8948.981000	0.607360	19.962770
11700.010000	8950.024000	0.608482	19.962623
11700.070000	8950.270000	0.608563	19.961827
11700.130000	8951.244000	0.610490	19.965709
11700.190000	8951.664000	0.608900	19.968968
11700.250000	8952.122000	0.609104	19.966816
11700.310000	8952.618000	0.607776	19.962923
11700.370000	8953.157000	0.608173	19.967936
11700.430000	8954.153000	0.608669	19.967017
11700.490000	8954.665000	0.607471	19.965382
11700.550000	8955.260000	0.607394	19.964024
11700.610000	8955.607000	0.607213	19.970037
11700.670000	8956.331000	0.607695	19.963878
11700.730000	8957.041000	0.607024	19.960213
11700.790000	8957.508000	0.607398	19.968643
11700.850000	8958.150000	0.607893	19.968152
11700.910000	8958.498000	0.608276	19.966527
11700.970000	8959.222000	0.607883	19.964855
11701.030000	8959.703000	0.607093	19.964784
11701.090000	8960.434000	0.607694	19.964277
11701.150000	8961.075000	0.608177	19.956744
11701.210000	8962.030000	0.609178	19.967841
11701.270000	8962.028000	0.607721	19.958951
11701.330000	8962.974000	0.607604	19.970024
11701.390000	8963.468000	0.607704	19.965921
11701.450000	8964.148000	0.607004	19.962912
11701.510000	8964.473000	0.607213	19.965148
11701.570000	8965.264000	0.608163	19.967107
11701.630000	8965.762000	0.607648	19.964273
11701.690000	8966.653000	0.608084	19.965131
11701.750000	8967.167000	0.609416	19.965128
11701.810000	8967.663000	0.608337	19.964346
11701.870000	8968.330000	0.608271	19.968174
11701.930000	8968.671000	0.607363	19.969880
11701.990000	8969.917000	0.609755	19.958340
11702.050000	8969.775000	0.605960	19.970346
11702.110000	8970.524000	0.606600	19.966345
11702.170000	8970.996000	0.607286	19.961123
11702.230000	8972.035000	0.607793	19.964038
11702.290000	8972.886000	0.608571	19.970682
11702.350000	8972.957000	0.607322	19.965542
11702.410000	8973.552000	0.607673	19.967305
11702.470000	8974.287000	0.608569	19.966304
11702.530000	8974.905000	0.608382	19.960424
11702.590000	8975.574000	0.608465	19.961931
11702.650000	8976.058000	0.607726	19.971253
11702.710000	8976.766000	0.608313	19.962909
11702.770000	8977.083000	0.606411	19.966017
11702.830000	8977.885000	0.609636	19.964556
11702.890000	8978.517000	0.607769	19.965206
11702.950000	8979.040000	0.608514	19.967139
11703.010000	8979.487000	0.609346	19.963193
11703.070000	8980.434000	0.608494	19.971414
11703.130000	8980.871000	0.608858	19.964893
11703.190000	8981.370000	0.606543	19.969622
11703.250000	8981.883000	0.607061	19.967514
11703.310000	8982.645000	0.608282	19.967847
11703.370000	8983.349000	0.608515	19.966382
11703.430000	8983.701000	0.608181	19.964219
11703.490000	8984.380000	0.606844	19.964186
11703.550000	8985.121000	0.606199	19.965598
11703.610000	8985.658000	0.608139	19.967430
11703.670000	8986.320000	0.608486	19.967875
11703.730000	8986.750000	0.607847	19.966309
11703.790000	8987.468000	0.607934	19.966708
11703.850000	8988.073000	0.606740	19.965769
11703.910000	8989.003000	0.608036	19.962121
11703.970000	8989.531000	0.607999	19.968208
11704.030000	8989.813000	0.607014	19.966788
11704.090000	8990.357000	0.607672	19.963886
11704.150000	8991.219000	0.608367	19.959795
11704.210000	8991.899000	0.609577	19.963064
11704.270000	8992.418000	0.608937	19.967575
11704.330000	8992.888000	0.607109	19.962298
11704.390000	8993.316000	0.608798	19.965677
11704.450000	8993.890000	0.608518	19.966740
11704.510000	8994.874000	0.608757	19.969238
11704.570000	8994.985000	0.607177	19.966779
11704.630000	8995.802000	0.607728	19.962246
11704.690000	8996.584000	0.608466	19.966558
11704.750000	8997.320000	0.607397	19.969504
11704.810000	8998.161000	0.610363	19.969253
11704.870000	8998.263000	0.608462	19.968705
11704.930000	8998.964000	0.607440	19.968809
11704.990000	8999.265000	0.607441	19.966777
11705.050000	9000.042000	0.607543	19.964765
11705.110000	9000.885000	0.609362	19.964835
11705.170000	9001.366000	0.608597	19.967171
11705.230000	9001.888000	0.607405	19.963573
11705.290000	9002.450000	0.608713	19.970008
11705.350000	9003.211000	0.607408	19.957057
11705.410000	9003.705000	0.607784	19.971712
11705.470000	9004.571000	0.607933	19.970391
11705.530000	9005.119000	0.608444	19.966855
11705.590000	9005.543000	0.606788	19.963242
11705.650000	9006.361000	0.607072	19.972381
11705.710000	9006.708000	0.607237	19.963124
11705.770000	9007.522000	0.608432	19.964069
11705.830000	9008.151000	0.609205	19.974591
11705.890000	9008.428000	0.607760	19.965219
11705.950000	9009.159000	0.609022	19.962925
11706.010000	9009.757000	0.609728	19.960114
11706.070000	9010.472000	0.609452	19.963494
11706.130000	9010.601000	0.607501	19.966753
11706.190000	9011.442000	0.607940	19.961964
11706.250000	9012.332000	0.608934	19.965751
11706.310000	9012.583000	0.607244	19.968240
11706.370000	9013.321000	0.607541	19.969631
11706.430000	9013.994000	0.608637	19.965780
11706.490000	9014.942000	0.608784	19.965627
11706.550000	9014.951000	0.607343	19.965477
11706.610000	9015.718000	0.607267	19.968903
11706.670000	9016.588000	0.607373	19.972522
11706.730000	9017.192000	0.607891	19.965514
11706.790000	9017.146000	0.606006	19.962751
11706.850000	9018.011000	0.607999	19.968048
11706.910000	9018.392000	0.608220	19.963669
11706.970000	9019.307000	0.607043	19.965565
11707.030000	9019.833000	0.608491	19.968077
11707.090000	9020.804000	0.607326	19.961874
11707.150000	9020.930000	0.606181	19.969091
11707.210000	9021.637000	0.608398	19.965978
11707.270000	9022.176000	0.607846	19.965647
11707.330000	9022.686000	0.608004	19.970741
11707.390000	9023.474000	0.608264	19.970185
11707.450000	9024.455000	0.608602	19.963127
11707.510000	9024.862000	0.609596	19.967079
11707.570000	9024.954000	0.606312	19.961575
11707.630000	9026.314000	0.609633	19.966237
11707.690000	9026.325000	0.606366	19.967378
11707.750000	9027.079000	0.608053	19.970634
11707.810000	9027.687000	0.608344	19.961190
11707.870000	9028.096000	0.608145	19.957023
11707.930000	9028.891000	0.607118	19.968232
11707.990000	9029.441000	0.609233	19.969772
11708.050000	9030.390000	0.609332	19.961234
11708.110000	9030.688000	0.608052	19.965166
11708.170000	9031.428000	0.609203	19.971097
11708.230000	9031.935000	0.608063	19.967769
11708.290000	9032.528000	0.608230	19.969245
11708.350000	9033.287000	0.607958	19.969863
11708.410000	9033.722000	0.608541	19.965946
11708.470000	9034.383000	0.608041	19.965833
11708.530000	9034.932000	0.608260	19.970310
11708.590000	9035.741000	0.608245	19.964225
11708.650000	9036.171000	0.607154	19.963818
11708.710000	9036.742000	0.606938	19.973093
11708.770000	9037.559000	0.608900	19.965528
11708.830000	9037.839000	0.607626	19.968392
11708.890000	9038.661000	0.608295	19.972725
11708.950000	9039.296000	0.607772	19.967263
11709.010000	9039.668000	0.606706	19.967003
11709.070000	9040.438000	0.608640	19.966635
11709.130000	9040.848000	0.609081	19.961143
11709.190000	9041.385000	0.609709	19.965107
11709.250000	9042.322000	0.608867	19.967129
11709.310000	9042.960000	0.609802	19.966054
11709.370000	9043.268000	0.607573	19.968721
11709.430000	9043.680000	0.606647	19.963342
11709.490000	9044.460000	0.607725	19.974413
11709.550000	9045.227000	0.610156	19.973681
11709.610000	9045.826000	0.608540	19.968819
11709.670000	9046.081000	0.607114	19.966654
11709.730000	9046.908000	0.608232	19.969834
11709.790000	9047.520000	0.608726	19.959845
11709.850000	9048.190000	0.608781	19.971297
11709.910000	9048.590000	0.607201	19.968103
11709.970000	9049.275000	0.608801	19.968494
11710.030000	9049.902000	0.607182	19.965553
11710.090000	9050.503000	0.608201	19.969788
11710.150000	9051.014000	0.607193	19.968898
11710.210000	9051.931000	0.608520	19.965577
11710.270000	9052.464000	0.607868	19.970676
11710.330000	9052.929000	0.607586	19.967132
11710.390000	9053.705000	0.609562	19.965227
11710.450000	9054.012000	0.609882	19.962971
11710.510000	9054.373000	0.607023	19.965424
11710.570000	9055.110000	0.608462	19.972664
11710.630000	9056.047000	0.608776	19.970165
11710.690000	9056.372000	0.607643	19.966585
11710.750000	9057.323000	0.609479	19.973073
11710.810000	9057.675000	0.609016	19.963780
11710.870000	9058.473000	0.608771	19.967086
11710.930000	9059.133000	0.608127	19.965756
11710.990000	9059.536000	0.608205	19.965444
11711.050000	9059.881000	0.608768	19.964853
11711.110000	9060.912000	0.609306	19.965290
11711.170000	9061.338000	0.608828	19.962776
11711.230000	9061.990000	0.609229	19.964857
11711.290000	9062.550000	0.608051	19.972928
11711.350000	9063.327000	0.608592	19.972353
11711.410000	9063.659000	0.607734	19.970031
11711.470000	9064.658000	0.609419	19.967925
11711.530000	9064.995000	0.607677	19.965184
11711.590000	9065.760000	0.609006	19.966141
11711.650000	9066.116000	0.608321	19.972472
11711.710000	9066.654000	0.607626	19.961043
11711.770000	9067.309000	0.609420	19.966190
11711.830000	9067.749000	0.607289	19.969555
11711.890000	9068.346000	0.607338	19.968435
11711.950000	9068.979000	0.608189	19.966819
11712.010000	9069.943000	0.607645	19.969465
11712.070000	9070.158000	0.607601	19.969680
11712.130000	9070.870000	0.608252	19.966711
11712.190000	9071.323000	0.609231	19.971290
11712.250000	9071.973000	0.608224	19.968882
11712.310000	9072.614000	0.608021	19.962674
11712.370000	9073.133000	0.609017	19.966732
11712.430000	9073.927000	0.609043	19.967162
11712.490000	9074.194000	0.608105	19.965975
11712.550000	9074.950000	0.607023	19.960584
11712.610000	9075.744000	0.608387	19.965854
11712.670000	9076.498000	0.608341	19.967005
11712.730000	9076.651000	0.607953	19.961555
11712.790000	9077.741000	0.608148	19.965972
11712.850000	9078.133000	0.609251	19.966821
11712.910000	9078.613000	0.608978	19.963678
11712.970000	9079.486000	0.608907	19.963966
11713.030000	9079.808000	0.608123	19.962548
11713.090000	9080.624000	0.607766	19.967469
11713.150000	9080.867000	0.608118	19.965673
11713.210000	9081.691000	0.608743	19.963273
11713.270000	9082.610000	0.609658	19.968240
11713.330000	9082.857000	0.609342	19.962471
11713.390000	9083.694000	0.610626	19.970817
11713.450000	9084.142000	0.609399	19.972135
11713.510000	9084.707000	0.608454	19.966118
11713.570000	9085.345000	0.609438	19.970371
11713.630000	9085.816000	0.607868	19.964215
11713.690000	9086.581000	0.608392	19.975451
11713.750000	9087.099000	0.608010	19.968297
11713.810000	9087.630000	0.606856	19.964295
11713.870000	9088.072000	0.607799	19.972294
11713.930000	9088.605000	0.607456	19.968207
11713.990000	9089.513000	0.608208	19.967254
11714.050000	9090.152000	0.607654	19.964737
11714.110000	9090.686000	0.607813	19.969106
11714.170000	9091.394000	0.609066	19.964337
11714.230000	9091.968000	0.608160	19.967221
11714.290000	9092.475000	0.608756	19.968038
11714.350000	9092.714000	0.607109	19.962574
11714.410000	9093.415000	0.607996	19.970187
11714.470000	9094.295000	0.608792	19.969212
11714.530000	9094.937000	0.608948	19.965910
11714.590000	9095.544000	0.608765	19.968123
11714.650000	9096.212000	0.608198	19.966768
11714.710000	9096.910000	0.607745	19.970789
11714.770000	9097.357000	0.607116	19.966738
11714.830000	9097.840000	0.607536	19.970123
11714.890000	9098.624000	0.608700	19.966508
11714.950000	9099.042000	0.607786	19.970859
11715.010000	9099.574000	0.608337	19.966431
11715.070000	9100.332000	0.608412	19.972588
11715.130000	9100.904000	0.608818	19.960715
11715.190000	9101.683000	0.609265	19.970521
11715.250000	9102.166000	0.608625	19.966888
11715.310000	9102.900000	0.608409	19.964597
11715.370000	9103.386000	0.609698	19.972380
11715.430000	9103.898000	0.607152	19.967925
11715.490000	9104.640000	0.608105	19.969769
11715.550000	9104.843000	0.606785	19.970886
11715.610000	9105.556000	0.608476	19.968337
11715.670000	9106.157000	0.608291	19.967053
11715.730000	9106.878000	0.608058	19.968938
11715.790000	9107.588000	0.608689	19.965563
11715.850000	9107.957000	0.608577	19.969828
11715.910000	9108.822000	0.607697	19.962120
11715.970000	9109.470000	0.608738	19.966241
11716.030000	9109.852000	0.609002	19.972801
11716.090000	9110.437000	0.607940	19.969513
11716.150000	9111.027000	0.607451	19.964792
11716.210000	9111.636000	0.608625	19.970807
11716.270000	9112.775000	0.609564	19.965136
11716.330000	9112.911000	0.608689	19.970230
11716.390000	9113.521000	0.607911	19.965760
11716.450000	9113.684000	0.608609	19.972284
11716.510000	9114.659000	0.607306	19.966666
11716.570000	9115.355000	0.608161	19.968440
11716.630000	9115.694000	0.607736	19.962786
11716.690000	9116.562000	0.607944	19.969027
11716.750000	9117.223000	0.607987	19.969206
11716.810000	9117.750000	0.608576	19.971021
11716.870000	9118.634000	0.608605	19.969166
11716.930000	9118.878000	0.609058	19.969529
11716.990000	9119.629000	0.608527	19.968816
11717.050000	9120.183000	0.608780	19.965226
11717.110000	9120.527000	0.607796	19.967530
11717.170000	9121.495000	0.609106	19.967696
11717.230000	9122.369000	0.609893	19.964717
11717.290000	9122.468000	0.608416	19.965443
11717.350000	9122.854000	0.607964	19.968087
11717.410000	9123.581000	0.608722	19.967654
11717.470000	9124.140000	0.608354	19.965691
11717.530000	9125.119000	0.608590	19.966543
11717.590000	9125.638000	0.608246	19.966881
11717.650000	9126.148000	0.607697	19.965335
11717.710000	9126.663000	0.608799	19.968539
11717.770000	9127.560000	0.610033	19.970845
11717.830000	9127.735000	0.610603	19.964037
11717.890000	9128.429000	0.607662	19.970178
11717.950000	9128.999000	0.608193	19.965511
11718.010000	9129.759000	0.608800	19.971941
11718.070000	9130.369000	0.608426	19.977410
11718.130000	9130.925000	0.607684	19.964842
11718.190000	9131.439000	0.608203	19.967762
11718.250000	9131.883000	0.607584	19.970015
11718.310000	9132.687000	0.609768	19.967703
11718.370000	9133.454000	0.607474	19.965866
11718.430000	9133.994000	0.609264	19.969950
11718.490000	9134.542000	0.609374	19.966791
11718.550000	9135.110000	0.607570	19.968535
11718.610000	9135.740000	0.608231	19.964209
11718.670000	9136.197000	0.607989	19.973152
11718.730000	9137.031000	0.606494	19.975891
11718.790000	9137.529000	0.608034	19.972907
11718.850000	9138.177000	0.607149	19.960423
11718.910000	9138.816000	0.607311	19.971961
11718.970000	9139.067000	0.608866	19.965890
11719.030000	9139.917000	0.608980	19.967890
11719.090000	9140.893000	0.608846	19.966946
11719.150000	9141.090000	0.607782	19.970621
11719.210000	9141.700000	0.609205	19.972601
11719.270000	9142.163000	0.608264	19.965827
11719.330000	9143.266000	0.609638	19.964860
11719.390000	9143.385000	0.607700	19.965532
11719.450000	9143.995000	0.610155	19.966100
11719.510000	9144.474000	0.608165	19.967144
11719.570000	9145.097000	0.607002	19.970953
11719.630000	9146.035000	0.607575	19.967195
11719.690000	9146.492000	0.608148	19.968622
11719.750000	9147.179000	0.607790	19.975052
11719.810000	9147.445000	0.607094	19.967944
11719.870000	9148.396000	0.607874	19.962332
11719.930000	9148.803000	0.607945	19.966190
11719.990000	9149.583000	0.608686	19.971830
11720.050000	9150.054000	0.607393	19.970557
11720.110000	9151.009000	0.609063	19.971443
11720.170000	9151.460000	0.608673	19.970389
11720.230000	9151.842000	0.608679	19.966573
11720.290000	9152.682000	0.610012	19.969286
11720.350000	9152.817000	0.608583	19.968563
11720.410000	9153.539000	0.608605	19.964019
11720.470000	9154.471000	0.609078	19.968053
11720.530000	9154.984000	0.609586	19.968759
11720.590000	9155.523000	0.607566	19.968953
11720.650000	9156.200000	0.608102	19.964798
11720.710000	9156.455000	0.607259	19.968589
11720.770000	9157.282000	0.608555	19.965886
11720.830000	9158.060000	0.608709	19.966872
11720.890000	9158.207000	0.608430	19.966314
11720.950000	9158.972000	0.608972	19.965657
11721.010000	9159.647000	0.609040	19.966987
11721.070000	9160.312000	0.609405	19.963644
11721.130000	9160.893000	0.609949	19.967732
11721.190000	9161.545000	0.608512	19.966105
11721.250000	9161.913000	0.607213	19.969657
11721.310000	9162.768000	0.608848	19.966480
11721.370000	9163.440000	0.609015	19.964709
11721.430000	9164.015000	0.608643	19.969196
11721.490000	9164.504000	0.607959	19.967969
11721.550000	9165.018000	0.608937	19.964752
11721.610000	9165.599000	0.608315	19.966811
11721.670000	9166.483000	0.610546	19.968051
11721.730000	9166.832000	0.608565	19.970591
11721.790000	9167.455000	0.607541	19.973975
11721.850000	9168.148000	0.609516	19.970691
11721.910000	9168.539000	0.607290	19.960857
11721.970000	9169.216000	0.607141	19.967999
11722.030000	9170.080000	0.607998	19.961623
11722.090000	9170.644000	0.608824	19.968912
11722.150000	9170.977000	0.609133	19.970718
11722.210000	9171.601000	0.607506	19.967408
11722.270000	9172.177000	0.607811	19.966472
11722.330000	9172.740000	0.610585	19.962549
11722.390000	9173.471000	0.608675	19.967842
11722.450000	9174.188000	0.608222	19.966469
11722.510000	9174.727000	0.607842	19.965070
11722.570000	9175.110000	0.607522	19.970374
11722.630000	9175.648000	0.608470	19.967290
11722.690000	9176.688000	0.608997	19.973006
11722.750000	9177.198000	0.608604	19.966386
11722.810000	9178.007000	0.609691	19.969783
11722.870000	9178.225000	0.608475	19.971721
11722.930000	9178.656000	0.608405	19.969630
11722.990000	9179.475000	0.608486	19.967699
11723.050000	9180.028000	0.609970	19.965440
11723.110000	9180.711000	0.609440	19.962267
11723.170000	9181.161000	0.608090	19.967084
11723.230000	9181.858000	0.608858	19.968510
11723.290000	9182.548000	0.608011	19.968822
11723.350000	9183.096000	0.607987	19.966042
11723.410000	9183.913000	0.609092	19.973468
11723.470000	9184.419000	0.608559	19.962663
11723.530000	9184.972000	0.608355	19.966656
11723.590000	9185.737000	0.608643	19.965102
11723.650000	9185.971000	0.608838	19.977275
11723.710000	9186.881000	0.609511	19.959383
11723.770000	9187.396000	0.608353	19.966324
11723.830000	9187.767000	0.608018	19.972382
11723.890000	9188.756000	0.608517	19.965591
11723.950000	9189.093000	0.608390	19.968728
11724.010000	9189.850000	0.609974	19.965095
11724.070000	9189.958000	0.608021	19.966759
11724.130000	9190.821000	0.608700	19.969059
11724.190000	9192.000000	0.609431	19.968885
11724.250000	9192.190000	0.608413	19.966807
11724.310000	9192.609000	0.608199	19.967547
11724.370000	9193.240000	0.607604	19.968745
11724.430000	9193.870000	0.608396	19.966512
11724.490000	9194.412000	0.608604	19.961428
11724.550000	9195.327000	0.608423	19.967833
11724.610000	9195.762000	0.609493	19.971390
11724.670000	9196.469000	0.609267	19.970617
11724.730000	9196.809000	0.609029	19.962132
11724.790000	9197.365000	0.607982	19.964255
11724.850000	9197.713000	0.607740	19.964595
11724.910000	9198.620000	0.607227	19.965738
11724.970000	9199.156000	0.608184	19.966559
11725.030000	9199.948000	0.608392	19.969775
11725.090000	9200.453000	0.609381	19.963222
11725.150000	9201.167000	0.608802	19.961997
11725.210000	9201.637000	0.608912	19.967105
11725.270000	9202.389000	0.608143	19.966286
11725.330000	9202.947000	0.608749	19.965435
11725.390000	9203.484000	0.610142	19.961908
11725.450000	9204.042000	0.609427	19.962935
11725.510000	9204.783000	0.608618	19.965290
11725.570000	9205.343000	0.607904	19.968262
11725.630000	9205.503000	0.607419	19.970596
11725.690000	9206.636000	0.608431	19.968107
11725.750000	9207.176000	0.610126	19.971241
11725.810000	9207.734000	0.607632	19.968367
11725.870000	9208.311000	0.606922	19.970104
11725.930000	9208.715000	0.609091	19.964732
11725.990000	9209.659000	0.609360	19.964500
11726.030000	9210.391000	0.608734	19.974440