File: velstep2_TR2_exp013_sepiolite.txt
Time(s)	Displ(microns)	Friction	EffectiveNormalstress(MPa)
11093.154000	3515.946000	0.498358	29.986167
11102.306000	3533.450000	0.501087	30.002150
11111.398000	3553.665000	0.497305	30.008147
11120.470000	3571.108000	0.495826	29.996855
11129.630000	3589.563000	0.495446	29.983645
11138.622000	3606.986000	0.495101	30.008927
11147.674000	3623.499000	0.497233	30.003758
11156.766000	3644.423000	0.494454	30.004959
11165.918000	3662.190000	0.492884	30.000587
11174.960000	3679.896000	0.494566	29.991522
11184.072000	3697.805000	0.493800	29.993264
11193.094000	3715.653000	0.494772	29.995828
11202.246000	3734.877000	0.491843	30.003932
11211.328000	3753.433000	0.490703	29.994550
11220.440000	3771.584000	0.490626	29.990259
11229.543000	3789.129000	0.489514	29.993391
11238.726000	3807.341000	0.491904	29.996209
11247.818000	3826.180000	0.489315	29.996831
11256.830000	3843.907000	0.488640	29.998485
11265.942000	3861.876000	0.489131	29.996830
11275.064000	3879.360000	0.489214	29.988421
11284.066000	3897.350000	0.491940	30.005664
11293.258000	3916.837000	0.487175	30.005295
11302.360000	3934.745000	0.487895	29.991559
11311.429000	3952.836000	0.487559	30.000998
11320.452000	3969.551000	0.489870	29.990276
11329.514000	3989.604000	0.488709	30.006098
11338.576000	4004.518000	0.482529	29.997477
11347.618000	4006.178000	0.479455	29.979890
11356.720000	4008.181000	0.477451	29.960581
11365.724000	4009.820000	0.475521	29.958790
11374.836000	4011.540000	0.474257	29.952848
11383.878000	4013.341000	0.473089	29.965796
11392.990000	4015.021000	0.471429	29.965134
11402.052000	4017.206000	0.469204	29.981422
11411.114000	4018.946000	0.469276	29.974774
11420.246000	4020.545000	0.468719	29.976080
11429.348000	4022.447000	0.467416	29.985177
11438.410000	4024.127000	0.467800	29.986620
11447.472000	4026.009000	0.466965	29.981943
11456.494000	4027.931000	0.466508	29.997434
11465.576000	4029.590000	0.465512	29.986683
11474.578000	4031.169000	0.466446	29.987246
11483.640000	4033.496000	0.465742	29.990563
11492.582000	4034.852000	0.466277	29.994718
11501.683000	4037.159000	0.465948	30.002051
11510.725000	4038.514000	0.465274	30.012398
11519.847000	4040.538000	0.465595	29.986781
11528.909000	4042.460000	0.464894	29.994998
11537.981000	4044.282000	0.464542	30.008698
11547.084000	4046.062000	0.465157	29.996634
11556.209000	4048.066000	0.464582	29.999994
11565.331000	4049.583000	0.464904	30.008200
11574.433000	4051.526000	0.464880	30.000195
11583.505000	4053.003000	0.464712	29.998797
11592.577000	4055.128000	0.466034	29.993448
11601.619000	4056.727000	0.465075	29.996534
11610.761000	4058.669000	0.465992	29.997518
11619.863000	4060.592000	0.465390	30.008592
11628.915000	4062.534000	0.465883	29.992362
11637.978000	4064.214000	0.464987	29.993488
11647.030000	4066.075000	0.464984	29.997569
11656.222000	4067.937000	0.465132	30.000477
11665.324000	4069.819000	0.464389	29.993483
11674.506000	4071.337000	0.463593	29.998682
11683.558000	4073.360000	0.464023	29.990399
11692.661000	4074.878000	0.463508	29.994462
11701.753000	4076.841000	0.462676	29.990593
11710.795000	4078.662000	0.463102	30.005716
11719.877000	4080.746000	0.462143	29.994473
11729.039000	4082.163000	0.461335	29.998098
11738.121000	4084.025000	0.462233	29.992518
11747.163000	4085.947000	0.461814	29.987383
11756.245000	4087.950000	0.461990	29.993516
11765.317000	4089.873000	0.461823	29.991079
11774.490000	4091.289000	0.461570	29.993548
11783.722000	4093.070000	0.461958	29.991117
11792.824000	4095.255000	0.460888	29.992169
11801.886000	4096.551000	0.461147	30.000067
11811.058000	4098.918000	0.460652	30.004670
11820.180000	4100.497000	0.461355	29.990556
11829.306000	4102.621000	0.462137	30.006842
11838.368000	4104.503000	0.461691	30.009450
11847.430000	4106.163000	0.462310	30.003983
11856.582000	4107.721000	0.462347	29.995367
11865.645000	4109.522000	0.461973	29.990976
11874.719000	4111.565000	0.462536	29.989634
11883.761000	4113.043000	0.461976	29.998441
11892.903000	4115.107000	0.462372	30.003427
11901.915000	4117.029000	0.461974	29.993537
11911.047000	4118.365000	0.462292	29.995714
11920.159000	4120.530000	0.462357	30.004119
11929.221000	4122.209000	0.462952	29.996866
11938.323000	4124.152000	0.463379	29.995711
11947.395000	4126.155000	0.462157	30.005729
11956.407000	4127.876000	0.462944	30.000459
11965.549000	4129.818000	0.463490	29.998070
11974.571000	4131.538000	0.462090	30.018021
11983.723000	4133.238000	0.462394	29.999992
11992.815000	4134.978000	0.461971	29.994507
12001.877000	4137.245000	0.463251	29.992640
12010.939000	4139.025000	0.463851	30.000874
12020.042000	4140.705000	0.464224	30.003553
12029.144000	4142.405000	0.464664	29.995118
12038.336000	4144.165000	0.464391	29.997671
12047.428000	4146.128000	0.463836	30.006400
12056.490000	4147.868000	0.464733	29.996878
12065.662000	4149.730000	0.464275	30.004479
12074.734000	4151.430000	0.464046	29.993335
12083.836000	4153.251000	0.463944	29.999436
12092.898000	4155.376000	0.463869	30.001230
12101.960000	4156.934000	0.463687	29.990018
12111.002000	4158.492000	0.463408	29.998388
12120.054000	4160.597000	0.463383	29.991259
12129.106000	4162.195000	0.462753	29.995503
12138.128000	4164.098000	0.462622	29.999964
12147.080000	4166.020000	0.462554	29.987771
12156.222000	4167.740000	0.461294	30.007665
12165.304000	4169.804000	0.461516	29.993755
12174.336000	4171.362000	0.462134	30.009247
12183.438000	4173.062000	0.461050	29.995015
12192.510000	4175.086000	0.460739	30.002381
12201.682000	4177.048000	0.460964	29.984689
12210.864000	4178.768000	0.460745	30.002592
12219.976000	4180.529000	0.460571	30.000151
12229.048000	4182.411000	0.460612	29.994263
12238.160000	4184.232000	0.460924	29.993410
12247.242000	4186.033000	0.460270	30.001051
12256.264000	4187.915000	0.460939	30.011832
12265.366000	4189.635000	0.460736	29.993214
12274.478000	4191.537000	0.461193	29.996287
12283.570000	4193.399000	0.461852	29.998051
12292.602000	4195.079000	0.460416	30.012044
12301.664000	4196.718000	0.461874	30.006975
12310.756000	4198.761000	0.461289	30.004951
12319.909000	4200.542000	0.461687	30.002346
12328.911000	4202.444000	0.461862	29.995567
12337.973000	4204.225000	0.461942	29.988627
12347.035000	4205.864000	0.462199	29.999132
12356.097000	4207.524000	0.461714	29.998988
12365.219000	4209.669000	0.462651	30.005075
12374.331000	4211.652000	0.462408	29.998890
12383.393000	4212.866000	0.461791	30.001921
12392.455000	4214.768000	0.461860	30.002301
12401.497000	4216.933000	0.462586	29.993802
12410.580000	4218.734000	0.461838	29.998289
12419.652000	4220.495000	0.462373	30.000649
12428.714000	4222.336000	0.462132	30.005470
12437.700000	4224.178000	0.462139	29.995880
12446.882000	4225.695000	0.461710	30.003437
12455.964000	4227.597000	0.463269	29.999190
12465.076000	4229.277000	0.463077	30.000000
12474.178000	4231.098000	0.463512	30.003960
12483.250000	4232.879000	0.464093	29.999388
12492.302000	4235.145000	0.464194	30.009641
12501.444000	4236.683000	0.464078	30.001158
12510.586000	4238.666000	0.463190	29.993231
12519.688000	4240.649000	0.463008	29.994950
12528.710000	4242.167000	0.463165	29.996787
12537.902000	4244.332000	0.463518	29.994198
12546.945000	4245.891000	0.463557	29.997358
12555.967000	4247.975000	0.462080	30.004473
12565.069000	4249.695000	0.462716	29.991634
12574.181000	4251.557000	0.462518	29.997482
12583.353000	4253.277000	0.461092	29.990212
12592.385000	4255.078000	0.460478	29.999331
12601.399000	4256.858000	0.460757	29.996054
12610.471000	4258.760000	0.460134	29.990496
12619.483000	4260.744000	0.461033	29.995106
12628.535000	4262.282000	0.460176	29.988013
12637.727000	4264.002000	0.460075	29.995477
12646.829000	4265.985000	0.459543	29.999157
12655.851000	4267.745000	0.460466	30.006156
12664.943000	4269.769000	0.459641	30.016642
12674.046000	4271.408000	0.459838	29.999862
12683.148000	4273.371000	0.460296	29.999316
12692.180000	4275.172000	0.459663	30.003126
12701.233000	4277.013000	0.459547	30.008547
12710.335000	4278.814000	0.459720	29.999677
12719.337000	4280.656000	0.459316	30.011492
12728.420000	4282.659000	0.459507	30.006485
12737.552000	4284.055000	0.459364	30.001770
12746.694000	4285.795000	0.459501	29.999055
12755.786000	4287.940000	0.460443	29.989309
12764.788000	4289.741000	0.459494	29.989127
12773.820000	4291.401000	0.459833	29.993397
12782.832000	4293.182000	0.459821	30.006772
12791.934000	4295.063000	0.460807	30.001348
12801.046000	4296.844000	0.460831	30.002610
12810.148000	4298.180000	0.461210	30.004121
12819.190000	4300.244000	0.461183	30.002589
12828.272000	4302.450000	0.461386	29.993659
12837.404000	4303.907000	0.461953	29.991033
12846.407000	4305.910000	0.461481	29.999939
12855.449000	4307.610000	0.460804	30.003729
12864.581000	4309.492000	0.461121	29.991806
12873.643000	4311.131000	0.460001	29.999843
12882.765000	4313.498000	0.461253	30.005419
12891.767000	4314.854000	0.460641	29.997200
12900.879000	4316.271000	0.462063	29.998309
12909.931000	4318.557000	0.461095	29.989754
12919.003000	4320.459000	0.460805	29.997054
12928.175000	4322.301000	0.462053	30.007640
12937.277000	4324.345000	0.462315	29.997779
12946.369000	4325.741000	0.462283	29.989842
12955.491000	4327.623000	0.461626	29.999359
12964.553000	4329.383000	0.462060	29.986773
12973.615000	4331.569000	0.461707	29.996026
12982.757000	4332.985000	0.461957	29.997655
12991.949000	4334.928000	0.461519	30.000068
13001.001000	4336.344000	0.462264	29.987712
13010.103000	4338.591000	0.461664	29.987974
13019.096000	4340.736000	0.460912	29.987770
13028.218000	4342.172000	0.460653	30.001297
13037.235000	4344.378000	0.459708	30.005525
13046.287000	4345.956000	0.459915	29.990842
13055.400000	4347.494000	0.460603	29.996853
13064.492000	4349.457000	0.458901	30.007202
13073.554000	4351.562000	0.459467	29.992751
13082.596000	4353.120000	0.459732	29.998223
13091.598000	4354.921000	0.459505	30.005547
13100.620000	4357.025000	0.460057	29.989857
13109.652000	4358.280000	0.460486	29.990191
13118.744000	4360.729000	0.459450	29.983504
13127.856000	4362.024000	0.458859	30.002957
13137.028000	4363.987000	0.459151	29.993506
13146.090000	4365.524000	0.459159	30.001529
13155.132000	4367.629000	0.459462	30.002492
13164.154000	4369.754000	0.461152	30.000348
13173.186000	4371.190000	0.461239	29.998024
13182.268000	4372.850000	0.461350	30.003671
13191.380000	4374.894000	0.460533	30.011434
13200.462000	4376.634000	0.459726	29.999675
13209.544000	4378.597000	0.460388	29.991703
13218.586000	4380.560000	0.461312	29.994180
13227.529000	4382.280000	0.461412	29.996987
13236.691000	4383.635000	0.461124	29.995900
13245.733000	4385.538000	0.460303	29.999642
13254.795000	4387.318000	0.461717	30.005416
13263.937000	4389.301000	0.462041	30.000962
13273.089000	4391.183000	0.461856	29.999864
13282.141000	4393.086000	0.461637	29.990815
13291.183000	4394.785000	0.462292	29.996511
13300.306000	4396.465000	0.461802	29.999095
13309.568000	4398.408000	0.462452	29.990955
13318.690000	4400.492000	0.461885	29.990878
13327.882000	4402.151000	0.461892	30.005125
13336.995000	4404.033000	0.461835	29.998264
13346.007000	4405.612000	0.461901	30.010588
13355.080000	4407.392000	0.461975	29.993602
13364.212000	4409.416000	0.462782	30.005062
13373.345000	4411.520000	0.462449	29.995510
13382.487000	4412.937000	0.462536	30.007735
13391.559000	4414.535000	0.462312	30.006588
13400.621000	4416.377000	0.463198	29.996337
13409.673000	4418.765000	0.462327	30.000822
13418.736000	4420.201000	0.462931	30.002116
13427.798000	4421.861000	0.462756	29.995382
13436.860000	4423.702000	0.462649	30.008030
13445.892000	4425.827000	0.462360	29.991162
13454.984000	4427.405000	0.461848	30.000956
13463.966000	4429.389000	0.461562	29.999135
13473.038000	4431.210000	0.460569	30.005775
13482.160000	4433.092000	0.460781	30.004410
13491.312000	4435.156000	0.460722	29.993224
13500.414000	4436.390000	0.459887	29.997102
13509.526000	4438.535000	0.460340	29.994467
13518.588000	4440.619000	0.459991	30.004496
13527.740000	4442.036000	0.459150	29.999868
13536.742000	4443.857000	0.459724	29.989879
13545.765000	4445.840000	0.460194	30.000460
13554.777000	4447.641000	0.459580	29.995775
13563.819000	4449.118000	0.459706	30.008002
13572.871000	4451.102000	0.460478	30.009131
13582.053000	4453.004000	0.461650	29.994975
13591.095000	4454.946000	0.461081	29.989933
13600.227000	4456.444000	0.461224	29.989406
13609.259000	4458.528000	0.461199	29.999695
13618.381000	4460.370000	0.460558	29.996811
13627.475000	4461.928000	0.460108	30.002365
13636.517000	4463.769000	0.460575	29.992180
13645.702000	4465.651000	0.461779	29.997010
13654.864000	4467.492000	0.460770	29.999947
13664.036000	4469.557000	0.460470	29.998302
13673.138000	4470.973000	0.460234	29.996006
13682.250000	4472.956000	0.460273	29.997256
13691.352000	4474.696000	0.460227	30.006110
13700.374000	4476.578000	0.460688	29.993795
13709.466000	4478.521000	0.460748	30.006369
13718.638000	4480.626000	0.459902	30.011141
13727.730000	4481.941000	0.460669	29.999440
13736.812000	4483.924000	0.459967	29.995373
13745.954000	4485.786000	0.460427	30.007255
13755.177000	4487.384000	0.460258	30.004818
13764.200000	4489.388000	0.460384	29.995420
13773.303000	4491.148000	0.460497	30.007590
13782.537000	4493.232000	0.460735	29.986512
13791.689000	4494.851000	0.461899	29.997464
13800.781000	4496.490000	0.461341	29.992997
13809.783000	4498.332000	0.461882	29.997430
13818.795000	4500.558000	0.461208	29.994182
13827.787000	4501.792000	0.461128	30.001495
13836.779000	4503.998000	0.462202	30.011923
13845.831000	4505.617000	0.461316	29.993733
13854.913000	4507.499000	0.461092	30.005881
13864.115000	4509.381000	0.462198	30.001873
13873.227000	4510.898000	0.460932	30.004833
13882.419000	4513.124000	0.461185	29.992892
13891.421000	4515.168000	0.460881	29.991245
13900.523000	4516.544000	0.459916	29.997321
13909.505000	4518.750000	0.458885	29.993244
13918.607000	4520.085000	0.459993	29.990330
13927.739000	4522.129000	0.460167	30.006236
13936.921000	4523.930000	0.459422	30.004642
13945.983000	4525.933000	0.459768	29.995170
13955.005000	4527.653000	0.459317	30.000452
13964.127000	4529.556000	0.459275	29.992382
13973.209000	4530.972000	0.458672	29.998324
13982.331000	4532.733000	0.458934	29.989990
13991.373000	4534.938000	0.459262	30.000656
14000.455000	4536.557000	0.459334	29.996655
14009.457000	4538.217000	0.459446	30.004323
14018.600000	4540.018000	0.460165	30.009807
14027.792000	4541.980000	0.460432	30.013077
14036.835000	4544.024000	0.460055	29.997718
14045.947000	4545.805000	0.459934	30.008100
14055.029000	4547.727000	0.460449	29.989357
14064.111000	4549.670000	0.460662	30.000896
14073.323000	4551.269000	0.460552	29.992560
14082.495000	4553.090000	0.461042	30.006470
14091.567000	4554.992000	0.461133	30.002263
14100.599000	4556.712000	0.460130	29.998761
14109.651000	4558.553000	0.460687	30.009747
14118.764000	4560.395000	0.461248	29.993074
14127.856000	4562.378000	0.461105	30.003443
14136.918000	4563.795000	0.461628	30.004559
14146.020000	4565.757000	0.461686	29.986032
14155.082000	4567.660000	0.460609	29.993744
14164.194000	4569.521000	0.461743	30.003775
14173.256000	4571.140000	0.460561	30.014369
14182.388000	4573.366000	0.460690	29.993712
14191.510000	4574.762000	0.461739	29.982191
14200.552000	4576.503000	0.461229	29.996687
14209.654000	4578.020000	0.462203	29.990858
14218.796000	4580.165000	0.462624	29.992324
14227.818000	4582.088000	0.460946	30.005002
14236.880000	4583.787000	0.462370	29.999239
14245.952000	4585.609000	0.461902	29.998007
14254.994000	4587.288000	0.462332	30.009979
14264.076000	4589.231000	0.461707	30.004028
14273.198000	4591.093000	0.461415	30.004415
14282.270000	4592.954000	0.461524	30.001515
14291.352000	4594.877000	0.461906	30.017682
14300.365000	4596.496000	0.461769	30.003802
14309.478000	4598.620000	0.461524	29.999932
14318.560000	4600.421000	0.461044	30.005296
14327.692000	4601.838000	0.460146	30.001712
14336.714000	4604.043000	0.460304	29.998163
14345.776000	4605.844000	0.461105	29.999101
14354.838000	4607.706000	0.460415	30.007177
14363.820000	4609.163000	0.460156	29.994927
14372.842000	4611.187000	0.460337	30.006832
14381.944000	4612.947000	0.459626	29.995583
14390.990000	4614.748000	0.459771	29.995083
14400.092000	4616.569000	0.460222	29.990774
14409.114000	4618.492000	0.458895	29.992203
14418.146000	4620.293000	0.459600	29.998119
14427.198000	4621.952000	0.459317	29.999953
14436.200000	4623.814000	0.459587	29.982522
14445.202000	4625.453000	0.459312	29.997522
14454.317000	4627.396000	0.459223	29.994205
14463.369000	4629.055000	0.460122	29.998020
14472.461000	4631.018000	0.458658	29.992972
14481.563000	4632.819000	0.459436	29.992761
14490.675000	4634.883000	0.459105	30.011447
14499.787000	4636.320000	0.460123	29.992842
14508.839000	4638.060000	0.459865	29.995800
14517.891000	4639.881000	0.459955	30.003234
14526.933000	4641.925000	0.458517	30.010176
14536.035000	4643.523000	0.459182	30.004843
14545.177000	4645.486000	0.459016	29.997226
14554.219000	4647.227000	0.459548	29.988708
14563.361000	4649.432000	0.459247	30.001005
14572.393000	4650.990000	0.459555	29.999353
14581.485000	4652.771000	0.460029	30.002026
14590.567000	4655.119000	0.459701	29.991842
14599.659000	4656.535000	0.460038	29.993659
14608.841000	4658.437000	0.460504	29.991698
14617.813000	4660.097000	0.460204	30.002086
14627.005000	4662.039000	0.460207	29.990644
14636.097000	4663.577000	0.459500	29.997804
14645.210000	4665.641000	0.460202	29.994112
14654.262000	4667.301000	0.459934	29.994892
14663.365000	4669.122000	0.460105	30.001524
14672.607000	4671.307000	0.459473	30.007290
14681.640000	4672.663000	0.459960	30.005279
14690.792000	4674.828000	0.461224	29.993260
14699.964000	4676.508000	0.460241	30.007647
14709.026000	4678.248000	0.460938	29.992740
14718.048000	4679.948000	0.460392	29.992869
14727.221000	4681.850000	0.460240	29.990081
14736.263000	4683.975000	0.460437	30.010805
14745.345000	4685.816000	0.460008	29.994104
14754.447000	4687.557000	0.460617	29.996474
14763.549000	4689.438000	0.459085	29.990993
14772.741000	4691.098000	0.458584	29.994263
14781.834000	4692.838000	0.458526	29.990636
14790.856000	4694.680000	0.459885	29.988697
14799.918000	4696.501000	0.458584	30.003860
14808.980000	4698.342000	0.459311	30.000607
14818.162000	4700.588000	0.459491	29.990309
14827.226000	4702.167000	0.459741	30.000799
14836.278000	4703.968000	0.458614	29.995391
14845.320000	4705.607000	0.458966	30.009229
14854.322000	4707.610000	0.458954	30.002241
14863.504000	4709.290000	0.459676	29.998327
14872.546000	4711.151000	0.460400	30.005060
14881.588000	4712.730000	0.459685	29.999838
14890.650000	4714.592000	0.459855	30.006048
14899.672000	4716.959000	0.459184	30.004330
14908.744000	4718.173000	0.459164	29.999265
14917.867000	4720.096000	0.459631	30.004153
14926.979000	4722.079000	0.458615	30.006603
14935.937000	4723.961000	0.459704	29.996653
14944.999000	4725.276000	0.458738	29.991550
14954.061000	4727.441000	0.459071	30.001352
14963.114000	4728.918000	0.459029	30.000289
14972.226000	4731.165000	0.458516	29.995716
14981.408000	4732.925000	0.458567	29.999361
14990.480000	4734.686000	0.458712	30.011146
14999.604000	4736.264000	0.458839	29.994555
15008.616000	4738.571000	0.458826	30.001945
15017.798000	4740.089000	0.457692	30.009197
15026.840000	4742.072000	0.457899	29.998817
15035.902000	4743.852000	0.457692	30.001468
15045.044000	4745.734000	0.457431	30.008196
15054.136000	4747.414000	0.457061	30.000342
15063.308000	4749.296000	0.458018	30.002595
15072.370000	4750.996000	0.458093	30.007194
15081.522000	4752.797000	0.457869	29.991828
15090.574000	4754.173000	0.456892	29.998077
15099.636000	4756.641000	0.458118	29.999481
15108.828000	4758.139000	0.458759	29.992885
15117.920000	4760.021000	0.458023	30.006830
15127.112000	4761.984000	0.458615	29.993981
15136.164000	4763.845000	0.458104	29.999217
15145.236000	4765.727000	0.457362	29.996749
15154.288000	4767.285000	0.457469	29.997920
15163.440000	4769.370000	0.457524	29.998762
15172.492000	4771.130000	0.457164	29.996551
15181.674000	4772.931000	0.457443	29.994122
15190.777000	4774.712000	0.456365	29.996174
15199.829000	4776.574000	0.456994	29.995533
15208.941000	4778.435000	0.456129	30.007431
15218.003000	4779.832000	0.456512	29.984264
15227.025000	4781.855000	0.457192	29.990889
15236.127000	4783.757000	0.455259	30.009634
15245.189000	4785.599000	0.455915	30.002800
15254.251000	4787.339000	0.457885	29.998596
15263.433000	4789.464000	0.457492	30.004345
15272.526000	4791.184000	0.457664	30.009374
15281.628000	4792.702000	0.457207	29.993103
15290.740000	4794.928000	0.457479	30.005145
15299.892000	4796.749000	0.457131	29.989142
15308.894000	4798.024000	0.456523	29.998433
15317.956000	4800.351000	0.457117	30.001573
15327.058000	4801.828000	0.456989	30.003530
15336.200000	4803.771000	0.457537	29.985328
15345.232000	4805.835000	0.456291	29.996476
15354.364000	4807.534000	0.456254	29.991464
15363.396000	4809.113000	0.456111	29.999730
15372.448000	4811.258000	0.456863	29.994344
15381.550000	4812.958000	0.457201	30.005482
15390.612000	4814.779000	0.457225	29.986585
15399.674000	4816.236000	0.457512	29.991474
15408.706000	4818.522000	0.456002	30.008859
15417.886000	4820.000000	0.457703	29.996652
15426.900000	4822.104000	0.456971	29.997646
15436.002000	4823.602000	0.456683	29.995619
15445.094000	4825.686000	0.457055	29.991605
15454.126000	4827.345000	0.456295	30.005791
15463.298000	4829.146000	0.456768	30.013907
15472.410000	4831.069000	0.457044	29.993956
15481.492000	4833.133000	0.456226	30.007016
15490.647000	4834.752000	0.457374	29.987548
15499.661000	4836.391000	0.456948	30.001309
15508.833000	4838.252000	0.457017	29.991816
15517.915000	4840.296000	0.457564	30.005022
15526.977000	4842.016000	0.457400	30.000996
15536.030000	4843.493000	0.457879	29.999116
15545.254000	4845.456000	0.457312	30.000756
15554.386000	4847.277000	0.457289	29.998820
15563.408000	4849.200000	0.457124	29.989683
15572.430000	4850.819000	0.457217	30.004061
15581.572000	4852.923000	0.457538	30.000831
15590.634000	4854.825000	0.456948	29.995258
15599.746000	4856.363000	0.455866	30.003900
15608.848000	4858.448000	0.456661	30.001289
15617.920000	4860.046000	0.456390	30.000520
15627.012000	4861.989000	0.455927	30.004615
15636.084000	4863.628000	0.456124	30.008030
15645.296000	4865.753000	0.456745	29.989918
15654.368000	4867.351000	0.456558	29.990375
15663.460000	4869.071000	0.456914	29.996378
15672.542000	4871.257000	0.456269	29.986497
15681.634000	4872.795000	0.455633	30.000489
15690.696000	4874.717000	0.456706	29.991031
15699.718000	4876.518000	0.456421	29.999458
15708.780000	4878.542000	0.456139	29.994980
15717.802000	4880.019000	0.456672	29.995677
15726.824000	4881.901000	0.455861	30.010670
15735.886000	4884.005000	0.456043	30.011948
15744.948000	4885.442000	0.455158	29.988876
15754.000000	4887.344000	0.456570	30.008414
15763.152000	4889.226000	0.456437	29.992978
15772.294000	4890.582000	0.456273	30.006599
15781.356000	4892.403000	0.456383	30.001428
15790.528000	4894.852000	0.457554	29.997203
15799.560000	4896.592000	0.457111	29.999671
15808.613000	4898.535000	0.456037	30.007212
15817.675000	4900.154000	0.456577	29.988798
15826.747000	4902.137000	0.456163	29.998156
15835.829000	4903.452000	0.455739	30.009108
15844.911000	4905.516000	0.456299	30.006636
15853.923000	4907.418000	0.456351	29.999243
15863.155000	4909.482000	0.456056	30.000362
15872.247000	4911.101000	0.456202	30.002258
15881.229000	4912.882000	0.455634	30.000218
15890.271000	4914.703000	0.455616	29.993099
15899.354000	4916.504000	0.456191	29.994115
15908.466000	4918.204000	0.456795	30.007481
15917.558000	4920.227000	0.456092	29.998327
15926.611000	4921.826000	0.456262	29.994896
15935.698000	4923.890000	0.456916	29.993278
15944.760000	4925.307000	0.456240	30.006747
15953.803000	4927.168000	0.456574	30.003209
15962.835000	4928.828000	0.456760	30.005826
15971.907000	4930.669000	0.456579	29.996236
15980.969000	4932.733000	0.456961	29.995951
15989.958000	4934.797000	0.455830	29.992263
15999.100000	4936.396000	0.456442	30.002884
16008.172000	4938.440000	0.455620	30.000201
16017.224000	4939.897000	0.455659	30.003945
16026.449000	4941.779000	0.456936	29.987153
16035.431000	4943.741000	0.456204	29.997100
16044.545000	4945.340000	0.456332	30.004453
16053.627000	4947.202000	0.454922	30.005904
16062.809000	4949.144000	0.455571	29.986421
16071.871000	4951.168000	0.454978	30.006490
16080.983000	4952.848000	0.454385	29.990488
16090.145000	4954.790000	0.454741	29.993422
16099.198000	4956.449000	0.454406	29.993210
16108.230000	4958.433000	0.454011	29.991710
16117.282000	4959.910000	0.454820	30.000284
16126.384000	4961.933000	0.454270	29.999826
16135.456000	4963.836000	0.454360	30.006774
16144.548000	4965.616000	0.454341	30.001318
16153.670000	4967.053000	0.454555	30.005487
16162.794000	4969.117000	0.455531	29.997572
16171.856000	4970.898000	0.454288	30.004491
16180.978000	4972.760000	0.454911	29.996602
16190.010000	4974.318000	0.454340	30.007519
16199.092000	4976.442000	0.454647	29.996170
16208.104000	4978.041000	0.454297	29.987834
16217.296000	4979.943000	0.454831	29.993431
16226.448000	4981.684000	0.454536	30.002746
16235.540000	4983.808000	0.454300	29.993352
16244.612000	4985.629000	0.454454	30.000592
16253.684000	4987.329000	0.455326	29.987910
16262.796000	4989.070000	0.454558	29.998193
16271.938000	4990.931000	0.455100	30.011224
16281.090000	4992.773000	0.455103	29.987702
16290.085000	4994.513000	0.455186	29.992273
16299.107000	4996.354000	0.455732	30.002300
16308.179000	4998.338000	0.455652	30.002452
16317.232000	5000.139000	0.454641	30.003931
16326.344000	5001.778000	0.455606	29.995584
16335.476000	5003.619000	0.455860	29.989092
16344.588000	5005.643000	0.455155	30.002534
16353.690000	5007.444000	0.455400	29.994459
16362.792000	5009.002000	0.456544	29.994276
16371.964000	5011.106000	0.455415	29.997021
16381.037000	5012.745000	0.455708	30.000048
16390.149000	5014.344000	0.456328	30.002092
16399.361000	5016.266000	0.455730	29.994266
16408.533000	5018.027000	0.456567	29.997651
16417.605000	5019.889000	0.456876	30.002173
16426.777000	5021.932000	0.457480	29.989855
16435.809000	5023.713000	0.456883	29.995178
16444.901000	5025.696000	0.457250	29.997967
16453.965000	5027.275000	0.456983	29.994471
16462.897000	5029.217000	0.455320	30.004395
16471.959000	5030.573000	0.455571	30.001536
16481.102000	5032.961000	0.455970	30.002258
16490.144000	5034.701000	0.455272	30.010335
16499.196000	5036.664000	0.455342	29.987006
16508.328000	5038.647000	0.454544	30.000272
16517.430000	5040.145000	0.454343	30.002991
16526.502000	5041.986000	0.454736	30.003358
16535.574000	5043.747000	0.455130	29.992022
16544.616000	5045.588000	0.455050	30.011346
16553.728000	5047.733000	0.454235	30.002519
16562.850000	5049.251000	0.453613	29.994602
16571.922000	5051.072000	0.454140	29.996034
16580.935000	5052.752000	0.454303	30.005603
16590.078000	5054.775000	0.454188	30.002874
16599.100000	5056.617000	0.453729	29.996625
16608.162000	5058.316000	0.454497	29.995189
16617.235000	5059.996000	0.453734	30.000827
16626.307000	5061.858000	0.454628	30.006021
16635.439000	5063.598000	0.454362	30.004760
16644.481000	5065.439000	0.454958	29.989273
16653.663000	5067.261000	0.455209	29.999750
16662.755000	5068.778000	0.454523	29.997745
16671.907000	5070.660000	0.454480	30.006327
16681.049000	5073.068000	0.455989	29.994115
16690.201000	5074.748000	0.454548	30.004971
16699.263000	5076.286000	0.455465	29.996664
16708.445000	5078.269000	0.455375	30.002467
16717.577000	5079.888000	0.455396	29.991237
16726.769000	5082.134000	0.455222	30.017277
16735.911000	5083.996000	0.455159	29.991212
16744.933000	5085.655000	0.454790	30.001702
16753.945000	5087.395000	0.455466	29.999199
16763.047000	5089.014000	0.454932	29.996951
16772.089000	5091.038000	0.454742	30.001785
16781.231000	5092.859000	0.454804	29.994283
16790.323000	5094.498000	0.454968	29.997009
16799.415000	5096.501000	0.455116	30.013854
16808.447000	5098.140000	0.455545	30.008316
16817.499000	5099.860000	0.455401	30.002969
16826.621000	5101.945000	0.455812	29.990675
16835.663000	5103.564000	0.456532	29.997933
16844.685000	5105.304000	0.456198	29.996944
16853.797000	5107.226000	0.456216	30.005443
16862.949000	5109.088000	0.455681	29.999039
16872.031000	5110.788000	0.455112	30.008909
16881.093000	5112.832000	0.455762	30.000419
16890.205000	5114.450000	0.454410	30.007083
16899.257000	5116.494000	0.455790	30.003794
16908.309000	5118.154000	0.454684	30.004445
16917.351000	5120.278000	0.455343	29.997222
16926.453000	5122.019000	0.454864	30.001737
16935.525000	5123.617000	0.453583	30.001378
16944.577000	5125.722000	0.454161	29.990952
16953.599000	5127.341000	0.452597	30.002182
16962.611000	5129.283000	0.454323	29.996788
16971.643000	5131.003000	0.454081	29.999204
16980.755000	5132.663000	0.453443	29.998247
16989.887000	5134.666000	0.454732	29.989520
16998.999000	5136.609000	0.453156	29.994909
17008.061000	5138.389000	0.453672	29.989500
17017.173000	5140.109000	0.453586	29.996069
17026.215000	5141.728000	0.453050	29.995573
17035.277000	5143.732000	0.454422	30.006073
17044.379000	5145.209000	0.453326	30.006591
17053.441000	5147.232000	0.454328	30.002419
17062.553000	5149.195000	0.454137	29.992487
17071.685000	5150.632000	0.453990	30.000995
17080.717000	5152.919000	0.454349	29.995792
17089.839000	5154.376000	0.453416	29.996122
17099.041000	5156.318000	0.454225	29.994314
17108.134000	5158.241000	0.453851	30.005281
17117.226000	5159.799000	0.454683	30.004506
17126.218000	5161.701000	0.454353	30.006558
17135.340000	5163.583000	0.454328	29.994524
17144.352000	5165.606000	0.454805	29.994600
17153.434000	5167.306000	0.453145	30.011361
17162.516000	5169.310000	0.453065	29.993735
17171.608000	5170.686000	0.453977	30.000374
17180.630000	5172.406000	0.453865	29.990201
17189.732000	5174.308000	0.453314	30.007037
17198.874000	5176.372000	0.453721	30.011172
17207.966000	5178.132000	0.453645	29.996038
17217.078000	5179.792000	0.454609	30.000854
17226.100000	5181.775000	0.455165	29.993244
17235.252000	5183.596000	0.454280	29.993672
17244.274000	5185.296000	0.454689	29.998110
17253.296000	5186.793000	0.455139	29.997575
17262.348000	5189.039000	0.455101	29.998986
17271.460000	5190.699000	0.454443	30.013173
17280.472000	5192.560000	0.455660	30.007079
17289.624000	5194.807000	0.455241	29.988441
17298.716000	5196.082000	0.455850	29.990569
17307.749000	5198.206000	0.455225	29.991775
17316.811000	5199.886000	0.454838	29.997054
17325.923000	5201.606000	0.455262	29.989427
17334.965000	5203.710000	0.454064	30.000080
17344.017000	5205.309000	0.454810	30.011801
17353.069000	5207.333000	0.452943	29.990621
17362.191000	5209.154000	0.453316	30.008045
17371.263000	5210.935000	0.452546	30.002555
17380.395000	5212.918000	0.452901	30.004164
17389.467000	5214.395000	0.452400	30.005555
17398.559000	5216.418000	0.453329	30.002381
17407.572000	5218.584000	0.452984	29.997968
17416.634000	5219.960000	0.452371	30.013970
17425.716000	5221.882000	0.452530	30.012139
17434.798000	5223.703000	0.452683	30.002178
17443.860000	5225.241000	0.452210	30.004752
17452.882000	5226.698000	0.453072	29.997598
17461.944000	5229.066000	0.453248	29.996996
17470.976000	5230.563000	0.454003	29.997566
17480.238000	5232.567000	0.453440	29.992465
17489.340000	5234.529000	0.452512	30.003289
17498.473000	5236.351000	0.453322	29.990456
17507.495000	5238.192000	0.452494	29.999811
17516.607000	5239.973000	0.452405	30.001236
17525.699000	5241.652000	0.453388	29.998548
17534.851000	5243.555000	0.453415	29.990281
17544.033000	5245.315000	0.453467	30.003814
17553.055000	5247.238000	0.452996	29.988770
17562.077000	5248.998000	0.453285	29.991933
17571.199000	5250.981000	0.453475	30.006627
17580.291000	5252.357000	0.453590	29.990739
17589.393000	5254.462000	0.453139	30.012297
17598.525000	5256.364000	0.454709	29.995873
17607.627000	5258.165000	0.453722	29.998352
17616.729000	5259.642000	0.453471	30.010153
17625.791000	5261.828000	0.453457	29.987249
17634.813000	5263.548000	0.453224	29.994067
17643.905000	5265.187000	0.453274	29.989940
17652.987000	5267.048000	0.452789	30.002399
17661.959000	5268.991000	0.452914	29.997374
17671.082000	5270.509000	0.453090	29.994255
17680.204000	5272.370000	0.454273	29.994718
17689.266000	5274.192000	0.453990	30.006342
17698.258000	5276.074000	0.454764	30.000271
17707.310000	5277.895000	0.454376	30.000615
17716.402000	5279.716000	0.456150	30.001367
17725.524000	5281.740000	0.455344	29.994112
17734.616000	5283.419000	0.454403	30.003082
17743.718000	5285.078000	0.454748	30.005355
17752.800000	5286.718000	0.453819	30.006005
17761.892000	5289.004000	0.454152	29.998106
17770.904000	5290.866000	0.453669	30.005896
17779.946000	5292.545000	0.453485	29.995970
17789.009000	5294.346000	0.452931	29.995991
17798.081000	5296.147000	0.451670	30.003795
17807.183000	5298.070000	0.452209	30.000454
17816.325000	5299.952000	0.452105	30.007928
17825.417000	5301.813000	0.452458	29.992317
17834.569000	5303.554000	0.452150	30.006460
17843.631000	5305.112000	0.452406	29.990472
17852.853000	5307.257000	0.452115	30.011842
17861.905000	5309.119000	0.452376	29.993901
17870.977000	5311.041000	0.451424	29.987692
17880.079000	5312.680000	0.451859	30.001997
17889.141000	5314.400000	0.451398	29.994007
17898.263000	5316.464000	0.452168	29.992810
17907.305000	5317.800000	0.451938	29.993408
17916.447000	5319.864000	0.451310	29.996139
17925.469000	5321.887000	0.451450	30.007272
17934.571000	5323.607000	0.452277	30.006483
17943.673000	5325.246000	0.452239	29.988457
17952.785000	5327.290000	0.451616	30.008731
17961.829000	5328.707000	0.452460	29.990261
17970.891000	5330.508000	0.453056	30.008200
17979.953000	5332.612000	0.452890	30.001991
17989.195000	5334.312000	0.453393	29.987917
17998.277000	5336.234000	0.452462	29.996483
18007.409000	5337.914000	0.452398	29.994874
18016.501000	5339.857000	0.452513	29.990969
18025.583000	5341.597000	0.452534	30.000887
18034.645000	5343.398000	0.453096	30.010554
18043.787000	5345.381000	0.453009	30.001772
18052.820000	5346.959000	0.453572	29.990304
18061.872000	5348.862000	0.453484	30.011296
18070.944000	5350.521000	0.452429	30.015657
18080.036000	5352.484000	0.452973	29.998068
18089.138000	5354.710000	0.453244	30.005125
18098.200000	5356.146000	0.452803	29.988662
18107.332000	5357.644000	0.452717	30.017511
18116.454000	5359.991000	0.453879	29.992194
18125.516000	5361.752000	0.454363	30.006930
18134.598000	5363.391000	0.454027	30.000140
18143.690000	5365.111000	0.455013	29.995268
18152.692000	5367.114000	0.454943	30.007451
18161.774000	5368.672000	0.454146	30.000686
18170.836000	5370.554000	0.454322	30.003309
18179.968000	5372.517000	0.453617	29.992090
18189.070000	5374.480000	0.453550	30.000147
18198.092000	5376.200000	0.453425	29.995407
18207.154000	5378.001000	0.453469	30.009553
18216.226000	5380.065000	0.453511	29.993878
18225.348000	5381.664000	0.453053	29.990621
18234.340000	5383.364000	0.453144	29.998468
18243.373000	5384.922000	0.452362	29.995410
18252.475000	5386.885000	0.451902	29.992463
18261.628000	5388.706000	0.451701	29.993999
18270.710000	5390.972000	0.452146	29.991638
18279.752000	5392.267000	0.452405	29.996205
18288.934000	5394.412000	0.451126	30.002900
18298.006000	5396.213000	0.451510	30.000480
18307.068000	5398.075000	0.451158	29.993300
18316.211000	5399.896000	0.451556	29.988552
18325.283000	5401.535000	0.451594	30.011543
18334.345000	5403.417000	0.450609	30.007689
18343.367000	5404.955000	0.451795	30.003050
18352.499000	5407.141000	0.453188	30.005585
18361.601000	5408.820000	0.452563	29.992499
18370.695000	5410.581000	0.452394	29.994260
18379.847000	5412.584000	0.451835	30.001714
18388.949000	5414.203000	0.452936	29.995402
18398.071000	5416.227000	0.452210	29.998601
18407.073000	5418.108000	0.452412	30.003000
18416.165000	5419.990000	0.452723	29.990319
18425.347000	5421.893000	0.451408	30.001266
18434.400000	5423.430000	0.452217	29.994848
18443.402000	5425.130000	0.452503	30.006057
18452.554000	5426.992000	0.452563	29.991805
18461.616000	5429.056000	0.452504	30.005208
18470.690000	5430.351000	0.452257	30.004429
18479.852000	5432.193000	0.452619	30.004026
18488.914000	5434.257000	0.452771	30.002988
18498.106000	5435.612000	0.453730	29.998017
18507.198000	5437.960000	0.453632	29.997959
18516.320000	5439.700000	0.454014	29.994315
18525.492000	5441.622000	0.453651	29.995666
18534.554000	5443.140000	0.453011	30.006999
18543.657000	5445.265000	0.453646	29.994209
18552.769000	5446.944000	0.454550	30.008120
18561.861000	5448.705000	0.454004	30.000243
18570.933000	5450.728000	0.455361	29.997519
18580.016000	5452.610000	0.455228	29.989097
18589.038000	5454.229000	0.455409	30.000240
18598.120000	5456.293000	0.454706	29.998433
18607.202000	5457.750000	0.454246	29.988732
18616.244000	5459.612000	0.453689	29.996053
18625.296000	5461.696000	0.454570	29.999776
18634.418000	5463.234000	0.453949	29.995750
18643.420000	5465.298000	0.454311	29.983700
18652.432000	5467.160000	0.453689	29.989912
18661.534000	5469.022000	0.453364	29.993622
18670.656000	5470.620000	0.452857	30.001716
18679.708000	5472.462000	0.453175	30.010029
18688.780000	5474.323000	0.452843	29.996994
18697.852000	5475.942000	0.451987	30.000215
18707.014000	5477.986000	0.452294	29.998955
18716.046000	5479.382000	0.451673	30.003661
18725.098000	5481.709000	0.452287	29.990477
18734.240000	5483.349000	0.452141	29.989407
18743.272000	5485.089000	0.451681	29.998561
18752.364000	5487.011000	0.452083	30.000807
18761.466000	5488.832000	0.452509	29.999130
18770.528000	5490.451000	0.451748	30.003550
18779.590000	5492.455000	0.453007	29.992997
18788.642000	5494.053000	0.452899	30.000960
18797.714000	5496.158000	0.452114	30.010386
18806.786000	5497.777000	0.452890	30.012704
18815.918000	5500.003000	0.452044	30.004389
18825.030000	5501.480000	0.452538	30.005753
18834.152000	5503.422000	0.452712	29.998256
18843.204000	5505.142000	0.452827	30.006310
18852.246000	5507.166000	0.451372	30.000525
18861.318000	5508.623000	0.452666	30.007828
18870.420000	5510.647000	0.452841	29.996285
18879.522000	5512.630000	0.452688	29.996252
18888.654000	5514.330000	0.452644	29.997157
18897.806000	5516.110000	0.453552	29.995188
18906.828000	5518.377000	0.453360	30.000890
18915.930000	5519.611000	0.452901	29.993127
18925.002000	5521.554000	0.453058	29.991863
18934.044000	5523.517000	0.453311	29.993287
18943.196000	5524.953000	0.452960	29.995186
18952.218000	5526.997000	0.453185	30.002637
18961.320000	5529.102000	0.453405	29.994758
18970.472000	5530.377000	0.453438	30.000042
18979.564000	5532.319000	0.454268	29.992423
18988.736000	5534.161000	0.453876	29.998726
18997.809000	5536.123000	0.453968	30.010861
19006.871000	5537.641000	0.454545	30.000162
19015.963000	5539.928000	0.455447	29.997600
19025.035000	5541.709000	0.455140	30.009486
19034.067000	5543.429000	0.454524	30.015978
19043.109000	5545.128000	0.454982	29.998558
19052.221000	5547.031000	0.454897	29.995475
19061.403000	5548.730000	0.455563	30.002249
19070.546000	5550.794000	0.453725	30.003800
19079.708000	5552.676000	0.453238	30.013992
19088.880000	5554.639000	0.453295	30.005479
19097.882000	5556.319000	0.452962	29.996066
19106.984000	5558.383000	0.452033	29.989276
19116.006000	5559.840000	0.451911	29.995411
19125.108000	5561.884000	0.451895	30.000085
19134.130000	5563.604000	0.452607	29.994087
19143.312000	5565.546000	0.452816	29.985904
19152.415000	5566.943000	0.451530	30.003537
19161.587000	5569.027000	0.452318	30.004415
19170.619000	5570.909000	0.451763	30.012147
19179.771000	5572.386000	0.450672	30.003321
19188.863000	5574.450000	0.451972	29.995346
19198.045000	5576.109000	0.451872	29.991046
19207.227000	5577.829000	0.452350	29.999937
19216.289000	5580.055000	0.452563	29.999830
19225.371000	5581.775000	0.451852	29.997394
19234.583000	5583.617000	0.451954	29.995195
19243.705000	5585.155000	0.452442	30.003440
19252.737000	5586.956000	0.451882	30.006468
19261.860000	5588.635000	0.453254	29.989776
19270.972000	5590.821000	0.452334	30.002562
19280.124000	5592.662000	0.453771	29.991781
19289.226000	5594.605000	0.452453	29.987936
19298.248000	5596.345000	0.452783	30.002338
19307.300000	5597.863000	0.451895	29.993866
19316.482000	5599.826000	0.453141	29.995382
19325.624000	5601.910000	0.453616	29.992643
19334.646000	5603.468000	0.452865	29.997752
19343.758000	5605.411000	0.453472	30.000861
19352.780000	5607.191000	0.453836	29.987920
19361.942000	5609.073000	0.453162	29.994597
19370.944000	5610.814000	0.452897	30.007736
19380.086000	5612.129000	0.454216	29.992583
19389.198000	5614.294000	0.455855	29.997907
19398.250000	5616.379000	0.455408	30.001951
19407.312000	5617.815000	0.455417	30.000767
19416.374000	5619.576000	0.456521	30.008311
19425.446000	5621.701000	0.455836	29.996431
19434.539000	5623.582000	0.456709	29.999295
19443.601000	5625.383000	0.456148	29.999522
19452.823000	5626.982000	0.454314	29.998792
19461.875000	5628.297000	0.455334	29.993959
19470.927000	5630.847000	0.454931	30.000612
19479.959000	5632.304000	0.454430	30.002944
19489.071000	5634.206000	0.454761	30.013982
19498.143000	5636.250000	0.454080	30.007049
19507.266000	5638.011000	0.454273	30.005212
19516.338000	5640.196000	0.453704	29.997044
19525.381000	5641.471000	0.453755	30.002993
19534.563000	5643.737000	0.452596	30.004798
19543.716000	5645.397000	0.453914	29.993813
19552.808000	5647.177000	0.453587	29.993926
19561.790000	5648.897000	0.452891	30.012418
19570.892000	5650.698000	0.452778	30.007522
19579.964000	5652.742000	0.453730	29.992362
19589.056000	5654.341000	0.452804	30.002177
19598.168000	5656.142000	0.452271	29.998990
19607.230000	5658.044000	0.452839	30.009247
19616.402000	5659.784000	0.452413	30.001609
19625.474000	5661.342000	0.452933	29.997572
19634.586000	5663.406000	0.452261	29.995317
19643.718000	5665.430000	0.453594	29.999399
19652.820000	5667.089000	0.452448	29.989874
19661.912000	5668.688000	0.452563	29.998429
19671.064000	5670.954000	0.452900	29.995232
19680.086000	5672.654000	0.452952	30.002079
19689.138000	5674.678000	0.453809	29.993899
19698.230000	5676.297000	0.453452	29.996991
19707.322000	5678.077000	0.453597	30.001438
19716.465000	5680.061000	0.452042	30.011007
19725.467000	5681.720000	0.453206	29.992928
19734.489000	5683.723000	0.453909	29.989700
19743.591000	5685.039000	0.452992	30.007846
19752.733000	5686.900000	0.454180	29.992899
19761.825000	5688.863000	0.452568	30.006349
19770.907000	5690.725000	0.454711	29.989492
19779.949000	5692.425000	0.454796	30.000256
19789.031000	5694.266000	0.454488	30.001172
19798.153000	5695.925000	0.455356	29.994504
19807.265000	5697.989000	0.454112	30.003507
19816.357000	5699.527000	0.453945	30.011184
19825.419000	5701.672000	0.454042	30.003686
19834.451000	5703.332000	0.454726	29.996913
19843.523000	5705.274000	0.454426	30.006951
19852.625000	5706.974000	0.454866	30.000985
19861.717000	5708.856000	0.454831	30.004546
19870.819000	5710.758000	0.455818	30.005397
19880.011000	5712.559000	0.456150	29.992815
19889.144000	5714.198000	0.455468	30.008554
19898.246000	5716.363000	0.455199	30.006905
19907.298000	5717.942000	0.455291	29.998485
19916.360000	5719.945000	0.455579	29.991499
19925.502000	5721.362000	0.454303	30.003432
19934.604000	5723.729000	0.455042	30.002485
19943.667000	5725.247000	0.454956	30.005278
19952.729000	5727.048000	0.455065	29.994194
19961.791000	5729.072000	0.453283	30.000990
19970.863000	5730.751000	0.453493	30.004918
19979.955000	5732.552000	0.453679	29.991670
19989.077000	5734.191000	0.453115	30.000281
19998.239000	5736.235000	0.452950	30.005558
20007.441000	5737.915000	0.453266	30.013233
20016.483000	5740.019000	0.453228	29.987581
20025.595000	5741.719000	0.452711	29.996636
20034.777000	5743.560000	0.453039	29.996348
20043.799000	5745.442000	0.453860	29.995699
20052.971000	5746.899000	0.453587	30.005334
20062.003000	5748.882000	0.452915	29.999803
20071.025000	5750.441000	0.453750	29.989258
20080.137000	5752.606000	0.454206	30.000375
20089.219000	5754.285000	0.454015	30.009727
20098.301000	5755.904000	0.453771	29.995261
20107.343000	5758.029000	0.454277	29.998669
20116.335000	5759.810000	0.454877	29.995623
20125.517000	5761.429000	0.454125	29.994559
20134.699000	5763.493000	0.454906	30.002856
20143.791000	5765.435000	0.454907	29.998910
20152.903000	5766.912000	0.453742	29.991569
20162.075000	5769.017000	0.454120	30.000273
20171.147000	5770.717000	0.454421	30.000108
20180.199000	5772.599000	0.454200	30.007990
20189.261000	5774.299000	0.453851	29.992183
20198.253000	5776.059000	0.454501	29.991423
20207.315000	5777.941000	0.454121	29.987935
20216.487000	5780.066000	0.455169	29.990151
20225.630000	5781.826000	0.454710	30.006868
20234.622000	5783.425000	0.454267	30.003092
20243.694000	5785.489000	0.455066	30.002741
20252.856000	5787.088000	0.454593	30.013258
20261.968000	5789.212000	0.454872	29.993602
20271.020000	5790.932000	0.455473	30.008565
20280.123000	5792.369000	0.455320	29.998908
20289.265000	5794.312000	0.456182	29.999315
20298.237000	5796.173000	0.454566	30.008914
20307.389000	5797.732000	0.456364	30.000522
20316.481000	5799.897000	0.456220	29.990357
20325.523000	5801.718000	0.455889	30.006050
20334.595000	5803.580000	0.455016	30.012313
20343.677000	5805.441000	0.454721	30.001212
20352.859000	5807.060000	0.455589	29.999567
20361.982000	5808.760000	0.455105	29.996197
20371.054000	5810.682000	0.455039	29.996011
20380.196000	5812.807000	0.454259	30.006430
20389.298000	5814.284000	0.454833	29.989042
20398.360000	5816.085000	0.453815	29.997999
20407.462000	5818.129000	0.453179	30.004780
20416.595000	5819.869000	0.453457	29.996617
20425.657000	5821.407000	0.454177	29.992224
20434.719000	5823.492000	0.453877	30.009384
20443.741000	5825.394000	0.453452	30.008177
20452.763000	5827.073000	0.453370	29.997110
20461.825000	5828.976000	0.453435	29.997409
20470.897000	5830.635000	0.453258	30.002189
20480.069000	5832.800000	0.453833	30.002364
20489.222000	5834.055000	0.453663	30.014210
20498.344000	5836.443000	0.453405	30.001472
20507.516000	5838.041000	0.453509	30.001197
20516.518000	5839.660000	0.454671	30.005919
20525.580000	5841.684000	0.453852	30.009181
20534.652000	5843.444000	0.454190	29.997676
20543.764000	5845.306000	0.453428	30.001028
20552.877000	5847.431000	0.454299	29.995727
20562.019000	5848.645000	0.455212	30.000462
20571.141000	5850.648000	0.454739	30.004023
20580.223000	5852.550000	0.453935	29.992924
20589.296000	5854.655000	0.453848	29.997633
20598.308000	5856.172000	0.455080	29.997471
20607.411000	5858.297000	0.453555	30.004403
20616.473000	5859.977000	0.453582	30.001608
20625.535000	5861.596000	0.454648	30.004987
20634.637000	5863.680000	0.454282	29.995556
20643.689000	5864.995000	0.454235	30.008077
20652.751000	5867.019000	0.453980	29.993333
20661.793000	5868.779000	0.454429	30.000711
20670.885000	5870.924000	0.454110	30.013353
20680.047000	5872.806000	0.454762	29.992474
20689.189000	5874.041000	0.455702	29.995885
20698.362000	5876.246000	0.455620	30.008539
20707.444000	5878.108000	0.455126	29.996069
20716.586000	5879.646000	0.455408	30.001395
20725.688000	5881.487000	0.456445	29.995143
20734.830000	5883.369000	0.456463	30.000030
20743.902000	5885.474000	0.456257	30.008652
20752.994000	5887.052000	0.455881	29.992548
20762.156000	5889.197000	0.456084	30.003774
20771.308000	5890.857000	0.455122	30.004910
20780.390000	5892.536000	0.455733	30.001483
20789.412000	5894.357000	0.455628	29.993129
20798.474000	5896.199000	0.455272	30.002742
20807.527000	5898.061000	0.455136	30.000411
20816.669000	5899.861000	0.454705	30.002944
20825.771000	5901.845000	0.455272	29.997761
20834.883000	5903.484000	0.454048	29.997821
20843.935000	5905.447000	0.453096	30.010540
20853.027000	5907.106000	0.454006	29.991856
20862.059000	5908.826000	0.453790	30.010634
20871.161000	5910.688000	0.453600	29.992402
20880.183000	5912.529000	0.454041	29.999894
20889.286000	5914.634000	0.453294	29.996001
20898.428000	5916.172000	0.453411	29.995317
20907.490000	5918.155000	0.453281	29.995644
20916.602000	5920.178000	0.452639	29.996385
20925.644000	5921.979000	0.453566	29.997513
20934.707000	5923.133000	0.453716	29.993475
20943.650000	5925.096000	0.453968	29.998828
20952.743000	5926.917000	0.453977	30.000329
20961.775000	5928.718000	0.453560	30.003618
20970.877000	5930.701000	0.455066	29.996908
20980.139000	5932.643000	0.454381	30.008112
20989.251000	5934.404000	0.454366	29.999982
20998.303000	5936.144000	0.454070	30.002052
21007.436000	5938.188000	0.454576	29.999556
21016.548000	5939.989000	0.454398	30.011417
21025.640000	5942.013000	0.453750	30.007373
21034.702000	5943.510000	0.453822	30.000542
21043.775000	5944.987000	0.454222	30.006628
21052.887000	5947.193000	0.454639	30.010813
21062.019000	5948.852000	0.454038	30.012046
21071.041000	5950.694000	0.454864	30.006586
21080.143000	5952.555000	0.455109	30.006445
21089.285000	5954.316000	0.455288	30.001890
21098.427000	5956.319000	0.454852	30.009694
21107.549000	5957.817000	0.454819	30.000781
21116.692000	5959.881000	0.455288	29.996054
21125.794000	5961.520000	0.455278	30.004176
21134.826000	5963.361000	0.455453	30.008472
21143.878000	5965.547000	0.455895	30.005803
21152.940000	5967.105000	0.455694	30.002620
21162.062000	5968.683000	0.456512	29.990423
21171.154000	5970.666000	0.455363	29.994806
21180.286000	5972.225000	0.456056	29.992608
21189.429000	5974.329000	0.455333	30.001080
21198.491000	5976.272000	0.456098	30.002355
21207.553000	5978.133000	0.455823	30.010079
21216.585000	5979.833000	0.455004	30.000251
21225.727000	5981.897000	0.454962	29.998149
21234.819000	5983.395000	0.454846	29.986341
21243.971000	5985.256000	0.454893	29.989020
21253.033000	5987.240000	0.454350	30.001503
21262.165000	5988.939000	0.452858	30.006522
21271.227000	5991.064000	0.453320	29.998775
21280.329000	5992.602000	0.453818	29.990711
21289.331000	5994.484000	0.453549	29.998035
21295.401000	5995.739000	0.453607	29.997505